Workbook

Sheet ALCOHOL
A1: SIGNATURE COCKTAIL RECIPE
B5: Cocktail Signature (ORIENTAL / BALINESE PURITY) / 5 portion | J5: Cocktail Signature Chapetieau / SEDUCTION | P5: Cocktail Signature Sunset Surf / TRUE CALM
B6: Ingredients | C6: QTY | E6: Unit Price | F6: Total Price | J6: Ingredients | K6: QTY | M6: Unit Price | N6: Total Price | P6: Ingredients | Q6: QTY | S6: Unit Price | T6: Total Price
B7: Pandan Iceland | C7: 300 | D7: ml | E7: ='SUPPLIER & PRICE'!L14 -> 290 | F7: =SUM(E7*C7) -> 87000 | J7: Gordon Dry Gin | K7: 40 | L7: ml | M7: ='SUPPLIER & PRICE'!F97 -> 400 | N7: =SUM(M7*K7) -> 16000 | P7: Jose cuervo | Q7: 45 | R7: ml | S7: ='SUPPLIER & PRICE'!F76 -> 566.66667 | T7: =SUM(S7*Q7) -> 25500
B8: Moncino blanco | C8: 100 | D8: ml | E8: ='SUPPLIER & PRICE'!F91 -> 666.66667 | F8: =SUM(E8*C8) -> 66666.667 | J8: Moncino Bianco | K8: 20 | L8: ml | M8: ='SUPPLIER & PRICE'!F91 -> 666.66667 | N8: =SUM(M8*K8) -> 13333.333 | P8: Triple sec | Q8: 20 | R8: ml | S8: ='SUPPLIER & PRICE'!L16 -> 407.14286 | T8: =SUM(S8*Q8) -> 8142.8571
B9: Lemon Fresh | C9: 80 | D9: ml | E9: ='SUPPLIER & PRICE'!F8 -> 116.66667 | F9: =SUM(E9*C9) -> 9333.3333 | J9: Lavanda Syrup | K9: 40 | L9: ml | M9: ='SUPPLIER & PRICE'!F164 -> 56.755556 | N9: =SUM(K9*M9) -> 2270.2222 | P9: lemon | Q9: 10 | R9: ml | S9: ='SUPPLIER & PRICE'!F8 -> 116.66667 | T9: =SUM(S9*Q9) -> 1166.6667
B10: Kintamani Orange | C10: 90 | D10: ml | E10: ='SUPPLIER & PRICE'!F9 -> 66.666667 | F10: =SUM(E10*C10) -> 6000 | J10: Lemon | K10: 150 | L10: gr | M10: ='SUPPLIER & PRICE'!F8 -> 116.66667 | N10: =SUM(K10*M10) -> 17500 | P10: Simple syrup | Q10: 5 | R10: ml | S10: =PREPARATION!L148 -> 18.736842 | T10: =SUM(S10*Q10) -> 93.684211
B11: Pandan Syrup | C11: 60 | D11: ml | E11: ='SUPPLIER & PRICE'!F140 -> 158.57143 | F11: =SUM(E11*C11) -> 9514.2857 | J11: Total Qty | K11: 240 | L11: ml | P11: Basil cordial | Q11: 45 | R11: ml | S11: =PREPARATION!L89 -> 82.307692 | T11: =SUM(Q11*S11) -> 3703.8462
B12: Coconut Cream | C12: 50 | D12: ml | E12: ='SUPPLIER & PRICE'!F46 -> 75 | F12: =SUM(E12*C12) -> 3750 | J12: Basic Cost | N12: =SUM(N7:N10) -> 49103.556 | P12: Elderflower syrup | Q12: 15 | R12: ml | S12: ='SUPPLIER & PRICE'!F141 -> 158.57143 | T12: =SUM(Q12*S12) -> 2378.5714
B13: Hydro Coco | C13: 150 | D13: ml | E13: ='SUPPLIER & PRICE'!F48 -> 31 | F13: =SUM(E13*C13) -> 4650 | J13: Miscelenious 5% | N13: =SUM(N12*0.05) -> 2455.1778 | P13: Total Qty | Q13: =SUM(Q7:Q12) -> 140 | R13: ml
B14: Total Qty | C14: 600 | D14: ml | G14: Portion / 120 ml | J14: Total Cost | N14: =SUM(N12:N13) -> 51558.733 | P14: Garnish | S14: Sunkist 20 gr | T14: =F109 -> 1200
B15: Basic Cost | F15: =SUM(F7:F13) -> 186914.29 | G15: =SUM(F15/5) -> 37382.857 | J15: Percentage Cost % | N15: =SUM(N14/N16) -> 0.39660564 | P15: Basic Cost | T15: =SUM(T7:T12) -> 40985.626
B16: Miscelenious 5% | F16: =SUM(F15*5%) -> 9345.7143 | G16: =SUM(F16/5) -> 1869.1429 | J16: Selling Price ++ | N16: 130000 | P16: Miscelenious 5% | T16: =SUM(T15*0.05) -> 2049.2813
B17: Total Cost | F17: =SUM(F15:F16) -> 196260 | G17: =SUM(F17/5) -> 39252 | P17: Total Cost | T17: =SUM(T15:T16) -> 43034.907
B18: Percentage Cost % | F18: =SUM(F17/F19) -> 0.30193846 | G18: =SUM(G17/G19) -> 0.30193846 | P18: Percentage Cost % | T18: =SUM(T17/T19) -> 0.30739219
B19: Selling Price ++ | F19: 650000 | G19: 130000 | P19: Selling Price ++ | T19: 140000
B21: Cocktail Signature La clique | J21: Cocktail Signature (CORRIDA / LUST)
B22: Ingredients | C22: QTY | E22: Unit Price | F22: Total Price | J22: Ingredients | K22: QTY | M22: Unit Price | N22: Total Price
B23: Gordon Dry Gin | C23: 50 | D23: ml | E23: =PREPARATION!L53 -> 483.33333 | F23: =SUM(C23*E23) -> 24166.667 | J23: Limo | K23: 45 | L23: ml | M23: ='SUPPLIER & PRICE'!F88 -> 560 | N23: =SUM(M23*K23) -> 25200
B24: Bols Creme De Cassis | C24: 15 | D24: ml | E24: =PREPARATION!L126 -> 74.13865 | F24: =SUM(E24*C24) -> 1112.0797 | J24: Elder Flower Syrup | K24: 15 | L24: ml | M24: ='SUPPLIER & PRICE'!F141 -> 158.57143 | N24: =SUM(M24*K24) -> 2378.5714
B25: Plum Cordial | C25: 45 | D25: ml | E25: =PREPARATION!L126 -> 74.13865 | F25: =SUM(E25*C25) -> 3336.2392 | J25: Kintamani Orange | K25: 60 | L25: ml | M25: ='SUPPLIER & PRICE'!F9 -> 66.666667 | N25: =SUM(K25*M25) -> 4000
B26: Tonic Water | C26: 1 | D26: can | E26: ='SUPPLIER & PRICE'!F62 -> 5041.6667 | F26: =E26 -> 5041.6667 | J26: Tonic Water | K26: 1 | L26: can | M26: ='SUPPLIER & PRICE'!F59 -> 5208.3333 | N26: =SUM(K26*M26) -> 5208.3333
B27: Total Qty | C27: 200 | D27: ml | J27: Total Qty | K27: 250 | L27: ml
B28: Basic Cost | F28: =SUM(F23:F26) -> 33656.652 | J28: Garnish | M28: chilli 2 gr | N28: =SUM('SUPPLIER & PRICE'!F18*2) -> 100
B29: Miscelenious 5% | F29: =SUM(F28*0.05) -> 1682.8326 | J29: Basic Cost | N29: =SUM(N23:N28) -> 36886.905
B30: Total Cost | F30: =SUM(F28:F29) -> 35339.485 | J30: Miscelenious 5% | N30: =SUM(N29*0.05) -> 1844.3452
B31: Percentage Cost % | F31: =SUM(F30/F32) -> 0.27184219 | J31: Total Cost | N31: =SUM(N29:N30) -> 38731.25
B32: Selling Price ++ | F32: 130000 | J32: Percentage Cost % | N32: =SUM(N31/N33) -> 0.27665179
J33: Selling Price ++ | N33: 140000
B36: Cocktail Signature (Coliseum / NOSTALGIA) | J36: Cocktail Signature (BARNUM N BAILEY / DOMINANCE)
B37: Ingredients | C37: QTY | E37: Unit Price | F37: Total Price | J37: Ingredients | K37: QTY | M37: Unit Price | N37: Total Price
B38: Gin sesame | C38: 30 | D38: ml | E38: =PREPARATION!L44 -> 481.81818 | F38: =SUM(E38*C38) -> 14454.545 | J38: Jim Beam Black | K38: 35 | L38: ml | M38: ='SUPPLIER & PRICE'!F77 -> 833.33333 | N38: =SUM(M38*K38) -> 29166.667
B39: Moncino Bianco | C39: 20 | D39: ml | E39: ='SUPPLIER & PRICE'!F91 -> 666.66667 | F39: =SUM(C39*E39) -> 13333.333 | J39: Limo | K39: 30 | L39: ml | M39: ='SUPPLIER & PRICE'!F88 -> 560 | N39: =SUM(M39*K39) -> 16800
B40: Bols Peach | C40: 10 | D40: ml | E40: ='SUPPLIER & PRICE'!L16 -> 407.14286 | F40: =SUM(C40*E40) -> 4071.4286 | J40: Cherry Cordial | K40: 60 | L40: ml | M40: =PREPARATION!L109 -> 69.333229 | N40: =SUM(K40*M40) -> 4159.9937
B41: Peach Cordial | C41: 60 | D41: ml | E41: =PREPARATION!L99 -> 69.333229 | F41: =SUM(C41*E41) -> 4159.9937 | J41: Total Qty | K41: 125 | L41: ml
B42: Total Qty | C42: 120 | D42: ml | J42: Garnish | M42: jelly 1 pcs | N42: ='SUPPLIER & PRICE'!F151 -> 1250
B43: Garnish | E43: olive 2 pcs | F43: =SUM('SUPPLIER & PRICE'!F40*2) -> 2240 | J43: Basic Cost | N43: =SUM(N38:N42) -> 51376.66
B44: Basic Cost | F44: =SUM(F38:F43) -> 38259.301 | J44: Miscelenious 5% | N44: =SUM(N43*0.05) -> 2568.833
B45: Miscelenious 5% | F45: =SUM(F44*0.05) -> 1912.9651 | J45: Total Cost | N45: =SUM(N43:N44) -> 53945.493
B46: Total Cost | F46: =SUM(F44:F45) -> 40172.266 | J46: Percentage Cost % | N46: =SUM(N45/N47) -> 0.35963662
...

Sheet NON ALCOHOL
B2: COFFEE RECIPE
B5: ESPRESSO SINGLE / DOUBLE | I5: AMERICANO
B6: Ingredients | C6: QTY | E6: Unit Price | F6: Total Price | I6: Ingredients | J6: QTY | L6: Unit Price | M6: Total Price
B7: Coffee bean | C7: 20 | D7: gr | E7: ='SUPPLIER & PRICE'!F128 -> 280 | F7: =SUM(E7*C7) -> 5600 | I7: Coffee bean | J7: 20 | K7: gr | L7: =E7 -> 280 | M7: =SUM(L7*J7) -> 5600
B8: Water | C8: 100 | D8: ml | E8: ='SUPPLIER & PRICE'!F57 -> 1.1578947 | F8: =SUM(E8*C8) -> 115.78947 | I8: Water | J8: 400 | K8: ml | L8: =E8 -> 1.1578947 | M8: =SUM(L8*J8) -> 463.15789
B9: Total Qty | C9: 50 | D9: ml | I9: Total Qty | J9: 320 | K9: ml
B10: Basic Cost | F10: =SUM(F5:F8) -> 5715.7895 | I10: Basic Cost | M10: =SUM(M5:M8) -> 6063.1579
B11: Miscelenious 5% | F11: =SUM(F10*0.05) -> 285.78947 | I11: Miscelenious 5% | M11: =SUM(M10*0.05) -> 303.15789
B12: Total Cost | F12: =SUM(F10:F11) -> 6001.5789 | I12: Total Cost | M12: =SUM(M10:M11) -> 6366.3158
B13: Percentage Cost % | F13: =SUM(F12/F14) -> 0.20005263 | I13: Percentage Cost % | M13: =SUM(M12/M14) -> 0.21221053
B14: Selling Price ++ | F14: 30000 | I14: Selling Price ++ | M14: 30000
B16: CAPPUCINO | I16: FLAT WHITE
B17: Ingredients | C17: QTY | E17: Unit Price | F17: Total Price | I17: Ingredients | J17: QTY | L17: Unit Price | M17: Total Price
B18: Coffee bean | C18: 20 | D18: gr | E18: =E7 -> 280 | F18: =SUM(E18*C18) -> 5600 | I18: Coffee bean | J18: 20 | K18: gr | L18: =L7 -> 280 | M18: =SUM(L18*J18) -> 5600
B19: Water | C19: 100 | D19: ml | E19: =E8 -> 1.1578947 | F19: =SUM(E19*C19) -> 115.78947 | I19: Water | J19: 100 | K19: ml | L19: =L8 -> 1.1578947 | M19: =SUM(L19*J19) -> 115.78947
B20: Fresh milk | C20: 250 | D20: ml | E20: ='SUPPLIER & PRICE'!F4 -> 24 | F20: =SUM(E20*C20) -> 6000 | I20: Fresh milk | J20: 250 | K20: ml | L20: =E20 -> 24 | M20: =SUM(L20*J20) -> 6000
B21: Total Qty | C21: 320 | D21: ml | I21: Total Qty | J21: 320 | K21: ml
B22: Garnish | C22: Cookies | F22: 1500 | I22: Garnish | J22: Cookies | M22: 1500
B23: Basic Cost | F23: =SUM(F18:F22) -> 13215.789 | I23: Basic Cost | M23: =SUM(M18:M22) -> 13215.789
B24: Miscelenious 5% | F24: =SUM(F23*0.05) -> 660.78947 | I24: Miscelenious 5% | M24: =SUM(M23*0.05) -> 660.78947
B25: Total Cost | F25: =SUM(F23:F24) -> 13876.579 | I25: Total Cost | M25: =SUM(M23:M24) -> 13876.579
B26: Percentage Cost % | F26: =SUM(F25/F27) -> 0.34691447 | I26: Percentage Cost % | M26: =SUM(M25/M27) -> 0.30836842
B27: Selling Price ++ | F27: 40000 | I27: Selling Price ++ | M27: 45000
B29: LATTE | I29: MATCHA
B30: Ingredients | C30: QTY | E30: Unit Price | F30: Total Price | I30: Ingredients | J30: QTY | L30: Unit Price | M30: Total Price
B31: Coffee bean | C31: 20 | D31: gr | E31: =E18 -> 280 | F31: =SUM(E31*C31) -> 5600 | I31: Matcha powder | J31: 5 | K31: gr | L31: ='SUPPLIER & PRICE'!F127 -> 1080 | M31: =SUM(L31*J31) -> 5400
B32: Water | C32: 100 | D32: ml | E32: =E19 -> 1.1578947 | F32: =SUM(E32*C32) -> 115.78947 | I32: Water | J32: 100 | K32: ml | L32: ='SUPPLIER & PRICE'!F56 -> 1.0526316 | M32: =SUM(L32*J32) -> 105.26316
B33: Fresh milk | C33: 250 | D33: ml | E33: =E20 -> 24 | F33: =SUM(E33*C33) -> 6000 | I33: Fresh milk | J33: 250 | K33: ml | L33: =E33 -> 24 | M33: =SUM(L33*J33) -> 6000
B34: Total Qty | C34: 320 | D34: ml | I34: Total Qty | J34: 320 | K34: ml
B35: Garnish | C35: Cookies | F35: 1500 | I35: Garnish | J35: Cookies | M35: 1500
B36: Basic Cost | F36: =SUM(F31:F35) -> 13215.789 | I36: Basic Cost | M36: =SUM(M31:M35) -> 13005.263
B37: Miscelenious 5% | F37: =SUM(F36*0.05) -> 660.78947 | I37: Miscelenious 5% | M37: =SUM(M36*0.05) -> 650.26316
B38: Total Cost | F38: =SUM(F36:F37) -> 13876.579 | I38: Total Cost | M38: =SUM(M36:M37) -> 13655.526
B39: Percentage Cost % | F39: =SUM(F38/F40) -> 0.30836842 | I39: Percentage Cost % | M39: =SUM(M38/M40) -> 0.34138816
B40: Selling Price ++ | F40: 45000 | I40: Selling Price ++ | M40: 40000
B42: ADDITIONAL SYRUP (HAZELNUT, CARAMEL, VANILLA, BUTTERSCHOTCH) | I42: ADDITIONAL OATMILK
B43: Ingredients | C43: QTY | E43: Unit Price | F43: Total Price | I43: Ingredients | J43: QTY | L43: Unit Price | M43: Total Price
B44: Syrup | C44: 20 | D44: ml | E44: ='SUPPLIER & PRICE'!F147 -> 158.57143 | F44: =SUM(E44*C44) -> 3171.4286 | I44: Oatmilk | J44: 200 | K44: ml | L44: ='SUPPLIER & PRICE'!F6 -> 42 | M44: =SUM(L44*J44) -> 8400
B45: Total Qty | C45: 20 | D45: ml | I45: Total Qty | J45: 200 | K45: ml
B46: Basic Cost | F46: =SUM(F42:F44) -> 3171.4286 | I46: Basic Cost | M46: =SUM(M42:M44) -> 8400
...

Sheet NEW MENU
B2: Cocktail Signature Apero-Mile / Wisdom | H2: ROOTS JUICE | N2: MIX BERRY LEMONADE | T2: MIX BERRY LEMONADE 1liter
B3: Ingredients | C3: QTY | E3: Unit Price | F3: Total Price | H3: Ingredients | I3: QTY | K3: Unit Price | L3: Total Price | N3: Ingredients | O3: QTY | Q3: Unit Price | R3: Total Price | T3: Ingredients | U3: QTY | W3: Unit Price | X3: Total Price
B4: Vodka Chamomile | C4: 45 | D4: ml | E4: =PREPARATION!L18 -> 373.42857 | F4: =SUM(E4*C4) -> 16804.286 | H4: Beetroot | I4: 100 | J4: gr | K4: ='SUPPLIER & PRICE'!F26 -> 40 | L4: =SUM(K4*I4) -> 4000 | N4: Berry cordial | O4: 120 | P4: ml | Q4: =PREPARATION!L117 -> 66.884249 | R4: =SUM(Q4*O4) -> 8026.1099 | T4: Berry cordial | U4: 360 | V4: ml | W4: =PREPARATION!L117 -> 66.884249 | X4: =SUM(W4*U4) -> 24078.33
B5: Aperol | C5: 30 | D5: ml | E5: ='SUPPLIER & PRICE'!F104 -> 580 | F5: =SUM(E5*C5) -> 17400 | H5: Carrot | I5: 100 | J5: gr | K5: ='SUPPLIER & PRICE'!F19 -> 30 | L5: =SUM(K5*I5) -> 3000 | N5: Grape syrup | O5: 20 | P5: ml | Q5: =Q19 -> 158.57143 | R5: =SUM(Q5*O5) -> 3171.4286 | T5: Grape syrup | U5: 60 | V5: ml | W5: =Q5 -> 158.57143 | X5: =SUM(W5*U5) -> 9514.2857
B6: lemon | C6: 20 | D6: ml | E6: ='SUPPLIER & PRICE'!F8 -> 116.66667 | F6: =SUM(E6*C6) -> 2333.3333 | H6: Cucumber | I6: 100 | J6: gr | K6: ='SUPPLIER & PRICE'!F20 -> 10 | L6: =SUM(K6*I6) -> 1000 | N6: Blue berry syrup | O6: 20 | P6: ml | Q6: =Q5 -> 158.57143 | R6: =SUM(Q6*O6) -> 3171.4286 | T6: Blue berry syrup | U6: 60 | V6: ml | W6: =W5 -> 158.57143 | X6: =SUM(W6*U6) -> 9514.2857
B7: Elderflower syrup | C7: 10 | D7: ml | E7: ='SUPPLIER & PRICE'!F138 -> 158.57143 | F7: =SUM(E7*C7) -> 1585.7143 | H7: Ginger | I7: 10 | J7: gr | K7: ='SUPPLIER & PRICE'!F30 -> 35 | L7: =SUM(K7*I7) -> 350 | N7: Lemon jc | O7: 30 | P7: ml | Q7: =Q21 -> 116.66667 | R7: =SUM(Q7*O7) -> 3500 | T7: Lemon jc | U7: 90 | V7: ml | W7: =Q7 -> 116.66667 | X7: =SUM(W7*U7) -> 10500
B8: Honey | C8: 10 | D8: ml | E8: ='SUPPLIER & PRICE'!F31 -> 50 | F8: =SUM(C8*E8) -> 500 | H8: Green apple | I8: 100 | J8: gr | K8: ='SUPPLIER & PRICE'!F27 -> 35 | L8: =SUM(K8*I8) -> 3500 | N8: Polaris soda | O8: 1 | P8: can | Q8: =Q22 -> 5208.3333 | R8: =SUM(Q8*O8) -> 5208.3333 | T8: Polaris soda | U8: 2 | V8: can | W8: =W22 -> 5208.3333 | X8: =SUM(W8*U8) -> 10416.667
B9: Egg | C9: 1 | D9: pcs | E9: 2000 | F9: =SUM(C9*E9) -> 2000 | H9: Kintamani orange | I9: 60 | J9: ml | K9: ='SUPPLIER & PRICE'!F9 -> 66.666667 | L9: =SUM(K9*I9) -> 4000 | N9: Total Qty | O9: 300 | P9: ml | T9: Total Qty | U9: 900 | V9: ml
B10: Total Qty | C10: 200 | D10: ml | H10: Lemon jc | I10: 30 | J10: ml | K10: ='SUPPLIER & PRICE'!F8 -> 116.66667 | L10: =SUM(K10*I10) -> 3500 | N10: Garnish | Q10: lime 10 gr | R10: =R24 -> 180 | T10: Garnish | W10: lime 10 gr | X10: =R10 -> 180
B11: Garnish | E11: angostura | F11: ='SUPPLIER & PRICE'!L6 -> 1485 | H11: Pineapple | I11: 200 | J11: gr | K11: ='SUPPLIER & PRICE'!F16 -> 22.222222 | L11: =SUM(K11*I11) -> 4444.4444 | N11: Basic Cost | R11: =SUM(R4:R10) -> 23257.3 | T11: Basic Cost | X11: =SUM(X4:X10) -> 64203.568
B12: Basic Cost | F12: =SUM(F4:F11) -> 42108.333 | H12: Total Qty | I12: 300 | J12: ml | N12: Miscelenious 5% | R12: =SUM(R11*0.05) -> 1162.865 | T12: Miscelenious 5% | X12: =SUM(X11*0.05) -> 3210.1784
B13: Miscelenious 5% | F13: =SUM(F12*0.05) -> 2105.4167 | H13: Garnish | N13: Total Cost | R13: =SUM(R11:R12) -> 24420.165 | T13: Total Cost | X13: =SUM(X11:X12) -> 67413.746
B14: Total Cost | F14: =SUM(F12:F13) -> 44213.75 | N14: Percentage Cost % | R14: =SUM(R13/R15) -> 0.40700276 | T14: Percentage Cost % | X14: =SUM(X13/X15) -> 0.56178122
B15: Percentage Cost % | F15: =SUM(F14/F16) -> 0.36844792 | H15: Basic Cost | L15: =SUM(L4:L11) -> 23794.444 | N15: Selling Price ++ | R15: 60000 | T15: Selling Price ++ | X15: 120000
B16: Selling Price ++ | F16: 120000 | H16: Miscelenious 5% | L16: =SUM(L15*0.05) -> 1189.7222
H17: Total Cost | L17: =SUM(L15:L16) -> 24984.167 | N17: OSMANTHUS PALOMA LEMONADE | T17: OSMANTHUS PALOMA LEMONADE 1 LITER
B18: Cocktail Signature Starwood | H18: Percentage Cost % | L18: =SUM(L17/L19) -> 0.33312222 | N18: Ingredients | O18: QTY | Q18: Unit Price | R18: Total Price | T18: Ingredients | U18: QTY | W18: Unit Price | X18: Total Price
B19: Ingredients | C19: QTY | E19: Unit Price | F19: Total Price | H19: Selling Price ++ | L19: 75000 | N19: Osmanthus syrup | O19: 30 | P19: ml | Q19: ='SUPPLIER & PRICE'!F139 -> 158.57143 | R19: =SUM(Q19*O19) -> 4757.1429 | T19: Osmanthus syrup | U19: 90 | V19: ml | W19: =Q19 -> 158.57143 | X19: =SUM(W19*U19) -> 14271.429
B20: Jimbeam rosemary | C20: 40 | D20: ml | E20: =PREPARATION!L26 -> 516 | F20: =SUM(E20*C20) -> 20640 | N20: Paloma syrup | O20: 30 | P20: ml | Q20: =Q19 -> 158.57143 | R20: =SUM(Q20*O20) -> 4757.1429 | T20: Paloma syrup | U20: 90 | V20: ml | W20: =W19 -> 158.57143 | X20: =SUM(W20*U20) -> 14271.429
B21: Campari | C21: 20 | D21: ml | E21: ='SUPPLIER & PRICE'!F103 -> 600 | F21: =SUM(E21*C21) -> 12000 | H21: HYDRATE & HEAL | N21: Lemon | O21: 30 | P21: ml | Q21: =E22 -> 116.66667 | R21: =SUM(Q21*O21) -> 3500 | T21: Lemon | U21: 90 | V21: ml | W21: =Q21 -> 116.66667 | X21: =SUM(W21*U21) -> 10500
B22: lemon | C22: 15 | D22: ml | E22: =E6 -> 116.66667 | F22: =SUM(E22*C22) -> 1750 | H22: Ingredients | I22: QTY | K22: Unit Price | L22: Total Price | N22: Polaris soda | O22: 1 | P22: can | Q22: ='SUPPLIER & PRICE'!F68 -> 5208.3333 | R22: =SUM(Q22*O22) -> 5208.3333 | T22: Polaris soda | U22: 2 | V22: can | W22: =Q8 -> 5208.3333 | X22: =SUM(W22*U22) -> 10416.667
B23: Grape syrup | C23: 15 | D23: ml | E23: =E7 -> 158.57143 | F23: =SUM(E23*C23) -> 2378.5714 | H23: Watermelon | I23: 500 | J23: gr | K23: ='SUPPLIER & PRICE'!F12 -> 15 | L23: =SUM(K23*I23) -> 7500 | N23: Total Qty | O23: 300 | P23: ml | T23: Total Qty | U23: 900 | V23: ml
B24: Total Qty | C24: 120 | D24: ml | H24: MInt leave | I24: 10 | J24: gr | K24: ='SUPPLIER & PRICE'!F21 -> 60 | L24: =SUM(K24*I24) -> 600 | N24: Garnish | Q24: lime 10 gr | R24: =ALCOHOL!F123 -> 180 | T24: Garnish | W24: lime 10 gr | X24: =X10 -> 180
B25: Garnish | E25: Sunkist 20 gr | F25: =ALCOHOL!F95 -> 1200 | H25: ginger | I25: 25 | J25: gr | K25: ='SUPPLIER & PRICE'!F30 -> 35 | L25: =SUM(K25*I25) -> 875 | N25: Basic Cost | R25: =SUM(R19:R24) -> 18402.619 | T25: Basic Cost | X25: =SUM(X19:X24) -> 49639.524
B26: Basic Cost | F26: =SUM(F20:F25) -> 37968.571 | H26: Cucumber | I26: 100 | J26: ml | K26: ='SUPPLIER & PRICE'!F20 -> 10 | L26: =SUM(K26*I26) -> 1000 | N26: Miscelenious 5% | R26: =SUM(R25*0.05) -> 920.13095 | T26: Miscelenious 5% | X26: =SUM(X25*0.05) -> 2481.9762
B27: Miscelenious 5% | F27: =SUM(F26*0.05) -> 1898.4286 | H27: Lemon jc | I27: 30 | J27: ml | K27: ='SUPPLIER & PRICE'!F8 -> 116.66667 | L27: =SUM(K27*I27) -> 3500 | N27: Total Cost | R27: =SUM(R25:R26) -> 19322.75 | T27: Total Cost | X27: =SUM(X25:X26) -> 52121.5
B28: Total Cost | F28: =SUM(F26:F27) -> 39867 | H28: Honey | I28: 20 | J28: ml | K28: ='SUPPLIER & PRICE'!F31 -> 50 | L28: =SUM(K28*I28) -> 1000 | N28: Percentage Cost % | R28: =SUM(R27/R29) -> 0.32204583 | T28: Percentage Cost % | X28: =SUM(X27/X29) -> 0.43434583
B29: Percentage Cost % | F29: =SUM(F28/F30) -> 0.332225 | H29: Total Qty | I29: 300 | J29: ml | N29: Selling Price ++ | R29: 60000 | T29: Selling Price ++ | X29: 120000
B30: Selling Price ++ | F30: 120000 | H30: Garnish | K30: MInt 3 gr | L30: 180
H31: Basic Cost | L31: =SUM(L23:L30) -> 14655
B32: Cocktail Signature Grilled cheese / Vodka Cheese / Serenity | H32: Miscelenious 5% | L32: =SUM(L31*0.05) -> 732.75
B33: Ingredients | C33: QTY | E33: Unit Price | F33: Total Price | H33: Total Cost | L33: =SUM(L31:L32) -> 15387.75
B34: Vodka cheese | C34: 20 | D34: ml | E34: =PREPARATION!L35 -> 392.85714 | F34: =SUM(E34*C34) -> 7857.1429 | H34: Percentage Cost % | L34: =SUM(L33/L35) -> 0.20517
B35: Baileys | C35: 15 | D35: ml | E35: ='SUPPLIER & PRICE'!L5 -> 560 | F35: =SUM(E35*C35) -> 8400 | H35: Selling Price ++ | L35: 75000
B36: Amaretto | C36: 15 | D36: ml | E36: ='SUPPLIER & PRICE'!L16 -> 407.14286 | F36: =SUM(E36*C36) -> 6107.1429
B37: Oat milk | C37: 30 | D37: ml | E37: ='SUPPLIER & PRICE'!F6 -> 42 | F37: =SUM(E37*C37) -> 1260
B38: Hazelnut syrup | C38: 5 | D38: ml | E38: =E23 -> 158.57143 | F38: =SUM(C38*E38) -> 792.85714
B39: Total Qty | C39: 100 | D39: ml
B40: Garnish | E40: Grilled cheese | F40: 2500
B41: Basic Cost | F41: =SUM(F34:F40) -> 26917.143
...

Sheet PREPARATION
B1: PREPARATION
B6: PANDAN ICELAND | K6: UNIT PRICE | L6: UNIT PRICE / ML
B8: INGREDIENT | C8: Iceland vodka | D8: 500 ml | K8: ='SUPPLIER & PRICE'!J14 -> 145000
C9: Pandan Leaf | D9: 25 gr | K9: 5000
C10: TOTAL ML | D10: 450 ML | K10: =SUM(K8:K9) -> 150000 | L10: =SUM(K10/450) -> 333.33333
B11: METHOD | C11: Place all ingredients in a vacuum bag. Cook in sous vide for 2 hours at 55 degrees. Cool quickly in the freezer for half an hour. Filter.
B14: VODKA CHAMOMILE | K14: UNIT PRICE | L14: UNIT PRICE / ML
B16: INGREDIENT | C16: Fashion vodka | D16: 750 ml | K16: ='SUPPLIER & PRICE'!D96 -> 246000
C17: Chamomile | D17: 10 gr | K17: 15400
C18: TOTAL ML | D18: 700 ML | K18: =SUM(K16:K17) -> 261400 | L18: =SUM(K18/700) -> 373.42857
B19: METHOD | C19: Place all ingredients in a vacuum bag. Cook in sous vide for 2 hours at 55 degrees. Cool quickly in the freezer for half an hour. Filter.
B22: WHISKY ROSEMARY | K22: UNIT PRICE | L22: UNIT PRICE / ML
B24: INGREDIENT | C24: Jimbeam White | D24: 750 ml | K24: ='SUPPLIER & PRICE'!D78 -> 360000
C25: Rosemary | D25: 8 gr | K25: 1200
C26: TOTAL ML | D26: 700 ML | K26: =SUM(K24:K25) -> 361200 | L26: =SUM(K26/700) -> 516
B27: METHOD | C27: Place all ingredients in a vacuum bag. Cook in sous vide for 2 hours at 55 degrees. Cool quickly in the freezer for half an hour. Filter.
B30: VODKA CHEESE | K30: UNIT PRICE | L30: UNIT PRICE / ML
B32: INGREDIENT | C32: Fashion vodka | D32: 750 ml | K32: =K16 -> 246000
C33: Cheese cream | G33: 100 gr | K33: 15000
C34: Parmesan cheese | D34: 50 gr | K34: 14000
C35: TOTAL ML | D35: 700 ML | K35: =SUM(K32:K34) -> 275000 | L35: =SUM(K35/700) -> 392.85714
B36: METHOD | C36: Place all ingredients in a vacuum bag. Cook in sous vide for 2 hours at 55 degrees. Cool quickly in the freezer for half an hour. Filter.
B40: GIN SESAME OIL | K40: UNIT PRICE | L40: UNIT PRICE / ML
B42: INGREDIENT | C42: Gordons Gin | D42: 350 ml | K42: =+SUM(400*350) -> 140000
C43: Seasame oil | D43: 10 gr | K43: =SUM('SUPPLIER & PRICE'!F150*10) -> 4545.4545
C44: TOTAL ML | D44: 300 ML | K44: =SUM(K42:K43) -> 144545.45 | L44: =SUM(K44/300) -> 481.81818
B45: METHOD | C45: Place all ingredients in a vacuum bag. Cook in sous vide for 2 hours at 80 degrees. Cool quickly in the freezer for 24 an hour. Fast filter.
B49: GORDON GIN EARL GREY | K49: UNIT PRICE | L49: UNIT PRICE / ML
B51: INGREDIENT | C51: Gordons Gin | D51: 350 ml | K51: =K42 -> 140000
C52: Earl Grey Tea Bag | D52: 2 pcs | K52: 5000
C53: TOTAL ML | D53: 300 ML | K53: =SUM(K51:K52) -> 145000 | L53: =SUM(K53/300) -> 483.33333
B54: METHOD | C54: Place 2 teabags in the gin for 40 min. Take them out after squeezing them
B57: LAVANDA SYRUP | K57: UNIT PRICE | L57: UNIT PRICE / ML
B59: INGREDIENT | C59: Soy milk | D59: 1000 ml | K59: ='SUPPLIER & PRICE'!D5 -> 35000
C60: Sugar | D60: 1000 gr | K60: ='SUPPLIER & PRICE'!D28 -> 18000
C61: Water | D61: 300 ml | K61: 300
C62: Lavanda dry | D62: 25 gr | K62: =SUM('SUPPLIER & PRICE'!F148*25) -> 22500
C63: Butterfly flover | D63: 10 gr | K63: =SUM('SUPPLIER & PRICE'!F149*10) -> 9333.3333
C64: TOTAL ML | D64: 1500 ML | K64: =SUM(K59:K63) -> 85133.333 | L64: =SUM(K64/1500) -> 56.755556
B65: METHOD | C65: In a saucepan, place soy milk, sugar and water. Dissolve the sugar, then add the lavender. Leave on the stove for 20 minutes over low heat, stirring occasionally. Add clitoria. Cook for another 10 minutes. Cool and strain.
...

Sheet SUPPLIER & PRICE
B2: SUPPLIER | C2: ITEM | D2: PRICE | E2: REMARK | F2: PRICE IN ML / GRAM | H2: SUPPLIER | I2: ITEM | J2: PRICE | K2: REMARK | L2: PRICE IN ML / GRAM
B4: TOKO BUNGA | C4: Fresh Milk | D4: 24000 | E4: 1 LTR | F4: =SUM(D4/1000) -> 24 | H4: DDW | I4: Kahlua | J4: ='[1]Price List'!$E$110 -> 420000 | K4: 750 ml | L4: =SUM(J4/750) -> 560
C5: Soy Milk | D5: 35000 | E5: 1 LTR | F5: =SUM(D5/1000) -> 35 | I5: Baileys | J5: ='[1]Price List'!$E$111 -> 420000 | K5: 750 ml | L5: =SUM(J5/750) -> 560
C6: Oat Milk | D6: 42000 | E6: 1 LTR | F6: =SUM(D6/1000) -> 42 | I6: Angostura | J6: ='[1]Price List'!$E$5 -> 297000 | K6: 200 ml | L6: =SUM(J6/200) -> 1485
C7: Almond | D7: 48000 | E7: 1 LTR | F7: =SUM(D7/1000) -> 48 | I7: CapeDiscovery | J7: ='[1]Price List'!$E$3 -> 171000 | K7: 750 ml | L7: =SUM(J7/750) -> 228
C8: Lemon | D8: 35000 | E8: 300 ml / 1 KG | F8: =SUM(D8/300) -> 116.66667 | H8: ISOLA | I8: Isola blanco | J8: 154440 | K8: 750 ml | L8: =SUM(J8/750) -> 205.92
C9: Kintamani orange | D9: 20000 | E9: 300 ML / 1KG | F9: =SUM(D9/300) -> 66.666667 | I9: Isola Syrah | J9: 275000 | K9: 750 ml | L9: =SUM(J9/750) -> 366.66667
C10: Sunkist | D10: 35000 | E10: 1 kg | F10: =SUM(D10/1000) -> 35 | H10: SUNSETROAD | I10: Sunsetroad | J10: ='[1]Price List'!$E$82 -> 420000 | K10: 12 btl | L10: =SUM(J10/12) -> 35000
C11: Manggo | D11: 60000 | E11: 1 KG | F11: =SUM(D11/1000) -> 60 | H11: CORONA | I11: Corona | J11: ='[1]Price List'!$E$84 -> 1190000 | K11: 24 btl | L11: ='[1]Price List'!$F$84 -> 49583.333
C12: Watermelon | D12: 15000 | E12: 1 KG | F12: =SUM(D12/1000) -> 15 | H12: TSING TAO | I12: Tsing tao | J12: ='[1]Price List'!$E$83 -> 768000 | K12: 24 btl | L12: ='[1]Price List'!$F$83 -> 32000
C13: Kayu manis | D13: 150000 | E13: 1 kg | F13: =SUM(D13/1000) -> 150 | H13: ALBENS | I13: Albens | J13: ='[1]Price List'!$E$106 -> 750000 | K13: 24 btl | L13: ='[1]Price List'!$F$106 -> 31250
C14: Clove | D14: 200000 | E14: 1 kg | F14: =SUM(D14/1000) -> 200 | H14: VINYARD | I14: Icelan Blacktea | J14: ='[1]Price List'!$E$26 -> 145000 | K14: 500 ml | L14: =SUM(J14/500) -> 290
C15: Star anise | D15: 190000 | E15: 1 kg | F15: =SUM(D15/1000) -> 190 | I15: Robinso gin | J15: 90000 | K15: 350 ml | L15: =SUM(J15/350) -> 257.14286
C16: Pineapple | D16: 10000 | E16: 450 gr | F16: =SUM(D16/450) -> 22.222222 | H16: BOLS | I16: Triple sec | J16: 285000 | K16: 700 ml | L16: =SUM(J16/700) -> 407.14286
C17: Caisin | D17: 22000 | E17: 1 KG | F17: =SUM(D17/1000) -> 22 | I17: Creme de cassis | J17: ='[1]Price List'!$E$4 -> 455000 | K17: 700 ml | L17: ='[1]Price List'!$F$4 -> 650
C18: chlli | D18: ='[2]TOKO BUNGA'!$E$95 -> 15000 | E18: 0,3 KG | F18: =SUM(D18/300) -> 50 | I18: Peach Bols | J18: ='[1]Price List'!$E$4 -> 455000 | K18: 700 ml | L18: ='[1]Price List'!$F$4 -> 650
C19: Carrot | D19: 30000 | E19: 1 KG | F19: =SUM(D19/1000) -> 30 | I19: Banana Bols | J19: ='[1]Price List'!$E$4 -> 455000 | K19: 700 ml | L19: ='[1]Price List'!$F$4 -> 650
C20: Cucumber | D20: 10000 | E20: 1 KG | F20: =SUM(D20/1000) -> 10 | I20: Lychee Bols | J20: ='[1]Price List'!$E$4 -> 455000 | K20: 700 ml | L20: ='[1]Price List'!$F$4 -> 650
C21: Mint Leaf | D21: 60000 | E21: 1 KG | F21: =SUM(D21/1000) -> 60
C22: Banana | D22: 36000 | E22: 12 pcs | F22: =SUM(D22/12) -> 3000
C23: Apple | D23: 35000 | E23: 1 KG | F23: =SUM(D23/1000) -> 35
C24: Lime | D24: 18000 | E24: 1 KG | F24: =SUM(D24/1000) -> 18
C25: Strawberry | D25: 85000 | E25: 1 KG | F25: =SUM(D25/1000) -> 85
C26: Beetroots | D26: 40000 | E26: 1 KG | F26: =SUM(D26/1000) -> 40
C27: Apple Fresh | D27: 35000 | E27: 1 KG | F27: =SUM(D27/1000) -> 35
C28: Sugar | D28: 18000 | E28: 1 KG | F28: =SUM(D28/1000) -> 18
C29: Spinach | D29: 80000 | E29: 1KG | F29: =SUM(D29/1000) -> 80
C30: Ginger | D30: 35000 | E30: 1 kg | F30: =SUM(D30/1000) -> 35
C31: Honey | D31: 35000 | E31: 700 ml | F31: =SUM(D31/700) -> 50
C32: Cinnamon powder | D32: 25000 | E32: 75 gr | F32: =SUM(D32/75) -> 333.33333
C33: Cinnamo stick | D33: 160000 | E33: 1000 gr | F33: =D33/1000 -> 160
C34: Chocolate powder | D34: 55000 | E34: 165 gr | F34: =SUM(D34/165) -> 333.33333
C35: Avocado | D35: 40000 | E35: 1000 gr | F35: =D35/1000 -> 40
C36: Yoghurt | D36: 75000 | E36: 1000 ml | F36: =SUM(D36/1000) -> 75
C37: Protein powder | D37: 25000 | E37: 40 gr | F37: =SUM(D37/40) -> 625
C38: Peanut butter | D38: 60000 | E38: 500 gr | F38: =SUM(D38/500) -> 120
C39: Yakult | D39: 12500 | E39: 5 pcs | F39: =SUM(D39/5) -> 2500
C40: Black Olive | D40: 56000 | E40: 50 pcs | F40: =SUM(D40/50) -> 1120
C41: Tea sariwangi | D41: 25000 | E41: 100 PCS | F41: =SUM(D41/100) -> 250
C42: Cheese cream | D42: 150000 | E42: 1 kg | F42: =SUM(D42/1000) -> 150
...
