Workbook

Sheet BUK BUNGA (Groceries)
A1: DATE | B1: ITEM | C1: QYT | D1: PRICE | E1: SUBTOTAL | F1: TOTAL
E2: =D2*C2 -> 0
E3: =D3*C3 -> 0
E4: =D4*C4 -> 0
E5: =D5*C5 -> 0
E6: =D6*C6 -> 0
E7: =D7*C7 -> 0
E8: =D8*C8 -> 0
E9: =D9*C9 -> 0
E10: =D10*C10 -> 0
E11: =D11*C11 -> 0
E12: =D12*C12 -> 0
E13: =D13*C13 -> 0
... E17: =D17*C17 -> 0
E541: =D541*C541 -> 0 | F541: =SUM(F2:F540) -> 0

Sheet SEDANA JAYA (Groceries)
A1: DATE | B1: ITEM | C1: QYT | D1: PRICE | E1: SUBTOTAL | F1: TOTAL | G1: OUTSTANDING STATUS CHECK
F667: =SUM(F2:F666) -> 0

Sheet AD supplier (Groceries)
A1: DATE | B1: ITEM | C1: QYT | D1: PRICE | E1: SUBTOTAL | F1: TOTAL | G1: BILLS
E2: =D2*C2 -> 0 | F2: =SUM(E2:E7) -> 0
E3: =D3*C3 -> 0
E4: =D4*C4 -> 0
E5: =D5*C5 -> 0
E6: =D6*C6 -> 0
E7: =D7*C7 -> 0
E8: =D8*C8 -> 0 | F8: =SUM(E8:E10) -> 0
E9: =D9*C9 -> 0
E10: =D10*C10 -> 0
F21: =SUM(F2:F20) -> 0

Sheet RAFI SEAFOOD (Seafood)
A1: DATE | B1: DESCRIPTION | C1: QUANTITY | D1: PRICE | E1: BILLS | F1: SUBTOTAL | G1: TOTAL
F2: =SUM(C2*D2) -> 0 | G2: =SUM(F2:F6) -> 0
F3: =SUM(C3*D3) -> 0
F4: =SUM(C4*D4) -> 0
F5: =SUM(C5*D5) -> 0
F6: =SUM(C6*D6) -> 0
F7: =SUM(C7*D7) -> 0 | G7: =SUM(F7) -> 0
F8: =SUM(C8*D8) -> 0 | G8: =SUM(F8:F9) -> 0
F9: =SUM(C9*D9) -> 0
F10: =SUM(C10*D10) -> 0 | G10: =SUM(F10:F12) -> 0
F11: =SUM(C11*D11) -> 0
F12: =SUM(C12*D12) -> 0
F13: =SUM(C13*D13) -> 0 | G13: =SUM(F13:F17) -> 0
F14: =C14*D14 -> 0
F15: =C15*D15 -> 0
F16: =SUM(C16*D16) -> 0
F17: =SUM(C17*D17) -> 0
F18: =SUM(C18*D18) -> 0 | G18: =SUM(F18) -> 0
F19: =SUM(C19*D19) -> 0 | G19: =SUM(F19:F20) -> 0
F20: =SUM(C20*D20) -> 0
F21: =SUM(C21*D21) -> 0 | G21: =SUM(F21:F26) -> 0
F22: =SUM(C22*D22) -> 0
F23: =SUM(C23*D23) -> 0
F24: =SUM(C24*D24) -> 0
F25: =SUM(C25*D25) -> 0
F26: =SUM(C26*D26) -> 0
F27: =SUM(C27*D27) -> 0 | G27: =SUM(F27:F28) -> 0
F28: =SUM(C28*D28) -> 0
F29: =SUM(C29*D29) -> 0 | G29: =SUM(F29) -> 0
F30: =SUM(C30*D30) -> 0 | G30: =SUM(F30:F32) -> 0
F31: =C31*D31 -> 0
F32: =C32*D32 -> 0
F33: =C33*D33 -> 0 | G33: =SUM(F33:F37) -> 0
F34: =SUM(C34*D34) -> 0
F35: =SUM(C35*D35) -> 0
F36: =SUM(C36*D36) -> 0
F37: =SUM(C37*D37) -> 0
F38: =SUM(C38*D38) -> 0 | G38: =SUM(F38:F41) -> 0
F39: =SUM(C39*D39) -> 0
F40: =SUM(C40*D40) -> 0
...

Sheet MAMA RADA PRODUCTION (Dumpling)
A1: DATE | B1: INV NO. | C1: DESCRIPTIONS | D1: QTY | E1: BIILS | F1: PRICE | G1: SUBTOTAL | H1: TOTAL
G2: =D2*F2 -> 0 | H2: =SUM(G2) -> 0
G3: =SUM(D3*F3+D4*F4) -> 0
G5: =SUM(D5*F5+D6*F6+D7*F7) -> 0
G8: =SUM(D8*F8) -> 0
E12: GRAND TOTAL | H12: =SUM(H2:H11) -> 0

Sheet KSP (Chicken)
A1: DATE | B1: INV NO. | C1: DESCRIPTIONS | D1: QTY | E1: BILLS | F1: PRICE | G1: SUB TOTAL | H1: TOTAL
G2: =SUM(D2*F2) -> 0 | H2: =SUM(G2:G4) -> 0
G3: =SUM(D3*F3) -> 0
G4: =SUM(D4*F4) -> 0
G5: =SUM(D5*F5) -> 0 | H5: =SUM(G5:G6) -> 0
G6: =SUM(D6*F6) -> 0
G7: =SUM(D7*F7) -> 0 | H7: =SUM(G7:G8) -> 0
G8: =SUM(D8*F8) -> 0
G9: =D9*F9 -> 0 | H9: =SUM(G9:G11) -> 0
G10: =D10*F10 -> 0
G11: =D11*F11 -> 0
G12: =D12*F12 -> 0
H13: =SUM(H2:H12) -> 0

Sheet SURYA CIPTA NIAGA BALI (Beef)
A1: DATE | B1: INV NO. | C1: DESCRIPTIONS | D1: QTY | E1: BILLS | F1: PRICE | G1: SUBTOTAL | H1: TOTAL | I1: STATUS
H4: =SUM(G4:G5) -> 0
H6: =SUM(G6:G7) -> 0
G9: =D9*F9 -> 0 | H9: =SUM(D9*F9) -> 0
A10: TOTAL | G10: =SUM(H3:H9) -> 0

Sheet BAYU AGNI MERTA (Gas)
A1: DATE | B1: INV NO. | C1: DESCRIPTIONS | D1: QTY | E1: BILLS | F1: PRICE | G1: TOTAL
G2: =SUM(D2*F2) -> 0
G3: =D3*F3 -> 0
A4: TOTAL | E4: =SUM(G2:G3) -> 0

Sheet Joy Green (Mix Berry)
A1: NO | B1: DATE | C1: TOTAL | D1: PC | E1: STATUS
A3: Total | D3: =SUM(C2:C2) -> 0

Sheet CELEBRITY BAKERY (Bakery)
A1: DATE | B1: INV.NO | C1: DESCRIPTION | D1: QTY | E1: BILLS | F1: PRICE | G1: SUBTOTAL | H1: TOTAL
G2: =F2*D2 -> 0 | H2: =SUM(G2:G3) -> 0
G3: =F3*D3 -> 0
A5: TOTAL | E5: =SUM(H2:H4) -> 0

Sheet Krop (Edible flower)
A1: DATE | B1: INV.NO | C1: DESCRIPTION | D1: QTY | E1: BILLS | F1: PRICE | G1: SUBTOTAL | H1: TOTAL
G2: =D2*F2 -> 0 | H2: =SUM(G2:G5) -> 0
G3: =D3*F3 -> 0
G4: =D4*F4 -> 0
G5: =D5*F5 -> 0
G6: =D6*F6 -> 0 | H6: =SUM(G6:G9) -> 0
G7: =D7*F7 -> 0
G8: =D8*F8 -> 0
G9: =D9*F9 -> 0
A10: TOTAL | H10: =SUM(H2:H9) -> 0

Sheet Boiler (Dumplings&Syrniki)
A1: DATE | B1: INV.NO | C1: DESCRIPTION | D1: QTY | E1: BILLS | F1: PRICE | G1: SUBTOTAL | H1: TOTAL | I1: TOTAL AFTER TAX
G2: =D2*F2 -> 0 | H2: =SUM(G2:G4) -> 0 | I2: =(H2*10%)+H2 -> 0
G3: =D3*F3 -> 0
G4: =D4*F4 -> 0
A5: TOTAL | E5: =SUM(I2:I4) -> 0

Sheet Abdi Jaya (TKW, Vacuum Bag)
A1: DATE | B1: INV.NO | C1: DESCRIPTION | D1: QTY | E1: BILLS | F1: PRICE | G1: SUBTOTAL | H1: TOTAL
G2: =D2*F2 -> 0 | H2: =SUM(G2:G4) -> 0
G3: =D3*F3 -> 0
G4: =D4*F4 -> 0
G5: =D5*F5 -> 0 | H5: =SUM(G5:G14) -> 0
G6: =D6*F6 -> 0
G7: =D7*F7 -> 0
G8: =D8*F8 -> 0
G9: =D9*F9 -> 0
G10: =D10*F10 -> 0
G11: =D11*F11 -> 0
G12: =D12*F12 -> 0
G13: =D13*F13 -> 0
G14: =D14*F14 -> 0
G15: =D15*F15 -> 0 | H15: =SUM(G15:G17) -> 0
G16: =D16*F16 -> 0
G17: =D17*F17 -> 0
G18: =D18*F18 -> 0 | H18: =SUM(G18:G20) -> 0
G19: =D19*F19 -> 0
G20: =D20*F20 -> 0
A21: GRAND TOTAL | F21: =SUM(H2:H20) -> 0

Sheet Dishy Soap (Chemicals)
A1: DATE | B1: DESCRIPTION | C1: QTY | D1: BILLS | E1: PRICE | F1: SUBTOTAL | G1: TOTAL
F2: =C2*E2 -> 0 | G2: =SUM(F2:F2) -> 0
F3: =C3*E3 -> 0 | G3: =SUM(F3:F8) -> 0
F4: =C4*E4 -> 0
F5: =C5*E5 -> 0
F6: =C6*E6 -> 0
F7: =C7*E7 -> 0
F8: =C8*E8 -> 0
F9: =C9*E9 -> 0 | G9: =SUM(F9:F10) -> 0
F10: =C10*E10 -> 0
A11: GRAND TOTAL | G11: =SUM(G2:G10) -> 0

Sheet TOTAL
A1: SUPPLIER | B1: Total
A2: BU BUNGA | B2: ='BUK BUNGA (Groceries)'!F541 -> 0
A3: SEDANA JAYA | B3: ='SEDANA JAYA (Groceries)'!F667 -> 0
A4: RAFI SEAFOOD | B4: ='RAFI SEAFOOD (Seafood)'!D61 -> 0
A5: MAMA RADA PRODUCTION | B5: ='MAMA RADA PRODUCTION (Dumpling)'!H12 -> 0
A6: KSP | B6: ='KSP (Chicken)'!H13 -> 0
A7: SURYA CIPTA NIAGA BALI | B7: ='SURYA CIPTA NIAGA BALI (Beef)'!G10 -> 0
A8: BAYU AGNI MERTA | B8: ='BAYU AGNI MERTA (Gas)'!E4 -> 0
A9: JOY GREEN | B9: ='Joy Green (Mix Berry)'!D3 -> 0
A10: CELEBRITY BAKERY | B10: ='CELEBRITY BAKERY (Bakery)'!E5 -> 0
A11: KROP NATIION | B11: ='Krop (Edible flower)'!H10 -> 0
A12: BOILER | B12: ='Boiler (Dumplings&Syrniki)'!E5 -> 0
A13: ABDI JAYA | B13: ='Abdi Jaya (TKW, Vacuum Bag)'!D21 -> 0
A14: DISHY SOAP | B14: ='Dishy Soap (Chemicals)'!G11 -> 0
A15: TOTAL | B15: =SUM(B2:B12) -> 0
