Workbook

Sheet TEGAL JAYA (Bar Groceries)
A1: DATE | B1: INV NO. | C1: ITEM | D1: QYT | E1: PRICE | F1: SUBTOTAL | G1: TOTAL | H1: =SUM(G:G) -> 2853400
A2: 46097 | B2: 8210 | C2: KINTAMANI ORANGE | D2: 4.1 | E2: 25000 | F2: =E2*D2 -> 102500 | G2: =SUM(F2:F12) -> 553100
C3: LEMON | D3: 2 | E3: 45000 | F3: =E3*D3 -> 90000
C4: CARROT | D4: 1.1 | E4: 20000 | F4: =E4*D4 -> 22000
C5: CUCUMBER | D5: 1 | E5: 20000 | F5: =E5*D5 -> 20000
C6: ENGLISH SPINACH | D6: 0.3 | E6: 50000 | F6: =E6*D6 -> 15000
C7: BANANA | D7: 3.7 | E7: 18000 | F7: =E7*D7 -> 66600
C8: WATERMELON | D8: 3 | E8: 13000 | F8: =E8*D8 -> 39000
C9: FRESH MILK | D9: 3 | E9: 35000 | F9: =E9*D9 -> 105000
C10: STRAWBERRY | D10: 0.5 | E10: 85000 | F10: =E10*D10 -> 42500
C11: LIME | D11: 0.5 | E11: 15000 | F11: =E11*D11 -> 7500
C12: CHOCOLATE POWDER | D12: 1 | E12: 43000 | F12: =E12*D12 -> 43000
A13: 46106 | B13: 8548 | C13: HONEY PINEAPPLE | D13: 8 | E13: 12000 | F13: =E13*D13 -> 96000 | G13: =SUM(F13:F21) -> 530000
C14: SUNKIST | D14: 1 | E14: 55000 | F14: =E14*D14 -> 55000
C15: IMPORTED LEMON | D15: 2 | E15: 45000 | F15: =E15*D15 -> 90000
C16: ORANGE | D16: 2 | E16: 26000 | F16: =E16*D16 -> 52000
C17: STRAWBERRY | D17: 1 | E17: 85000 | F17: =E17*D17 -> 85000
C18: ROSEMARY | D18: 0.2 | E18: 120000 | F18: =E18*D18 -> 24000
C19: BASIL | D19: 0.2 | E19: 65000 | F19: =E19*D19 -> 13000
C20: SARIWANGI | D20: 1 | E20: 40000 | F20: =E20*D20 -> 40000
C21: CHOCOLATE POWDER | D21: 1 | E21: 75000 | F21: =E21*D21 -> 75000
A22: 46107 | B22: 8595 | C22: FRESH MILK | D22: 8 | E22: 30000 | F22: =E22*D22 -> 240000 | G22: =SUM(F22:F30) -> 774400
C23: OAT MILK | D23: 1 | E23: 60000 | F23: =E23*D23 -> 60000
C24: BLACK OLIVE | D24: 1 | E24: 70000 | F24: =E24*D24 -> 70000
C25: LIME | D25: 0.3 | E25: 18000 | F25: =E25*D25 -> 5400
C26: STRAWBERRY | D26: 1 | E26: 80000 | F26: =E26*D26 -> 80000
C27: PANDAN LEAVES | D27: 0.25 | E27: 20000 | F27: =E27*D27 -> 5000
C28: HONEY PINEAPPLE | D28: 12 | E28: 12000 | F28: =E28*D28 -> 144000
C29: KINTAMANI ORANGE | D29: 5 | E29: 25000 | F29: =E29*D29 -> 125000
C30: IMPORTED LEMON | D30: 1 | E30: 45000 | F30: =E30*D30 -> 45000
A31: 46108 | B31: 8633 | C31: SUNKIST | D31: 1.1 | E31: 45000 | F31: =E31*D31 -> 49500 | G31: =SUM(F31:F38) -> 347900
C32: IMPORTED LEMON | D32: 1 | E32: 45000 | F32: =E32*D32 -> 45000
C33: KINTAMANI ORANGE | D33: 3.1 | E33: 25000 | F33: =E33*D33 -> 77500
C34: MANGO | D34: 1.2 | E34: 70000 | F34: =E34*D34 -> 84000
C35: BANANA | D35: 1.8 | E35: 18000 | F35: =E35*D35 -> 32400
C36: MUSTARD GREEN | D36: 0.5 | E36: 25000 | F36: =E36*D36 -> 12500
C37: WATERMELON | D37: 3 | E37: 13000 | F37: =E37*D37 -> 39000
C38: LIME | D38: 0.5 | E38: 16000 | F38: =E38*D38 -> 8000
A39: 46109 | B39: 8688 | C39: SUNKIST | D39: 1 | E39: 45000 | F39: =E39*D39 -> 45000 | G39: =SUM(F39:F43) -> 220500
C40: KINTAMANI ORANGE | D40: 2.1 | E40: 25000 | F40: =E40*D40 -> 52500
...

Sheet BUK BUNGA BAR (Groceries)
A1: DATE | B1: ITEM | C1: QYT | D1: PRICE | E1: SUB TOTAL | F1: TOTAL | G1: =SUM(F:F) -> 15397000
A2: 46082 | B2: SUNKIST | C2: 1 | D2: 40000 | E2: =D2*C2 -> 40000 | F2: =SUM(E2:E6) -> 390000
B3: IMPORTED LEMON | C3: 1 | D3: 70000 | E3: =D3*C3 -> 70000
B4: KINTAMANI ORANGE | C4: 2 | D4: 35000 | E4: =D4*C4 -> 70000
B5: MANGO | C5: 3 | D5: 50000 | E5: =D5*C5 -> 150000
B6: WHITE SUGAR | C6: 3 | D6: 20000 | E6: =D6*C6 -> 60000
A7: 46083 | B7: HONEY PINEAPPLE | C7: 6 | D7: 10000 | E7: =D7*C7 -> 60000 | F7: =SUM(E7:E15) -> 631000
B8: IMPORTED LEMON | C8: 1 | D8: 70000 | E8: =D8*C8 -> 70000
B9: KINTAMANI ORANGE | C9: 3 | D9: 35000 | E9: =D9*C9 -> 105000
B10: WATERMELON | C10: 3.955 | D10: 16000 | E10: 63000
B11: GREEN MUSTARD | C11: 0.3 | D11: 20000 | E11: =D11*C11 -> 6000
B12: MINT LEAVES | C12: 0.2 | D12: 70000 | E12: =D12*C12 -> 14000
B13: FRESH MILK (GREENFIELDS) | C13: 6 | D13: 24000 | E13: =D13*C13 -> 144000
B14: OAT MILK | C14: 3 | D14: 40000 | E14: =D14*C14 -> 120000
B15: ALMOND MILK | C15: 1 | D15: 49000 | E15: =D15*C15 -> 49000
A16: 46084 | B16: KINTAMANI ORANGE | C16: 5 | D16: 35000 | E16: =D16*C16 -> 175000 | F16: =SUM(E16:E28) -> 770000
B17: IMPORTED LEMON | C17: 2 | D17: 70000 | E17: =D17*C17 -> 140000
B18: HONEY PINEAPPLE | C18: 2 | D18: 10000 | E18: =D18*C18 -> 20000
B19: CARROT | C19: 0.5 | D19: 30000 | E19: =D19*C19 -> 15000
B20: MANGO | C20: 1.14 | D20: 50000 | E20: =D20*C20 -> 57000
B21: BEET ROOT | C21: 0.64 | D21: 45000 | E21: 29000
B22: AVOCADO | C22: 0.67 | D22: 40000 | E22: 27000
B23: BASIL | C23: 0.3 | D23: 60000 | E23: =D23*C23 -> 18000
B24: LIME | C24: 0.3 | D24: 20000 | E24: =D24*C24 -> 6000
B25: STRAWBERRY | C25: 0.5 | D25: 100000 | E25: =D25*C25 -> 50000
B26: FRESH MILK (GREENFIELDS) | C26: 5 | D26: 24000 | E26: =D26*C26 -> 120000
B27: OAT MILK | C27: 2 | D27: 40000 | E27: =D27*C27 -> 80000
B28: HONEY BLOSSOM | C28: 1 | D28: 33000 | E28: =D28*C28 -> 33000
A29: 46085 | B29: KINTAMANI ORANGE | C29: 5 | D29: 35000 | E29: =D29*C29 -> 175000 | F29: =SUM(E29:E38) -> 879000
B30: IMPORTED LEMON | C30: 2.13 | D30: 70000 | E30: 149000
B31: HONEY PINEAPPLE | C31: 4 | D31: 10000 | E31: =D31*C31 -> 40000
B32: GREEN APPLE | C32: 2 | D32: 55000 | E32: =D32*C32 -> 110000
B33: LIME | C33: 0.3 | D33: 30000 | E33: =D33*C33 -> 9000
B34: FRESH MILK (GREENFIELDS) | C34: 5 | D34: 24000 | E34: =D34*C34 -> 120000
B35: OAT MILK | C35: 2 | D35: 40000 | E35: =D35*C35 -> 80000
B36: YOGHURT | C36: 1 | D36: 95000 | E36: =D36*C36 -> 95000
B37: AVOCADO | C37: 0.65 | D37: 40000 | E37: =D37*C37 -> 26000
B38: PEANUT BUTTER (SKIPPY) | C38: 1 | D38: 75000 | E38: =D38*C38 -> 75000
A39: 46086 | B39: KINTAMANI ORANGE | C39: 4 | D39: 35000 | E39: =D39*C39 -> 140000 | F39: =SUM(E39:E50) -> 759000
B40: HONEY PINEAPPLE | C40: 6 | D40: 10000 | E40: =D40*C40 -> 60000
...

Sheet WARUNG EKA (Drinks, Etc)
A1: INV NO | B1: DATE | C1: ITEM | D1: QYT | E1: PRICE | F1: SUBTOTAL | G1: TOTALPRICE | H1: =SUM(G:G) -> 9985000
A2: 80280 | B2: 46082 | C2: CRYSTAL ICE 5 KG | D2: 4 | E2: 8000 | F2: =E2*D2 -> 32000 | G2: =SUM(F2:F4) -> 76000
C3: AQUA GALLOON 19 LTR | D3: 1 | E3: 21000 | F3: =E3*D3 -> 21000
C4: CLEO GALLOON 19 LTR | D4: 1 | E4: 23000 | F4: =E4*D4 -> 23000
A5: 80349 | B5: 46083 | C5: CRYSTAL ICE 5 KG | D5: 6 | E5: 8000 | F5: =E5*D5 -> 48000 | G5: =SUM(F5:F7) -> 92000
C6: AQUA GALLOON 19 LTR | D6: 1 | E6: 21000 | F6: =E6*D6 -> 21000
C7: CLEO GALLOON 19 LTR | D7: 1 | E7: 23000 | F7: =E7*D7 -> 23000
A8: 80420 | B8: 46084 | C8: AQUA REFLECTIONS STILL 380 ML | D8: 1 | E8: 125000 | F8: =E8*D8 -> 125000 | G8: =SUM(F8:F13) -> 446000
C9: AQUA REFLECTIONS SPARKLING 750 ML | D9: 1 | E9: 120000 | F9: =E9*D9 -> 120000
C10: POLARIS SODA WATER CAN 330 ML | D10: 1 | E10: 125000 | F10: =E10*D10 -> 125000
C11: CRYSTAL ICE 5 KG | D11: 4 | E11: 8000 | F11: =E11*D11 -> 32000
C12: CLEO GALLOON 19 LTR | D12: 1 | E12: 23000 | F12: =E12*D12 -> 23000
C13: AQUA GALLOON 19 LTR | D13: 1 | E13: 21000 | F13: =E13*D13 -> 21000
A14: 80483 | B14: 46085 | C14: CRYSTAL ICE 5 KG | D14: 4 | E14: 8000 | F14: =E14*D14 -> 32000 | G14: =SUM(F14:F16) -> 99000
C15: AQUA GALLOON 19 LTR | D15: 1 | E15: 21000 | F15: =E15*D15 -> 21000
C16: CLEO GALLOON 19 LTR | D16: 2 | E16: 23000 | F16: =E16*D16 -> 46000
A17: 80563 | B17: 46086 | C17: AQUA REFLECTIONS STILL 750 ML | D17: 2 | E17: 115000 | F17: =E17*D17 -> 230000 | G17: =SUM(F17:F22) -> 885000
C18: CLEO GALLOON 19 LTR | D18: 1 | E18: 23000 | F18: =E18*D18 -> 23000
C19: AQUA GALLOON 19 LTR | D19: 1 | E19: 21000 | F19: =E19*D19 -> 21000
C20: POLARIS SODA WATER CAN 330 ML | D20: 1 | E20: 125000 | F20: =E20*D20 -> 125000
C21: BINTANG PINT 330 ML | D21: 1 | E21: 480000 | F21: =E21*D21 -> 480000
C22: EMPTY BOTTLE CHARGE | D22: 4 | E22: 1500 | F22: =E22*D22 -> 6000
A23: 80583 | B23: 46086 | C23: CRYSTAL ICE 5 KG | D23: 5 | E23: 8000 | F23: =E23*D23 -> 40000 | G23: =SUM(F23) -> 40000
A24: 80626 | B24: 46087 | C24: AQUA GALLOON 19 LTR | D24: 2 | E24: 21000 | F24: =E24*D24 -> 42000 | G24: =SUM(F24:F27) -> 240000
C25: CLEO GALLOON 19 LTR | D25: 1 | E25: 23000 | F25: =E25*D25 -> 23000
C26: CRYSTAL ICE 5 KG | D26: 5 | E26: 8000 | F26: =E26*D26 -> 40000
C27: COCA-COLA CAN 330 ML | D27: 1 | E27: 135000 | F27: =E27*D27 -> 135000
A28: 80705 | B28: 46088 | C28: CLEO GALLOON 19 LTR | D28: 1 | E28: 23000 | F28: =E28*D28 -> 23000 | G28: =SUM(F28:F30) -> 76000
C29: AQUA GALLOON 19 LTR | D29: 1 | E29: 21000 | F29: =E29*D29 -> 21000
C30: CRYSTAL ICE 5 KG | D30: 4 | E30: 8000 | F30: =E30*D30 -> 32000
A31: 80780 | B31: 46089 | C31: AQUA REFLECTIONS STILL 750 ML | D31: 3 | E31: 115000 | F31: =E31*D31 -> 345000 | G31: =SUM(F31:F33) -> 390000
C32: CRYSTAL ICE 5 KG | D32: 3 | E32: 8000 | F32: =E32*D32 -> 24000
C33: AQUA GALLOON 19 LTR | D33: 1 | E33: 21000 | F33: =E33*D33 -> 21000
A34: 80860 | B34: 46090 | C34: CRYSTAL ICE 5 KG | D34: 5 | E34: 8000 | F34: =E34*D34 -> 40000 | G34: =SUM(F34:F38) -> 324000
C35: POLARIS SODA WATER CAN 330 ML | D35: 1 | E35: 125000 | F35: =E35*D35 -> 125000
C36: AQUA REFLECTIONS STILL 750 ML | D36: 1 | E36: 115000 | F36: =E36*D36 -> 115000
C37: AQUA GALLOON 19 LTR | D37: 1 | E37: 21000 | F37: =E37*D37 -> 21000
C38: CLEO GALLOON 19 LTR | D38: 1 | E38: 23000 | F38: =E38*D38 -> 23000
A39: 80934 | B39: 46091 | C39: CRYSTAL ICE 5 KG | D39: 5 | E39: 8000 | F39: =E39*D39 -> 40000 | G39: =SUM(F39:F41) -> 84000
C40: AQUA GALLOON 19 LTR | D40: 1 | E40: 21000 | F40: =E40*D40 -> 21000
...

Sheet DEWATA COCONUT (Coconut)
A1: DATE | B1: INV NO. | C1: DESCRIPTIONS | D1: QTY | E1: BILLS | F1: PRICE | G1: TOTAL | H1: =E14 -> 1870000
A2: 46083 | B2: 13742 | C2: COCONUT LOGO | D2: 20 | F2: 12000 | G2: =F2*D2 -> 240000
A3: 46087 | B3: 13320 | C3: COCONUT LOGO | D3: 20 | F3: 12000 | G3: =F3*D3 -> 240000
A4: 46090 | B4: 13298 | C4: COCONUT LOGO | D4: 10 | F4: 12000 | G4: =F4*D4 -> 120000
A5: 46092 | B5: 13505 | C5: COCONUT LOGO | D5: 10 | F5: 13000 | G5: =F5*D5 -> 130000
A6: 46094 | B6: 13575 | C6: COCONUT LOGO | D6: 10 | F6: 12000 | G6: =F6*D6 -> 120000
A7: 46096 | B7: 13711 | C7: COCONUT LOGO | D7: 10 | F7: 12000 | G7: =F7*D7 -> 120000
A8: 46098 | B8: 13619 | C8: COCONUT LOGO | D8: 50 | F8: 13000 | G8: =F8*D8 -> 650000
A9: 46106 | B9: 13784 | C9: COCONUT LOGO | D9: 10 | F9: 13000 | G9: =F9*D9 -> 130000
A10: 46110 | B10: 13149 | C10: COCONUT LOGO | D10: 10 | F10: 12000 | G10: =F10*D10 -> 120000
E14: =SUM(G2:G13) -> 1870000

Sheet SEDANA JAYA
A1: DATE | B1: ITEM | C1: QYT | D1: PRICE | E1: TOTAL PRICE | F1: TOTAL
F47: =SUM(F2:F46) -> 0

Sheet PNB (Alcohol)
A1: DATE | B1: INV NO. | C1: DESCRIPTIONS | D1: QTY | E1: BILLS | F1: UNIT PRICE | G1: SUB TOTAL | H1: TOTAL | I1: =H7 -> 1120000
A2: 46097 | B2: SPNB26031443 | C2: LIMO APERITIVO 500 ML | D2: 4 | F2: 280000 | G2: =F2*D2 -> 1120000 | H2: =SUM(G2) -> 1120000
H7: =SUM(H2:H6) -> 1120000

Sheet DSP (Alcohol)
A1: DATE | B1: INV NO. | C1: DESCRIPTIONS | D1: QTY | E1: PRICE | F1: DISCOUNT | G1: UNIT PRICE | H1: SUBTOTAL | I1: TOTAL | J1: BILL | K1: =F16 -> 2647500
A2: 46084 | B2: SOMDG/DSP/26/03/0014 | C2: MDG - F VODKA | D2: 2 | E2: 246000 | F2: 0 | G2: =E2-F2 -> 246000 | H2: =SUM(D2*G2) -> 492000 | I2: =SUM(H2) -> 492000
A3: 46104 | B3: SODSP/DSP/26/03/1316 | C3: DA VINCI LEONARDO PROSECCO DOC | D3: 2 | E3: 370000 | F3: =E3*10% -> 37000 | G3: =E3-F3 -> 333000 | H3: =SUM(D3*G3) -> 666000 | I3: =SUM(H3) -> 666000
A4: 46107 | B4: SO/DSP/26/03/1559 | C4: MCGUIGAN - BLACK LABEL SAUVIGNON BLANC | D4: 3 | E4: 295000 | F4: =E4*10% -> 29500 | G4: =E4-F4 -> 265500 | H4: =SUM(D4*G4) -> 796500 | I4: =SUM(H4:H5) -> 1489500
C5: HUNTER'S RIESLING | D5: 2 | E5: 385000 | F5: =E5*10% -> 38500 | G5: =E5-F5 -> 346500 | H5: =SUM(D5*G5) -> 693000
F6: =E6*10% -> 0 | H6: =SUM(D6*G6) -> 0
F7: =E7*10% -> 0 | H7: =SUM(D7*G7) -> 0
F8: =E8*10% -> 0 | H8: =SUM(D8*G8) -> 0
F9: =E9*10% -> 0 | H9: =SUM(D9*G9) -> 0
F10: =E10*10% -> 0 | H10: =SUM(D10*G10) -> 0
F11: =E11*10% -> 0 | H11: =SUM(D11*G11) -> 0
F12: =E12*10% -> 0 | H12: =SUM(D12*G12) -> 0
F13: =E13*10% -> 0 | H13: =SUM(D13*G13) -> 0
F14: =E14*10% -> 0 | H14: =SUM(D14*G14) -> 0
F15: =E15*10% -> 0 | H15: =SUM(D15*G15) -> 0
A16: TOTAL | F16: =SUM(I2:I15) -> 2647500

Sheet DSP ARYA BIMA (Alcohol)
A1: DATE | B1: INV NO. | C1: DESCRIPTIONS | D1: QTY | E1: BILLS | F1: PRICE | G1: TOTAL | H1: =E3 -> 0
G2: =F2*D2 -> 0
A3: TOTAL | E3: =SUM(G2) -> 0

Sheet SELERA OR STIR UP (Syrup)
A1: DATE | B1: INV NO. | C1: DESCRIPTIONS | D1: QTY | E1: BILLS | F1: PRICE | G1: SUBTOTAL | H1: TOTAL | I1: =F12 -> 2886000
A2: 46083 | B2: SO.03-260091 | C2: KOOL KIWI PET 800 ML | D2: 7 | F2: 100000 | G2: =D2*F2 -> 700000 | H2: =SUM(G2:G2) -> 700000
A3: SUB TOTAL | D3: =SUM(D2:D2) -> 7 | F3: PPN (11%) | H3: =H2*11% -> 77000
A4: TOTAL | E4: =SUM(H2:H3) -> 777000
A5: 46093 | B5: SO.03-260108 | C5: MARVELOUSE MANGO PET 800 ML | D5: 4 | F5: 100000 | G5: =D5*F5 -> 400000 | H5: =SUM(G5:G9) -> 1900000
C6: PARADIESE PEACH PET 800 ML | D6: 6 | F6: 100000 | G6: =D6*F6 -> 600000
C7: VOILA VANILLA 700 ML | D7: 2 | F7: 100000 | G7: =D7*F7 -> 200000
C8: PRECIOUS POMELO PET 800 ML | D8: 2 | F8: 100000 | G8: =D8*F8 -> 200000
C9: CHEERFUL AMARENA CHERRY 700 ML | D9: 5 | F9: 100000 | G9: =D9*F9 -> 500000
A10: SUB TOTAL | D10: =SUM(D5:D9) -> 19 | F10: PPN (11%) | H10: =H5*11% -> 209000
A11: TOTAL | E11: =SUM(H5:H10) -> 2109000
E12: GRAND TOTAL | F12: =SUM(E4,E11) -> 2886000

Sheet DW BALI (Alcohol)
A1: DATE | B1: INV NO. | C1: DESCRIPTIONS | D1: AMOUNT | E1: BILLS | F1: PRICE | G1: SUBTOTAL | H1: TOTAL | I1: DUE DATE | J1: =E8 -> 5060000
A2: 46084 | B2: DW/73/257 | C2: GREY GOOSE VODKA 750 ML | D2: 2 | F2: 580000 | G2: =F2*D2 -> 1160000 | H2: =SUM(G2) -> 1160000 | I2: 46098
A3: 46097 | B3: DW/74/020 | C3: APEROL 700 ML | D3: 3 | F3: 380000 | G3: =F3*D3 -> 1140000 | H3: =SUM(G3) -> 1140000 | I3: 46111
A4: 46098 | B4: DW/74/195 | C4: HAVANA CLUB 3 YO 700 ML | D4: 2 | F4: 360000 | G4: =F4*D4 -> 720000 | H4: =SUM(G4:G6) -> 2760000 | I4: 46112
C5: JIM BEAM BLACK 700 ML | D5: 2 | F5: 450000 | G5: =F5*D5 -> 900000
C6: APEROL 700 ML | D6: 3 | F6: 380000 | G6: =F6*D6 -> 1140000
H7: =F7*D7 -> 0
A8: GRAND TOTAL | E8: =SUM(H2:H7) -> 5060000

Sheet DDB (Alcohol)
A1: DATE | B1: INV NO. | C1: DESCRIPTIONS | D1: AMOUNT | E1: BILLS | F1: PRICE | G1: TOTAL | H1: =E20 -> 2359504.8
A2: 46084 | B2: 44337 | C2: CAPE DISCOVERY BRUT CUVEE 750 ML | D2: 2 | F2: 157658 | G2: =SUM(D2*F2) -> 315316
A3: SUB TOTAL | F3: PPN | G3: =G2*11% -> 34684.76
A4: TOTAL | E4: =SUM(G2:G3) -> 350000.76
A5: 46091 | B5: 44811 | C5: ANGOSTURA AROMATIC BITTER 200 ML | D5: 1 | F5: 342343 | G5: =D5*F5 -> 342343
A6: SUB TOTAL | F6: PPN | G6: =G5*11% -> 37657.73
A7: TOTAL | E7: =SUM(G5:G6) -> 380000.73
A8: 46093 | B8: 44955 | C8: GORDON GIN PREMIUM DRY 750 ML | D8: 3 | F8: 236487 | G8: =F8*D8 -> 709461
G9: =G8*11% -> 78040.71
A10: TOTAL | E10: =SUM(G8:G9) -> 787501.71
A11: 46097 | B11: 45268 | C11: CAPE DISCOVERY BRUT CUVEE 750 ML | D11: 2 | F11: 157658 | G11: =F11*D11 -> 315316
G12: =G11*11% -> 34684.76
A13: TOTAL | E13: =SUM(G11:G12) -> 350000.76
A14: 46098 | B14: 45431 | C14: F VODKA 750 ML | D14: 2 | F14: 221622 | G14: =F14*D14 -> 443244
G15: =G14*11% -> 48756.84
A16: TOTAL | E16: =SUM(G14:G15) -> 492000.84
A19: TOTAL
A20: GRAND TOTAL | E20: =SUM(E4+E7+E10+E13+E16+E19) -> 2359504.8

Sheet NANO DEWATA NON CK(Alcohol)
A1: DATE | B1: INV NO. | C1: DESCRIPTIONS | D1: AMOUNT | E1: BILLS | F1: PRICE | G1: TOTAL | H1: =E14 -> 855000
A2: 46084 | B2: INX/NABLIX/26/03/0006 | C2: GIFFARD PARFAIT TRIPLE SEC | D2: 3 | F2: 285000 | G2: =SUM(D2*F2) -> 855000
A3: SUB TOTAL
A4: TOTAL | E4: =SUM(G2:G3) -> 855000
G5: =SUM(D5*F5) -> 0
A6: SUB TOTAL
A7: TOTAL | E7: =SUM(G5:G6) -> 0
A14: GRAND TOTAL | E14: =SUM(E4+E7+E10+E13) -> 855000

Sheet NANO DEWATA CK (Alcohol)
A1: DATE | B1: INV NO. | C1: DESCRIPTIONS | D1: AMOUNT | E1: BILLS | F1: PRICE | G1: DISCOUNT | H1: TOTAL | I1: =E14 -> 1800000
A2: 46084 | B2: INV/NANDAQ/26/03/0068 | C2: SAN TELMO MALBEC | D2: 3 | F2: 202702.7 | G2: =F2*11.11111% -> 22522.52 | H2: =(F2-G2)*D2 -> 540540.54
A3: PPN | H3: =H2*11% -> 59459.459
A4: TOTAL | E4: =SUM(H2:H3) -> 600000
A5: 46104 | B5: INV/NANDAQ/26/03/0424 | C5: SAN TELMO MALBEC | D5: 3 | F5: 202702.7 | G5: =F5*11.11111% -> 22522.52 | H5: =(F5-G5)*D5 -> 540540.54
A6: PPN | H6: =H5*11% -> 59459.459
A7: TOTAL | E7: =SUM(H5:H6) -> 600000
A8: 46111 | B8: INV/NANDAQ/26/03/0603 | C8: SAN TELMO MALBEC | D8: 3 | F8: 202702.7 | G8: =F8*11.11111% -> 22522.52 | H8: =(F8-G8)*D8 -> 540540.54
A9: PPN | H9: =H8*11% -> 59459.459
A10: TOTAL | E10: =SUM(H8:H9) -> 600000
A14: GRAND TOTAL | E14: =SUM(E4+E7+E10+E13) -> 1800000

Sheet BALI PERMATA JAYA (Corona Beer)
A1: DATE | B1: INV NO. | C1: DESCRIPTIONS | D1: AMOUNT | E1: BILLS | F1: PRICE | G1: TOTAL | H1: STATUS | I1: =E17 -> 1190000
A2: 46086 | B2: INV/PERMAQ/26/03/0185 | C2: CORONA BEER | D2: 24 | F2: 44669.67 | G2: =SUM(D2*F2) -> 1072072.1
A3: SUB TOTAL | D3: =SUM(D2) -> 24 | F3: PPN | G3: =G2*11% -> 117927.93
A4: TOTAL | E4: =SUM(G2:G3) -> 1190000
G5: =SUM(D5*F5) -> 0
A6: SUB TOTAL | D6: =SUM(D5) -> 0 | F6: PPN | G6: =G5*11% -> 0
A7: TOTAL | E7: =SUM(G5:G6) -> 0
G8: =SUM(D8*F8) -> 0
A9: SUB TOTAL | F9: PPN | G9: =G8*11% -> 0
A10: TOTAL | E10: =SUM(G8:G9) -> 0
G11: =SUM(D11*F11) -> 0
A12: SUB TOTAL | F12: PPN | G12: =G11*11% -> 0
A13: TOTAL | E13: =SUM(G11:G12) -> 0
A15: SUB TOTAL | F15: PPN | G15: =G14*11% -> 0
A16: TOTAL | E16: =SUM(G14:G15) -> 0
A17: GRAND TOTAL | E17: =E4+E7+E10+E13+E16 -> 1190000

Sheet BLACK COFFEE ROASTERS (Coffee)
A1: DATE | B1: INV NO. | C1: DESCRIPTIONS | D1: QTY | E1: PRICE | F1: BILLS | G1: TOTAL | H1: DUE DATE | I1: STATUS | J1: =F4 -> 5600000
A2: 46083 | B2: BL2-10-2769 | C2: CANGGU BLEND 1 KG | D2: 20 | E2: 280000 | G2: =SUM(D2*E2) -> 5600000 | H2: 46090 | I2: PAID
A3: 46111 | B3: BL2-10-2966 | C3: CANGGU BLEND 1 KG | D3: 20 | E3: 280000 | G3: =SUM(D3*E3) -> 5600000 | H3: 46118 | I3: UNPAID
A4: Total | F4: =SUM(G:G)-SUMIF(I:I,"PAID",G:G) -> 5600000

Sheet PT. PRASIDA LANTUR MAJU (Wine)
A1: DATE | B1: INV NO. | C1: DESCRIPTIONS | D1: QTY | E1: BILLS | F1: PRICE | G1: TOTAL | H1: DUE DATE | I1: =E11 -> 1315749.6
A2: 46084 | B2: PLM-INV0690/2026 | C2: ISOLA BIANCO 750 ML | D2: 2 | F2: 180180 | G2: =SUM(D2*F2) -> 360360 | H2: 46098
A3: SUBTOTAL | D3: =SUM(D2) -> 2 | F3: PPN | G3: =G2*11% -> 39639.6
A4: TOTAL | E4: =SUM(G2:G3) -> 399999.6
A5: 46111 | B5: PLM-INV0977/2026 | C5: ISOLA RISERVA SYRAH 750 | D5: 3 | F5: 275000 | G5: =F5*D5 -> 825000 | H5: 46125
A6: SUBTOTAL | D6: =SUM(D5) -> 3 | F6: PPN | G6: =G5*11% -> 90750
A7: TOTAL | E7: =SUM(G5:G6) -> 915750
G8: =F8*D8 -> 0
A9: SUBTOTAL | D9: =SUM(D8) -> 0 | F9: PPN | G9: =G8*11% -> 0
A10: TOTAL | E10: =SUM(G8:G9) -> 0
A11: GRAND TOTAL | E11: =SUM(E4,E7,E10) -> 1315749.6

Sheet PT LOVINA BEACH BREWERY
A1: DATE | B1: INV NO. | C1: DESCRIPTIONS | D1: BILLS | E1: TOTAL | F1: STATUS
A3: TOTAL | D3: =SUM(E2:E2) -> 0

Sheet CHAI CHITAI (Tea Leaf,etc)
A1: DATE | B1: INV NO. | C1: DESCRIPTIONS | D1: QTY | E1: BILLS | F1: PRICE | G1: SUBTOTAL | H1: TOTAL | I1: DISCOUNT | J1: TAX | K1: TOTAL | L1: =E9 -> 1687000
A2: 46084 | B2: #1 | C2: MANGO OOLONG | D2: 4 | F2: 190000 | G2: =F2*D2 -> 760000 | H2: =SUM(G2:G3) -> 2410000 | I2: =H2*30% -> 723000 | J2: =(H2-I2)*0% -> 0 | K2: =H2-I2 -> 1687000
C3: DA HONG PAO | D3: 5 | F3: 330000 | G3: =F3*D3 -> 1650000
F6: =190000*D2 -> 760000 | G6: =F6*D6 -> 0 | H6: =SUM(G6) -> 0 | I6: =H6*30% -> 0 | J6: =(H6-I6)*0% -> 0 | K6: =H6-I6 -> 0
A9: GRAND TOTAL | E9: =SUM(K2:K8) -> 1687000

Sheet MULIA JAYA (Passion Fruit)
A1: DATE | B1: DESCRIPTIONS | C1: QTY | D1: BILLS | E1: PRICE | F1: TOTAL | G1: STATUS
F2: =C2*E2 -> 0
A3: TOTAL | D3: =SUM(F2) -> 0

Sheet Dewata Kencana Distribusi (Vdka
A1: DATE | B1: DESCRIPTIONS | C1: QTY | D1: BILLS | E1: UNIT PRICE | F1: TOTAL | G1: STATUS | H1: DUE DATE | I1: =E3 -> 650200
A2: 46091 | B2: ICELAND VODKA BLACK TEA 700 ML 40.0% | C2: 4 | E2: 162550 | F2: =E2*C2 -> 650200 | G2: UNPAID | H2: 46118
A3: TOTAL | E3: =SUM(F:F)-SUMIF(G:G,"PAID",F:F) -> 650200

Sheet TOTAL
A1: NO | B1: SUPPLIER | C1: TOTAL
A2: 1 | B2: BUK BUNGA | C2: ='BUK BUNGA BAR (Groceries)'!E212 -> 15397000
A3: 2 | B3: TOKO EKA WHOLESALE | C3: ='WARUNG EKA (Drinks, Etc)'!F126 -> 9985000
A4: 3 | B4: DEWATA COCONUT | C4: ='DEWATA COCONUT (Coconut)'!E14 -> 1870000
A5: 4 | B5: SEDANA JAYA | C5: ='SEDANA JAYA'!F47 -> 0
A6: 5 | B6: PNB | C6: ='PNB (Alcohol)'!H7 -> 1120000
A7: 6 | B7: DSP | C7: ='DSP (Alcohol)'!F16 -> 2647500
A8: 7 | B8: DSP ARYA BIMA | C8: ='DSP ARYA BIMA (Alcohol)'!E3 -> 0
A9: 8 | B9: SELERA (SYRUP) | C9: ='SELERA OR STIR UP (Syrup)'!F12 -> 2886000
A10: 9 | B10: DW BALI | C10: ='DW BALI (Alcohol)'!E8 -> 5060000
A11: 10 | B11: DDB | C11: ='DDB (Alcohol)'!E20 -> 2359504.8
A12: 11 | B12: NANO DEWATA | C12: ='NANO DEWATA NON CK(Alcohol)'!E14 -> 855000
A13: 12 | B13: BALI PERMATA JAYA | C13: ='BALI PERMATA JAYA (Corona Beer)'!E17 -> 1190000
A14: 13 | B14: BLACK COFFEE ROASTERY | C14: ='BLACK COFFEE ROASTERS (Coffee)'!F4 -> 5600000
A15: 14 | B15: PRASIDA LANTUR MAJU | C15: ='PT. PRASIDA LANTUR MAJU (Wine)'!E11 -> 1315749.6
A16: 15 | B16: PT. LOVINA BEACH BREWERY | C16: ='PT LOVINA BEACH BREWERY'!D3 -> 0
A17: 16 | B17: CHAI CHITAI | C17: ='CHAI CHITAI (Tea Leaf,etc)'!E9 -> 1687000
A18: 17 | B18: MULIA JAYA | C18: ='MULIA JAYA (Passion Fruit)'!D3 -> 0
A19: 18 | B19: DEWATA KENCANA DISTRIBUSI | C19: ='Dewata Kencana Distribusi (Vdka'!E3 -> 650200
A20: TOTAL | C20: =SUM(C2:C13) -> 43370005
