Workbook

Sheet BUK BUNGA (Groceries)
A1: DATE | B1: ITEM | C1: QYT | D1: PRICE | E1: SUB TOTAL | F1: TOTAL
A2: 45995 | B2: LUMAJANG ORANGE | C2: 5 | D2: 20000 | E2: =SUM(C2*D2) -> 100000 | F2: =SUM(E2:E12) -> 572000
B3: IMPORTED LEMON | C3: 2 | D3: 70000 | E3: =SUM(C3*D3) -> 140000
B4: HONEY PINEAPPLE | C4: 6 | D4: 10000 | E4: =SUM(C4*D4) -> 60000
B5: SUNKIST | C5: 1 | D5: 38000 | E5: =SUM(C5*D5) -> 38000
B6: GREEN MUSTARD | C6: 0.3 | D6: 20000 | E6: =SUM(C6*D6) -> 6000
B7: MANGO | C7: 1 | D7: 25000 | E7: =SUM(C7*D7) -> 25000
B8: CARROT | C8: 1 | D8: 30000 | E8: =SUM(C8*D8) -> 30000
B9: CUCUMBER | C9: 1 | D9: 12000 | E9: =SUM(C9*D9) -> 12000
B10: FRESH MILK | C10: 3 | D10: 24000 | E10: =SUM(C10*D10) -> 72000
B11: OAT MILK | C11: 1 | D11: 40000 | E11: =SUM(C11*D11) -> 40000
B12: ALMOND | C12: 1 | D12: 49000 | E12: =SUM(C12*D12) -> 49000
A13: 45996 | B13: HONEY PINEAPPLE | C13: 8 | D13: 10000 | E13: =SUM(C13*D13) -> 80000 | F13: =SUM(E13:E25) -> 730000
B14: LUMAJANG ORANGE | C14: 2 | D14: 20000 | E14: =SUM(C14*D14) -> 40000
B15: HONEY | C15: 2 | D15: 35000 | E15: =SUM(C15*D15) -> 70000
B16: STRAWBERRY (250) | C16: 0.5 | D16: 95000 | E16: 48000
B17: MANGO | C17: 1.1 | D17: 38000 | E17: 42000
B18: FRESH MILK | C18: 5 | D18: 24000 | E18: =SUM(C18*D18) -> 120000
B19: OAT SIDE | C19: 3 | D19: 40000 | E19: =SUM(C19*D19) -> 120000
B20: SOY MILK | C20: 1 | D20: 45000 | E20: =SUM(C20*D20) -> 45000
B21: SUGAR | C21: 2 | D21: 20000 | E21: =SUM(C21*D21) -> 40000
B22: LIME | C22: 0.5 | D22: 30000 | E22: =SUM(C22*D22) -> 15000
B23: LIME | C23: 1 | D23: 30000 | E23: =SUM(C23*D23) -> 30000
B24: ROSEMARY | C24: 0.3 | D24: 150000 | E24: =SUM(C24*D24) -> 45000
B25: HONEY | C25: 1 | D25: 35000 | E25: =SUM(C25*D25) -> 35000
A26: 45997 | B26: WATERMELON | C26: 3.995 | D26: 15000 | E26: 60000 | F26: =SUM(E26:E34) -> 422000
B27: LUMAJANG ORANGE | C27: 2 | D27: 20000 | E27: =SUM(C27*D27) -> 40000
B28: GINGER | C28: 0.5 | D28: 35000 | E28: 18000
B29: CHILI | C29: 0.1 | D29: 80000 | E29: =SUM(C29*D29) -> 8000
B30: LIME | C30: 0.5 | D30: 30000 | E30: =SUM(C30*D30) -> 15000
B31: TRASH BAG | C31: 4 | D31: 20000 | E31: =SUM(C31*D31) -> 80000
B32: FRESH MILK | C32: 4 | D32: 24000 | E32: =SUM(C32*D32) -> 96000
B33: OATSIDE | C33: 2 | D33: 40000 | E33: =SUM(C33*D33) -> 80000
B34: SARIWANGI | C34: 1 | D34: 25000 | E34: =SUM(C34*D34) -> 25000
A35: 45998 | B35: WATERMELON | C35: 8.945 | D35: 15000 | E35: 134000 | F35: =SUM(E35:E42) -> 517000
B36: LUMAJANG ORANGE | C36: 2 | D36: 20000 | E36: =SUM(C36*D36) -> 40000
B37: MINT | C37: 0.3 | D37: 80000 | E37: =SUM(C37*D37) -> 24000
B38: CARROT | C38: 1 | D38: 30000 | E38: =SUM(C38*D38) -> 30000
B39: LIME | C39: 0.5 | D39: 30000 | E39: =SUM(C39*D39) -> 15000
B40: FRESH MILK | C40: 4 | D40: 24000 | E40: =SUM(C40*D40) -> 96000
...

Sheet WARUNG EKA (Drinks, Etc)
A1: INV NO | B1: DATE | C1: ITEM | D1: QYT | E1: PRICE | F1: SUBTOTAL | G1: TOTALPRICE
A2: 73975 | B2: 45992 | C2: CRYSTAL ICE 5KG | D2: 5 | E2: 8000 | F2: =SUM(D2*E2) -> 40000 | G2: =SUM(F2:F4) -> 82000
C3: AQUA GALLON 19LTR | D3: 1 | E3: 20000 | F3: =SUM(D3*E3) -> 20000
C4: CLEO GALLON 19LTR | D4: 1 | E4: 22000 | F4: =SUM(D4*E4) -> 22000
A5: 74056 | B5: 45993 | C5: CRYSTAL ICE 5KG | D5: 5 | E5: 8000 | F5: =SUM(D5*E5) -> 40000 | G5: =SUM(F5:F7) -> 82000
C6: AQUA GALLON 19LTR | D6: 1 | E6: 20000 | F6: =SUM(D6*E6) -> 20000
C7: CLEO GALLON 19LTR | D7: 1 | E7: 22000 | F7: =SUM(D7*E7) -> 22000
A8: 74126 | B8: 45994 | C8: CRYSTAL ICE 5KG | D8: 6 | E8: 8000 | F8: =SUM(D8*E8) -> 48000 | G8: =SUM(F8:F13) -> 703000
C9: COCA-COLA CAN 330ML | D9: 1 | E9: 135000 | F9: =SUM(D9*E9) -> 135000
C10: SPRITE CAN 330ML | D10: 1 | E10: 135000 | F10: =SUM(D10*E10) -> 135000
C11: AQUA GALLON 19LTR | D11: 1 | E11: 20000 | F11: =SUM(D11*E11) -> 20000
C12: AQUA REFLECTIONS SPARKLING 750ML | D12: 2 | E12: 120000 | F12: =SUM(D12*E12) -> 240000
C13: POLARIS SODA WATER CAN 330ML | D13: 1 | E13: 125000 | F13: =SUM(D13*E13) -> 125000
A14: 74191 | B14: 45995 | C14: CRYSTAL ICE 5KG | D14: 6 | E14: 8000 | F14: =SUM(D14*E14) -> 48000 | G14: =SUM(F14:F15) -> 92000
C15: CLEO GALLON 19LTR | D15: 2 | E15: 22000 | F15: =SUM(D15*E15) -> 44000
A16: 74321 | B16: 45997 | C16: AQUA GALLON 19LTR | D16: 2 | E16: 20000 | F16: =SUM(D16*E16) -> 40000 | G16: =SUM(F16:F18) -> 102000
C17: CLEO GALLON 19LTR | D17: 1 | E17: 22000 | F17: =SUM(D17*E17) -> 22000
C18: CRYSTAL ICE 5KG | D18: 5 | E18: 8000 | F18: =SUM(D18*E18) -> 40000
A19: 74387 | B19: 45998 | C19: CLEO GALLON 19LTR | D19: 2 | E19: 22000 | F19: =SUM(D19*E19) -> 44000 | G19: =SUM(F19:F23) -> 814000
C20: AQUA GALLON 19LTR | D20: 1 | E20: 20000 | F20: =SUM(D20*E20) -> 20000
C21: CRYSTAL ICE 5KG | D21: 5 | E21: 8000 | F21: =SUM(D21*E21) -> 40000
C22: BINTANG PINT 330ML | D22: 1 | E22: 480000 | F22: =SUM(D22*E22) -> 480000
C23: AQUA REFLECTIONS STILL 750ML | D23: 2 | E23: 115000 | F23: =SUM(D23*E23) -> 230000
A24: 74440 | B24: 45999 | C24: AQUA REFLECTIONS STILL 380ML | D24: 1 | E24: 125000 | F24: =SUM(D24*E24) -> 125000 | G24: =SUM(F24:F27) -> 302000
C25: POLARIS SODA WATER CAN 330ML | D25: 1 | E25: 125000 | F25: =SUM(D25*E25) -> 125000
C26: AQUA GALLON 19LTR | D26: 1 | E26: 20000 | F26: =SUM(D26*E26) -> 20000
C27: CRYSTAL ICE 5KG | D27: 4 | E27: 8000 | F27: =SUM(D27*E27) -> 32000
A28: 74505 | B28: 46000 | C28: CRYSTAL ICE 5KG | D28: 5 | E28: 10000 | F28: =SUM(D28*E28) -> 50000 | G28: =SUM(F28:F30) -> 92000
C29: AQUA GALLON 19LTR | D29: 1 | E29: 20000 | F29: =SUM(D29*E29) -> 20000
C30: CLEO GALLON 19LTR | D30: 1 | E30: 22000 | F30: =SUM(D30*E30) -> 22000
A31: 74575 | B31: 46001 | C31: CRYSTAL ICE 5KG | D31: 6 | E31: 8000 | F31: =SUM(D31*E31) -> 48000 | G31: =SUM(F31:F37) -> 705000
C32: AQUA GALLON 19LTR | D32: 1 | E32: 20000 | F32: =SUM(D32*E32) -> 20000
C33: CLEO GALLON 19LTR | D33: 1 | E33: 22000 | F33: =SUM(D33*E33) -> 22000
C34: COCA-COLA CAN 330ML | D34: 1 | E34: 135000 | F34: =SUM(D34*E34) -> 135000
C35: POLARIS SODA WATER CAN 330ML | D35: 1 | E35: 125000 | F35: =SUM(D35*E35) -> 125000
C36: AQUA REFLECTIONS STILL 380ML | D36: 1 | E36: 125000 | F36: =SUM(D36*E36) -> 125000
C37: AQUA REFLECTIONS STILL 750ML | D37: 2 | E37: 115000 | F37: =SUM(D37*E37) -> 230000
A38: 74644 | B38: 46002 | C38: CRYSTAL ICE 5KG | D38: 6 | E38: 8000 | F38: =SUM(D38*E38) -> 48000 | G38: =SUM(F38:F40) -> 223000
C39: AQUA GALLON 19LTR | D39: 2 | E39: 20000 | F39: =SUM(D39*E39) -> 40000
C40: COKE ZERO CAN 330ML | D40: 1 | E40: 135000 | F40: =SUM(D40*E40) -> 135000
...

Sheet DEWATA COCONUT (Coconut)
A1: DATE | B1: INV NO. | C1: DESCRIPTIONS | D1: AMOUNT | E1: BILLS | F1: PRICE | G1: TOTAL
A2: 45992 | B2: 12340 | C2: COCONUT LOGO | D2: 20 | F2: 12000 | G2: =SUM(D2*F2) -> 240000
A3: 45994 | B3: 12357 | C3: COCONUT LOGO | D3: 20 | F3: 12000 | G3: =SUM(D3*F3) -> 240000
A4: 45996 | B4: 11374 | C4: COCONUT LOGO | D4: 20 | F4: 12000 | G4: =SUM(D4*F4) -> 240000
A5: 45998 | B5: 13396 | C5: COCONUT LOGO | D5: 20 | F5: 12000 | G5: =SUM(D5*F5) -> 240000
A6: 46002 | B6: 11474 | C6: COCONUT LOGO | D6: 20 | F6: 12000 | G6: =SUM(D6*F6) -> 240000
A7: 46006 | B7: 13509 | C7: COCONUT LOGO | D7: 20 | F7: 12000 | G7: =SUM(D7*F7) -> 240000
A8: 46010 | B8: 8224 | C8: COCONUT LOGO | D8: 20 | F8: 12000 | G8: =SUM(D8*F8) -> 240000
A9: 46012 | B9: 12122 | C9: COCONUT LOGO | D9: 20 | F9: 13000 | G9: =SUM(D9*F9) -> 260000
A10: 46018 | B10: 12122 | C10: COCONUT LOGO | D10: 20 | F10: 13000 | G10: =SUM(D10*F10) -> 260000
A11: 46022 | B11: 12122 | C11: COCONUT LOGO | D11: 20 | E11: =_xlfn.DISPIMG("ID_3DB2A1BD094A4E7A8FAC00B7D3526E12",1) -> =DISPIMG("ID_3DB2A1BD094A4E7A8FAC00B7D3526E12",1) | F11: 12000 | G11: =SUM(D11*F11) -> 240000
E12: =SUM(G2:G11) -> 2440000

Sheet SEDANA JAYA
A1: DATE | B1: ITEM | C1: QYT | D1: PRICE | E1: TOTAL PRICE | F1: TOTAL
A2: 45993 | B2: LUMAJANG ORANGE | C2: 3 | D2: 28000 | E2: =SUM(C2*D2) -> 84000 | F2: =SUM(E2:E10) -> 749100
B3: IMPORTED LEMON | C3: 2 | D3: 83000 | E3: =SUM(C3*D3) -> 166000
B4: MUSTARD | C4: 0.3 | D4: 17000 | E4: =SUM(C4*D4) -> 5100
B5: MALANG APPLE | C5: 1 | D5: 61000 | E5: =SUM(C5*D5) -> 61000
B6: CUCUMBER | C6: 1 | D6: 17000 | E6: =SUM(C6*D6) -> 17000
B7: CARROT | C7: 1 | D7: 31000 | E7: =SUM(C7*D7) -> 31000
B8: WATERMELON | C8: 8 | D8: 15000 | E8: =SUM(C8*D8) -> 120000
B9: FRESH MILK | C9: 5 | D9: 35000 | E9: =SUM(C9*D9) -> 175000
B10: LYCHEE CAN | C10: 2 | D10: 45000 | E10: =SUM(C10*D10) -> 90000
A11: 45994 | B11: LUMAJANG ORANGE | C11: 5 | D11: 28000 | E11: =SUM(C11*D11) -> 140000 | F11: =SUM(E11:E20) -> 1051000
B12: IMPORTED LEMON | C12: 3 | D12: 83000 | E12: =SUM(C12*D12) -> 249000
B13: PINEAPPLE | C13: 8 | D13: 10000 | E13: =SUM(C13*D13) -> 80000
B14: SUNKIST | C14: 1 | D14: 50000 | E14: =SUM(C14*D14) -> 50000
B15: GREEN MUSTARD | C15: 1 | D15: 17000 | E15: =SUM(C15*D15) -> 17000
B16: GREEN APPLE | C16: 2 | D16: 61000 | E16: =SUM(C16*D16) -> 122000
B17: MANGO | C17: 2 | D17: 39000 | E17: =SUM(C17*D17) -> 78000
B18: STRAWBERRY | C18: 1 | D18: 120000 | E18: =SUM(C18*D18) -> 120000
B19: FRESH MILK | C19: 4 | D19: 35000 | E19: =SUM(C19*D19) -> 140000
B20: OAT MEAL | C20: 1 | D20: 55000 | E20: =SUM(C20*D20) -> 55000
E21: =SUM(C21*D21) -> 0
E22: =SUM(C22*D22) -> 0
E23: =SUM(C23*D23) -> 0 | F23: =SUM(E23:E36) -> 0
E24: =SUM(C24*D24) -> 0
E25: =SUM(C25*D25) -> 0
E26: =SUM(C26*D26) -> 0
E27: =SUM(C27*D27) -> 0
E28: =SUM(C28*D28) -> 0
E29: =SUM(C29*D29) -> 0
E30: =SUM(C30*D30) -> 0
E31: =SUM(C31*D31) -> 0
E32: =SUM(C32*D32) -> 0
E33: =SUM(C33*D33) -> 0
E34: =SUM(C34*D34) -> 0
E35: =SUM(C35*D35) -> 0
E36: =SUM(C36*D36) -> 0
F37: =SUM(F2:F36) -> 1800100

Sheet PNB (Alcohol)
A1: DATE | B1: INV NO. | C1: DESCRIPTIONS | D1: QTY | E1: BILLS | F1: UNIT PRICE | G1: SUB TOTAL | H1: TOTAL
A2: 45992 | B2: SPNO2512004 | C2: JOSE CUERVO GOLD | D2: 3 | F2: 425000 | G2: =D2*F2 -> 1275000 | H2: =SUM(D2*F2) -> 1275000
A3: 46022 | B3: SPNB25123393 | C3: LIMO APERITIVO 500 ML | D3: 5 | F3: 280000 | G3: =D3*F3 -> 1400000 | H3: =SUM(G3:G5) -> 2900000
C4: MANONO ROSSO 750 ML | D4: 3 | F4: 500000 | G4: =D4*F4 -> 1500000
G5: =D5*F5 -> 0
G6: =D6*F6 -> 0 | H6: =SUM(G6:G6) -> 0
H7: =SUM(H2:H6) -> 4175000

Sheet DSP (Alcohol)
A1: DATE | B1: INV NO. | C1: DESCRIPTIONS | D1: QTY | E1: PRICE | F1: DISCOUNT | G1: UNIT PRICE | H1: SUBTOTAL | I1: TOTAL | J1: BILL
A2: 46000 | B2: SO/DSP/25/12/0570 | C2: MCGUIGAN - BLACK LABEL SAUVIGNON BLANC | D2: 4 | E2: 295000 | F2: =E2*10% -> 29500 | G2: =E2-F2 -> 265500 | H2: =D2*G2 -> 1062000 | I2: =SUM(H2) -> 1062000
A3: 46002 | B3: SO/DSP/25/12/0692 | C3: HUNTER'S PINOT GRIS | D3: 4 | E3: 385000 | F3: =E3*10% -> 38500 | G3: =E3-F3 -> 346500 | H3: =D3*G3 -> 1386000 | I3: =SUM(H3:H4) -> 2718000
C4: DA VINCI LEONARDO PROSECCO DOC | D4: 4 | E4: 370000 | F4: =E4*10% -> 37000 | G4: =E4-F4 -> 333000 | H4: =D4*G4 -> 1332000
A5: 46006 | B5: SO/DSP/25/12/0908 | C5: DONA DOMINGA CLASICO DE FAMILIA SYRAH | D5: 3 | E5: 290000 | F5: =E5*10% -> 29000 | G5: =E5-F5 -> 261000 | H5: =D5*G5 -> 783000 | I5: =SUM(H5) -> 783000
A6: 46007 | B6: SO/DSP/25/12/1004 | C6: SAN MARZANO TALO PRIMITIVO MERLOT | D6: 3 | E6: 375000 | F6: =E6*10% -> 37500 | G6: =E6-F6 -> 337500 | H6: =D6*G6 -> 1012500 | I6: =SUM(H6) -> 1012500
A7: 46010 | B7: SOMDG/DSP/25/12/0138 | C7: MDG - F VODKA | D7: 3 | E7: 246000 | G7: =E7-F7 -> 246000 | H7: =D7*G7 -> 738000 | I7: =SUM(H7:H9) -> 3132000
A8: 46018 | B8: SO/DSP/25/12/1806 | C8: MCGUIGAN - BLACK LABEL SAUVIGNON BLANC | D8: 4 | E8: 295000 | F8: =E8*10% -> 29500 | G8: =E8-F8 -> 265500 | H8: =D8*G8 -> 1062000 | I8: =SUM(H8) -> 1062000
A9: 46019 | B9: SO/DSP/25/12/1870 | C9: DA VINCI LEONARDO PROSECCO DOC | D9: 4 | E9: 370000 | F9: =E9*10% -> 37000 | G9: =E9-F9 -> 333000 | H9: =SUM(D9*G9) -> 1332000 | I9: =SUM(H9) -> 1332000
A10: 46021 | B10: SO/DSP/25/12/2113 | C10: HUNTER'S PINOT GRIS | D10: 4 | E10: 385000 | F10: =E10*10% -> 38500 | G10: =E10-F10 -> 346500 | H10: =SUM(D10*G10) -> 1386000 | I10: =SUM(H10:H13) -> 4846500
C11: HUNTER'S RIESLING | D11: 4 | E11: 385000 | F11: =E11*10% -> 38500 | G11: =E11-F11 -> 346500 | H11: =SUM(D11*G11) -> 1386000
C12: SAN MARZANO TALO PRIMITIVO MERLOT | D12: 3 | E12: 375000 | F12: =E12*10% -> 37500 | G12: =E12-F12 -> 337500 | H12: =SUM(D12*G12) -> 1012500
C13: MCGUIGAN-BLACK LABEL SAUVIGNON BLANC | D13: 4 | E13: 295000 | F13: =E13*10% -> 29500 | G13: =E13-F13 -> 265500 | H13: =SUM(D13*G13) -> 1062000
A14: 46021 | B14: SOMDG/DSP/25/12/0226 | C14: MDG - SACCHARUM WHITE RUM | D14: 1 | E14: 281500 | G14: =E14-F14 -> 281500 | H14: =SUM(D14*G14) -> 281500 | I14: =SUM(H14) -> 281500
A15: 46021 | B15: SO/DSP/25/12/2093 | C15: DA VINCI LEONARDO PROSECCO DOC | D15: 3 | E15: 370000 | F15: =E15*10% -> 37000 | G15: =E15-F15 -> 333000 | H15: =SUM(D15*G15) -> 999000 | I15: =SUM(H15) -> 999000
A16: 46021 | B16: SO/DSP/25/12/2181 | C16: DONA DOMINGA CLASICO DE FAMILIA SYRAH | D16: 10 | E16: 290000 | F16: =E16*10% -> 29000 | G16: =E16-F16 -> 261000 | H16: =SUM(D16*G16) -> 2610000 | I16: =SUM(H16) -> 2610000
F17: =E17*10% -> 0 | G17: =E17-F17 -> 0 | H17: =SUM(D17*G17) -> 0 | I17: =SUM(H17) -> 0
F18: =E18*10% -> 0 | G18: =E18-F18 -> 0 | H18: =SUM(D18*G18) -> 0 | I18: =SUM(H18) -> 0
F19: =E19*10% -> 0 | G19: =E19-F19 -> 0 | H19: =SUM(D19*G19) -> 0 | I19: =SUM(H19) -> 0
A20: TOTAL | F20: =SUM(I2:I19) -> 19838500

Sheet DSP ARYA BIMA (Alcohol)
A1: DATE | B1: INV NO. | C1: DESCRIPTIONS | D1: QTY | E1: BILLS | F1: PRICE | G1: SUBTOTAL | H1: TOTAL
A2: 46009 | B2: SOPR/ABC/25/12/0254 | C2: CODIGO BLANCO | D2: 1 | F2: 855000 | G2: =F2*D2 -> 855000 | H2: =SUM(G2) -> 855000
A3: 46017 | B3: SOPR/ABC/25/12/0411 | C3: CODIGO BLANCO | D3: 2 | F3: 855000 | G3: =F3*D3 -> 1710000 | H3: =SUM(G3) -> 1710000
A4: 46021 | B4: SOPR/ABC/25/12/0491 | C4: JOSE CUERVO REPOSADO TEQUILA | D4: 3 | E4: =_xlfn.DISPIMG("ID_133B4CAC025048A48D22D160DF5EAE6B",1) -> =DISPIMG("ID_133B4CAC025048A48D22D160DF5EAE6B",1) | F4: 356250 | G4: =F4*D4 -> 1068750 | H4: =SUM(G4) -> 1068750
A5: TOTAL | E5: =SUM(H2:H4) -> 3633750

Sheet SELERA OR STIR UP (Syrup)
A1: DATE | B1: INV NO. | C1: DESCRIPTIONS | D1: QTY | E1: BILLS | F1: PRICE | G1: SUBTOTAL | H1: TOTAL
A2: 45992 | B2: SO-2504780 | C2: MARVELOUS MANGO PET | D2: 5 | F2: 100000 | G2: =D2*F2 -> 500000 | H2: =SUM(G2:G6) -> 500000
A7: SUB TOTAL | D7: =SUM(D2:D6) -> 5 | F7: PPN (11%) | H7: =H2*11% -> 55000
A8: TOTAL | E8: =SUM(H2:H7) -> 555000
A9: 45999 | B9: SO-2504895 | C9: PARADISE PEACH PET | D9: 3 | F9: 100000 | G9: =D9*F9 -> 300000 | H9: =SUM(G9:G11) -> 800000
C10: KOOL KIWI PET | D10: 3 | F10: 100000 | G10: =D10*F10 -> 300000
C11: VOILA VANILLA | D11: 2 | F11: 100000 | G11: =D11*F11 -> 200000
A12: SUB TOTAL | D12: =SUM(D9:D11) -> 8 | F12: PPN (11%) | H12: =H9*11% -> 88000
A13: TOTAL | E13: =SUM(H9:H12) -> 888000
A14: 45992 | B14: SO-2504780 | C14: MARVELOUS MANGO PET | D14: 5 | F14: 100000 | G14: =D14*F14 -> 500000 | H14: =SUM(G14:G18) -> 500000
A19: SUB TOTAL | D19: =SUM(D14:D18) -> 5 | F19: PPN (11%) | H19: =H14*11% -> 55000
A20: TOTAL | E20: =SUM(H14:H19) -> 555000
A21: 46020 | B21: SO-2505255 | C21: MARVELOUS MANGO PET | D21: 4 | E21: =_xlfn.DISPIMG("ID_D63085A15C36462487EA4D8D9789A550",1) -> =DISPIMG("ID_D63085A15C36462487EA4D8D9789A550",1) | F21: 100000 | G21: =D21*F21 -> 400000 | H21: =SUM(G21:G25) -> 400000
A26: SUB TOTAL | D26: =SUM(D21:D25) -> 4 | F26: PPN (11%) | H26: =H21*11% -> 44000
A27: TOTAL | E27: =SUM(H21:H26) -> 444000
A28: GRAND TOTAL | E28: =SUM(E8,E13,E20,E27) -> 2442000

Sheet DW BALI (Alcohol)
A1: DATE | B1: INV NO. | C1: DESCRIPTIONS | D1: AMOUNT | E1: BILLS | F1: PRICE | G1: SUBTOTAL | H1: TOTAL
A2: 46001 | B2: DW/68/007 | C2: APEROL | D2: 2 | F2: 370000 | G2: =F2*D2 -> 740000 | H2: =SUM(G2) -> 740000
A3: 46001 | B3: DW/68/001 | C3: JIM BEAM WHITE 750ML | D3: 4 | F3: 300000 | G3: =F3*D3 -> 1200000 | H3: =SUM(G3) -> 1200000
A4: 46004 | B4: DW/68/179 | C4: JIM BEAM BLACK 750ML | D4: 1 | F4: 450000 | G4: =F4*D4 -> 450000 | H4: =SUM(F4:F5) -> 870000
C5: BAILEYS IRISH CREAM 750ML | D5: 1 | F5: 420000 | G5: =F5*D5 -> 420000
A6: 46021 | B6: 110 | C6: JOSE CUERVO 700ML | D6: 10 | E6: =_xlfn.DISPIMG("ID_7637A752F7C54F13939F83F13A88A484",1) -> =DISPIMG("ID_7637A752F7C54F13939F83F13A88A484",1) | G6: =F6*D6 -> 0 | H6: =SUM(G6:G12) -> 0
C7: CAMPARI | D7: 3
C8: JIM BEAM BLACK 750ML | D8: 4
C9: GREY GOOSE 750ML | D9: 1
C10: EL JIMADOR REPOSADO | D10: 1
C11: APEROL | D11: 1
C12: CODIGO BIANCO | D12: 1
G14: =F14*D14 -> 0
A15: GRAND TOTAL | F15: =SUM(H2:H14) -> 2810000

Sheet DDB (Alcohol)
A1: DATE | B1: INV NO. | C1: DESCRIPTIONS | D1: AMOUNT | E1: BILLS | F1: PRICE | G1: TOTAL
A2: 45999 | B2: 38678 | C2: CAPE DISCOVERY BRUT CUVEE 750ML | D2: 3 | F2: 157658 | G2: =SUM(D2*F2) -> 472974
A3: SUB TOTAL | F3: PPN | G3: =G2*11% -> 52027.14
A4: TOTAL | E4: =SUM(G2:G3) -> 525001.14
A5: 46021 | B5: 00867 | C5: CAPE DISCOVERY BRUT CUVEE 750ML | D5: 3 | E5: =_xlfn.DISPIMG("ID_61B926048EC84CFEBE8E5552B52457FF",1) -> =DISPIMG("ID_61B926048EC84CFEBE8E5552B52457FF",1) | G5: =D5*F5 -> 0
C6: GORDON GIN | D6: 3
A7: SUB TOTAL | F7: PPN | G7: =G5*11% -> 0
A8: TOTAL | E8: =SUM(G5:G7) -> 0
A11: TOTAL
A14: TOTAL
A15: GRAND TOTAL | E15: =SUM(E4+E8+E11+E14) -> 525001.14

Sheet NANO DEWATA (Alcohol)
A1: DATE | B1: INV NO. | C1: DESCRIPTIONS | D1: AMOUNT | E1: BILLS | F1: PRICE | G1: TOTAL
G2: =SUM(D2*F2) -> 0
A3: SUB TOTAL
A4: TOTAL | E4: =SUM(G2:G3) -> 0
G5: =SUM(D5*F5) -> 0
A6: SUB TOTAL
A7: TOTAL | E7: =SUM(G5:G6) -> 0
A14: GRAND TOTAL | E14: =SUM(E4+E7+E10+E13) -> 0

Sheet BALI PERMATA JAYA (Corona Beer)
A1: DATE | B1: INV NO. | C1: DESCRIPTIONS | D1: AMOUNT | E1: BILLS | F1: PRICE | G1: TOTAL | H1: STATUS
A2: 45999 | B2: INV/PERMAQ/25/12/0251 | C2: CORONA BEER | D2: 24 | F2: 44670 | G2: =SUM(D2*F2) -> 1072080
A3: SUB TOTAL | D3: =SUM(D2) -> 24 | F3: PPN | G3: =G2*11% -> 117928.8
A4: TOTAL | E4: =SUM(G2:G3) -> 1190008.8
G5: =SUM(D5*F5) -> 0
A6: SUB TOTAL | D6: =SUM(D5) -> 0 | F6: PPN | G6: =G5*11% -> 0
A7: TOTAL | E7: =SUM(G5:G6) -> 0
G8: =SUM(D8*F8) -> 0
A9: SUB TOTAL | F9: PPN | G9: =G8*11% -> 0
A10: TOTAL | E10: =SUM(G8:G9) -> 0
G11: =SUM(D11*F11) -> 0
A12: SUB TOTAL | F12: PPN | G12: =G11*11% -> 0
A13: TOTAL | E13: =SUM(G11:G12) -> 0
A15: SUB TOTAL | F15: PPN | G15: =G14*11% -> 0
A16: TOTAL | E16: =SUM(G14:G15) -> 0
A17: GRAND TOTAL | E17: =E4+E7+E10+E13+E16 -> 1190008.8

Sheet BLACK COFFEE ROASTERS (Coffee)
A1: DATE | B1: INV NO. | C1: DESCRIPTIONS | D1: QTY | E1: PRICE | F1: BILLS | G1: TOTAL
A2: 46001 | B2: BL2-10-2320 | C2: CANGGU BLEND 1KG | D2: 10 | E2: 280000 | F2: =_xlfn.DISPIMG("ID_A7288E1D8486499C936AD7CFEE5889FB",1) -> =DISPIMG("ID_A7288E1D8486499C936AD7CFEE5889FB",1) | G2: =SUM(D2*E2) -> 2800000
A3: 46006 | B3: BL2-10-2348 | C3: CANGGU BLEND 1KG | D3: 10 | E3: 280000 | F3: =_xlfn.DISPIMG("ID_EC8B07304AE24AABAA210E4FDB7BE2A3",1) -> =DISPIMG("ID_EC8B07304AE24AABAA210E4FDB7BE2A3",1) | G3: =SUM(D3*E3) -> 2800000
A4: Total | F4: =SUM(G2:G3) -> 5600000

Sheet PT. PRASIDA LANTUR MAJU (Wine)
A1: DATE | B1: INV NO. | C1: DESCRIPTIONS | D1: QTY | E1: BILLS | F1: PRICE | G1: TOTAL
A2: 45999 | B2: PLM-INV4742/2025 | C2: ISOLA RISERVA SYRAH 750ML | D2: 3 | F2: 275000 | G2: =SUM(D2*F2) -> 825000
A3: SUBTOTAL | D3: =SUM(D2) -> 3 | F3: PPN | G3: =G2*11% -> 90750
A4: TOTAL | E4: =SUM(G2:G3) -> 915750
A7: TOTAL | E7: =SUM(G5:G6) -> 0
A8: GRAND TOTAL | E8: =E4+E7 -> 915750

Sheet PT LOVINA BEACH BREWERY
A1: DATE | B1: INV NO. | C1: DESCRIPTIONS | D1: BILLS | E1: TOTAL | F1: STATUS
A3: TOTAL | D3: =SUM(E2:E2) -> 0

Sheet CHAI CHITAI (Tea Leaf,etc)
A1: DATE | B1: INV NO. | C1: DESCRIPTIONS | D1: QTY | E1: BILLS | F1: PRICE | G1: TOTAL
A12: GRAND TOTAL | E12: =SUM(G7+G11) -> 0

Sheet MULIA JAYA (Passion Fruit)
A1: DATE | B1: DESCRIPTIONS | C1: QTY | D1: BILLS | E1: PRICE | F1: TOTAL | G1: STATUS
F2: =C2*E2 -> 0
A3: TOTAL | D3: =SUM(F2) -> 0

Sheet Dewata Kencana Distribusi (Vdka
A1: DATE | B1: DUE DATE | C1: DESCRIPTIONS | D1: QTY | E1: BILLS | F1: UNIT PRICE | G1: SUBTOTAL | H1: TOTAL
A2: 46018 | B2: 46031 | C2: ICELAND VODKA BLACK TEA 700ML | D2: 6 | F2: 152550 | G2: =F2*D2 -> 915300 | H2: =SUM(G2) -> 915300
A3: GRAND TOTAL | F3: =SUM(H2) -> 915300

Sheet Indobev Mentari Sejahtera
A1: DATE | B1: INV NO. | C1: DESCRIPTIONS | D1: AMOUNT | E1: BILLS | F1: PRICE | G1: SUBTOTAL | H1: TOTAL
A2: 46017 | B2: INX/PMBALX/25/12/0555 | C2: BOLS CURACAO TRIPLE SEC | D2: 4 | F2: 400000 | G2: =F2*D2 -> 1600000 | H2: =SUM(G2) -> 1600000
G3: =F3*D3 -> 0 | H3: =SUM(G3) -> 0
G4: =F4*D4 -> 0 | H4: =SUM(F4:F5) -> 0
G5: =F5*D5 -> 0
A6: GRAND TOTAL | F6: =SUM(H2:H5) -> 1600000

Sheet TOTAL
A1: NO | B1: SUPPLIER | C1: TOTAL
A2: 1 | B2: BUK BUNGA | C2: ='BUK BUNGA (Groceries)'!F317 -> 20186000
A3: 2 | B3: TOKO EKA WHOLESALE | C3: ='WARUNG EKA (Drinks, Etc)'!G117 -> 10506000
A4: 3 | B4: DEWATA COCONUT | C4: ='DEWATA COCONUT (Coconut)'!E12 -> 2440000
A5: 4 | B5: SEDANA JAYA | C5: ='SEDANA JAYA'!F37 -> 1800100
A6: 5 | B6: PNB | C6: ='PNB (Alcohol)'!H7 -> 4175000
A7: 6 | B7: DSP | C7: ='DSP (Alcohol)'!F20 -> 19838500
A8: 7 | B8: DSP ARYA BIMA | C8: ='DSP ARYA BIMA (Alcohol)'!E5 -> 3633750
A9: 8 | B9: SELERA (SYRUP) | C9: ='SELERA OR STIR UP (Syrup)'!F19 -> PPN (11%)
A10: 9 | B10: DW BALI | C10: ='DW BALI (Alcohol)'!E15 -> 0
A11: 10 | B11: DDB | C11: ='DDB (Alcohol)'!E15 -> 525001.14
A12: 11 | B12: NANO DEWATA | C12: ='NANO DEWATA (Alcohol)'!E14 -> 0
A13: 12 | B13: BALI PERMATA JAYA | C13: ='BALI PERMATA JAYA (Corona Beer)'!E17 -> 1190008.8
A14: 13 | B14: BLACK COFFEE ROASTERY | C14: ='BLACK COFFEE ROASTERS (Coffee)'!F4 -> 5600000
A15: 14 | B15: PRASIDA LANTUR MAJU | C15: ='PT. PRASIDA LANTUR MAJU (Wine)'!E8 -> 915750
A16: 15 | B16: PT. LOVINA BEACH BREWERY | C16: ='PT LOVINA BEACH BREWERY'!D3 -> 0
A17: 16 | B17: CHAI CHITAI | C17: ='CHAI CHITAI (Tea Leaf,etc)'!E12 -> 0
A18: 17 | B18: MULIA JAYA | C18: ='MULIA JAYA (Passion Fruit)'!D3 -> 0
A19: 18 | B19: DEWATA KENCANA DISTRIBUSI | C19: ='Dewata Kencana Distribusi (Vdka'!F3 -> 915300
A20: 19 | B20: INDOBEV MENTARI SEJAHTERA | C20: ='Indobev Mentari Sejahtera'!F6 -> 1600000
A21: TOTAL | C21: =SUM(C2:C13) -> 64294360
