Workbook

Sheet BUK BUNGA (Groceries)
A1: DATE | B1: ITEM | C1: QYT | D1: PRICE | E1: SUB TOTAL | F1: TOTAL
A2: 45962 | B2: LUMAJANG ORANGE | C2: 3 | D2: 20000 | E2: =SUM(C2*D2) -> 60000 | F2: =SUM(E2:E13) -> 680000
B3: IMPORTED LEMON | C3: 4 | D3: 75000 | E3: =SUM(C3*D3) -> 300000
B4: LIME | C4: 0.3 | D4: 30000 | E4: =SUM(C4*D4) -> 9000
B5: MUSTARD | C5: 0.3 | D5: 15000 | E5: 5000
B6: PINEAPPLE | C6: 6 | D6: 10000 | E6: =SUM(C6*D6) -> 60000
B7: MANGO | C7: 1 | D7: 38000 | E7: =SUM(C7*D7) -> 38000
B8: APPLE | C8: 1 | D8: 48000 | E8: =SUM(C8*D8) -> 48000
B9: STRAWBERRY (250 GR) | C9: 0.5 | D9: 100000 | E9: =SUM(C9*D9) -> 50000
B10: FRESH MILK | C10: 1 | D10: 24000 | E10: =SUM(C10*D10) -> 24000
B11: CONDENSED MILK | C11: 1 | D11: 16000 | E11: =SUM(C11*D11) -> 16000
B12: EVAPORATED MILK | C12: 1 | D12: 30000 | E12: =SUM(C12*D12) -> 30000
A13: 45963 | B13: LYCHEE CAN | C13: 1 | D13: 40000 | E13: =SUM(C13*D13) -> 40000 | F13: =SUM(E13:E19) -> 433000
B14: LUMAJANG ORANGE | C14: 2 | D14: 20000 | E14: =SUM(C14*D14) -> 40000
B15: LEMON | C15: 1 | D15: 70000 | E15: =SUM(C15*D15) -> 70000
B16: FRESH MILK | C16: 4 | D16: 24000 | E16: =SUM(C16*D16) -> 96000
B17: OAT MILK | C17: 3 | D17: 40000 | E17: =SUM(C17*D17) -> 120000
B18: GINGER | C18: 0.2 | D18: 35000 | E18: =SUM(C18*D18) -> 7000
B19: PINEAPPLE | C19: 6 | D19: 10000 | E19: =SUM(C19*D19) -> 60000
A20: 45964 | B20: WATERMELON | C20: 7.585 | D20: 15000 | E20: 114000 | F20: =SUM(E20:E35) -> 1327000
B21: PINEAPPLE | C21: 8 | D21: 10000 | E21: =SUM(C21*D21) -> 80000
B22: SUNKIST | C22: 2.13 | D22: 38000 | E22: 81000
B23: LEMON | C23: 4 | D23: 75000 | E23: =SUM(C23*D23) -> 300000
B24: ORANGE | C24: 3 | D24: 20000 | E24: =SUM(C24*D24) -> 60000
B25: CUCUMBER | C25: 2 | D25: 12000 | E25: =SUM(C25*D25) -> 24000
B26: GREEN APPLE | C26: 2.1 | D26: 48000 | E26: 101000
B27: MANGO | C27: 2 | D27: 38000 | E27: =SUM(C27*D27) -> 76000
B28: GREEN MUSTARD | C28: 1 | D28: 12000 | E28: =SUM(C28*D28) -> 12000
B29: MINT | C29: 0.5 | D29: 60000 | E29: =SUM(C29*D29) -> 30000
B30: LIME | C30: 1 | D30: 30000 | E30: =SUM(C30*D30) -> 30000
B31: STRAWBERRY (250 GR) | C31: 1 | D31: 100000 | E31: =SUM(C31*D31) -> 100000
B32: FRESH MILK | C32: 4 | D32: 24000 | E32: =SUM(C32*D32) -> 96000
B33: OAT MILK | C33: 2 | D33: 40000 | E33: =SUM(C33*D33) -> 80000
B34: ALMOND MILK | C34: 2 | D34: 49000 | E34: =SUM(C34*D34) -> 98000
B35: SOYA MILK | C35: 1 | D35: 45000 | E35: =SUM(C35*D35) -> 45000
A36: 45965 | B36: LUMAJANG ORANGE | C36: 2 | D36: 20000 | E36: =SUM(C36*D36) -> 40000 | F36: =SUM(E36:E41) -> 496000
B37: LEMON | C37: 2.1 | D37: 75000 | E37: 158000
B38: PINEAPPLE | C38: 6 | D38: 10000 | E38: =SUM(C38*D38) -> 60000
B39: MANGO | C39: 1.1 | D39: 38000 | E39: 42000
B40: STRAWBERRY (250 GR) | C40: 1 | D40: 100000 | E40: =SUM(C40*D40) -> 100000
...

Sheet WARUNG EKA (Drinks, Etc)
A1: INV NO | B1: DATE | C1: ITEM | D1: QYT | E1: PRICE | F1: SUBTOTAL | G1: TOTALPRICE
A2: 71905 | B2: 45962 | C2: CRYSTAL ICE 5 KG | D2: 4 | E2: 8000 | F2: =SUM(D2*E2) -> 32000 | G2: =SUM(F2:F3) -> 52000
C3: AQUA GALLON | D3: 1 | E3: 20000 | F3: =SUM(D3*E3) -> 20000
A4: 71971 | B4: 45963 | C4: AQUA GALLON | D4: 1 | E4: 20000 | F4: =SUM(D4*E4) -> 20000 | G4: =SUM(F4:F6) -> 528000
C5: CRYSTAL ICE 5 KG | D5: 6 | E5: 8000 | F5: =SUM(D5*E5) -> 48000
C6: AQUA REFLECTIONS STILL 750ML | D6: 4 | E6: 115000 | F6: =SUM(D6*E6) -> 460000
A7: 72030 | B7: 45964 | C7: AQUA GALLON | D7: 2 | E7: 20000 | F7: =SUM(D7*E7) -> 40000 | G7: =SUM(F7:F9) -> 132000
C8: CLEO GALLON | D8: 2 | E8: 22000 | F8: =SUM(D8*E8) -> 44000
C9: CRYSTAL ICE 5 KG | D9: 6 | E9: 8000 | F9: =SUM(D9*E9) -> 48000
A10: 72121 | B10: 45965 | C10: CRYSTAL ICE 5 KG | D10: 4 | E10: 8000 | F10: =SUM(D10*E10) -> 32000 | G10: =SUM(F10:F15) -> 784000
C11: CLEO GALLON | D11: 1 | E11: 22000 | F11: =SUM(D11*E11) -> 22000
C12: COKE ZERO CAN 330ML | D12: 1 | E12: 135000 | F12: =SUM(D12*E12) -> 135000
C13: AQUA REFLECTIONS SPARKLING 750ML | D13: 2 | E13: 120000 | F13: =SUM(D13*E13) -> 240000
C14: AQUA REFLECTIONS STILL 750ML | D14: 2 | E14: 115000 | F14: =SUM(D14*E14) -> 230000
C15: AQUA REFLECTIONS STILL 380ML | D15: 1 | E15: 125000 | F15: =SUM(D15*E15) -> 125000
A16: 72185 | B16: 45966 | C16: CRYSTAL ICE 5 KG | D16: 4 | E16: 8000 | F16: =SUM(D16*E16) -> 32000 | G16: =SUM(F16:F18) -> 74000
C17: CLEO GALLON | D17: 1 | E17: 22000 | F17: =SUM(D17*E17) -> 22000
C18: AQUA GALLON | D18: 1 | E18: 20000 | F18: =SUM(D18*E18) -> 20000
A19: 72264 | B19: 45967 | C19: AQUA GALLON | D19: 1 | E19: 20000 | F19: =SUM(D19*E19) -> 20000 | G19: =SUM(F19:F20) -> 42000
C20: CLEO GALLON | D20: 1 | E20: 22000 | F20: =SUM(D20*E20) -> 22000
A21: 72318 | B21: 45968 | C21: CLEO GALLON | D21: 1 | E21: 22000 | F21: =SUM(D21*E21) -> 22000 | G21: =SUM(F21:F25) -> 810000
C22: CRYSTAL ICE 5 KG | D22: 6 | E22: 8000 | F22: =SUM(D22*E22) -> 48000
C23: COCA COLA CAN 330 ML | D23: 1 | E23: 135000 | F23: =SUM(D23*E23) -> 135000
C24: SCHWEPPES TONIC WATER CAN 250 ML | D24: 1 | E24: 125000 | F24: =SUM(D24*E24) -> 125000
C25: BINTANG PINT 330 ML | D25: 1 | E25: 480000 | F25: =SUM(D25*E25) -> 480000
A26: 72401 | B26: 45969 | C26: CLEO GALLON | D26: 1 | E26: 22000 | F26: =SUM(D26*E26) -> 22000 | G26: =SUM(F26:F28) -> 195000
C27: CRYSTAL ICE 5 KG | D27: 6 | E27: 8000 | F27: =SUM(D27*E27) -> 48000
C28: POLARS SODA WATER CAN 330 ML | D28: 1 | E28: 125000 | F28: =SUM(D28*E28) -> 125000
A29: 72489 | B29: 45970 | C29: CLEO GALLON | D29: 2 | E29: 22000 | F29: =SUM(D29*E29) -> 44000 | G29: =SUM(F29:F32) -> 1262000
C30: AQUA GALLON | D30: 1 | E30: 20000 | F30: =SUM(D30*E30) -> 20000
C31: CRYSTAL ICE 5 KG | D31: 6 | E31: 8000 | F31: =SUM(D31*E31) -> 48000
C32: AQUA REFLECTIONS STILL 750ML | D32: 10 | E32: 115000 | F32: =SUM(D32*E32) -> 1150000
A33: 72524 | B33: 45971 | C33: CLEO GALLON | D33: 2 | E33: 22000 | F33: =SUM(D33*E33) -> 44000 | G33: =SUM(F33:F37) -> 576000
C34: CRYSTAL ICE 5 KG | D34: 4 | E34: 8000 | F34: =SUM(D34*E34) -> 32000
C35: AQUA REFLECTIONS STILL 750ML | D35: 2 | E35: 115000 | F35: =SUM(D35*E35) -> 230000
C36: AQUA REFLECTIONS SPARKLING 380ML | D36: 1 | E36: 135000 | F36: =SUM(D36*E36) -> 135000
C37: COKE ZERO CAN 330ML | D37: 1 | E37: 135000 | F37: =SUM(D37*E37) -> 135000
A38: 72595 | B38: 45972 | C38: AQUA REFLECTIONS STILL 750ML | D38: 2 | E38: 115000 | F38: =SUM(D38*E38) -> 230000 | G38: =SUM(F38:F41) -> 288000
C39: AQUA GALLON | D39: 1 | E39: 20000 | F39: =SUM(D39*E39) -> 20000
C40: CLEO GALLON | D40: 1 | E40: 22000 | F40: =SUM(D40*E40) -> 22000
...

Sheet DEWATA COCONUT (Coconut)
A1: DATE | B1: INV NO. | C1: DESCRIPTIONS | D1: AMOUNT | E1: BILLS | F1: PRICE | G1: TOTAL
A2: 45963 | B2: 10978 | C2: COCONUT LOGO | D2: 20 | F2: 12000 | G2: =SUM(D2*F2) -> 240000
A3: 45968 | B3: 13028 | C3: COCONUT LOGO | D3: 20 | F3: 12000 | G3: =SUM(D3*F3) -> 240000
A4: 45974 | B4: 11113 | C4: COCONUT LOGO | D4: 15 | F4: 12000 | G4: =SUM(D4*F4) -> 180000
A5: 45976 | B5: 12182 | C5: COCONUT LOGO | D5: 15 | F5: 12000 | G5: =SUM(D5*F5) -> 180000
A6: 45980 | B6: 11206 | C6: COCONUT LOGO | D6: 20 | F6: 12000 | G6: =SUM(D6*F6) -> 240000
A7: 45982 | B7: 11259 | C7: COCONUT LOGO | D7: 20 | F7: 12000 | G7: =SUM(D7*F7) -> 240000
A8: 45985 | B8: 13204 | C8: COCONUT LOGO | D8: 20 | F8: 12000 | G8: =SUM(D8*F8) -> 240000
A9: 45989 | B9: 13311 | C9: COCONUT LOGO | D9: 20 | F9: 12000 | G9: =SUM(D9*F9) -> 240000
E10: =SUM(G2:G9) -> 1800000

Sheet SEDANA JAYA
A1: DATE | B1: ITEM | C1: QYT | D1: PRICE | E1: TOTAL PRICE | F1: TOTAL
A2: 45974 | B2: WATERMELON | C2: 7.5 | D2: 15000 | E2: =SUM(C2*D2) -> 112500 | F2: =SUM(E2:E11) -> 644800
B3: KINTAMANI ORANGE | C3: 3 | D3: 25000 | E3: =SUM(C3*D3) -> 75000
B4: MALANG APPLE | C4: 1 | D4: 61000 | E4: =SUM(C4*D4) -> 61000
B5: CHINESE CABBAGE | C5: 0.5 | D5: 17000 | E5: =SUM(C5*D5) -> 8500
B6: LIME | C6: 0.3 | D6: 28000 | E6: =SUM(C6*D6) -> 8400
B7: SMALL CHILIES | C7: 0.1 | D7: 44000 | E7: =SUM(C7*D7) -> 4400
B8: OAT MEAL | C8: 3 | D8: 55000 | E8: =SUM(C8*D8) -> 165000
B9: SUGAR | C9: 3 | D9: 25000 | E9: =SUM(C9*D9) -> 75000
B10: CUCUMBER | C10: 1 | D10: 15000 | E10: =SUM(C10*D10) -> 15000
B11: STRAWBERRY | C11: 1 | D11: 120000 | E11: =SUM(C11*D11) -> 120000
A12: 45975 | B12: WATERMELON | C12: 11 | D12: 15000 | E12: =SUM(C12*D12) -> 165000 | F12: =SUM(E12:E22) -> 845800
B13: PINEAPPLE | C13: 6 | D13: 10000 | E13: =SUM(C13*D13) -> 60000
B14: IMPORTED LEMON | C14: 2 | D14: 83000 | E14: =SUM(C14*D14) -> 166000
B15: MANGO | C15: 1 | D15: 39000 | E15: =SUM(C15*D15) -> 39000
B16: GREEN APPLE | C16: 1 | D16: 61000 | E16: =SUM(C16*D16) -> 61000
B17: GREEN LIIME | C17: 2 | D17: 28000 | E17: =SUM(C17*D17) -> 56000
B18: GREEN MUSTARD | C18: 1 | D18: 11000 | E18: =SUM(C18*D18) -> 11000
B19: FRESH MILK | C19: 4 | D19: 35000 | E19: =SUM(C19*D19) -> 140000
B20: OAT MILK | C20: 2 | D20: 60000 | E20: =SUM(C20*D20) -> 120000
B21: TRASH BAG | C21: 1 | D21: 20000 | E21: =SUM(C21*D21) -> 20000
B22: GINGER | C22: 0.2 | D22: 39000 | E22: =SUM(C22*D22) -> 7800
A23: 45976 | B23: PINEAPPLE | C23: 10 | D23: 10000 | E23: =SUM(C23*D23) -> 100000 | F23: =SUM(E23:E36) -> 1058800
B24: LUMAJANG ORANGE | C24: 4.4 | D24: 28000 | E24: =SUM(C24*D24) -> 123200
B25: LOCAL LEMON | C25: 2 | D25: 60000 | E25: =SUM(C25*D25) -> 120000
B26: GREEN MUSTARD | C26: 0.3 | D26: 12000 | E26: =SUM(C26*D26) -> 3600
B27: CUCUMBER | C27: 1 | D27: 17000 | E27: =SUM(C27*D27) -> 17000
B28: CARROT | C28: 2 | D28: 31000 | E28: =SUM(C28*D28) -> 62000
B29: MINT | C29: 0.2 | D29: 72000 | E29: =SUM(C29*D29) -> 14400
B30: GREEN APPLE | C30: 2 | D30: 61000 | E30: =SUM(C30*D30) -> 122000
B31: MANGO | C31: 1 | D31: 39000 | E31: =SUM(C31*D31) -> 39000
B32: BASIL | C32: 0.2 | D32: 88000 | E32: =SUM(C32*D32) -> 17600
B33: STRAWBERRY | C33: 0.5 | D33: 120000 | E33: =SUM(C33*D33) -> 60000
B34: GREEN FIELD FRESH MIILK | C34: 6 | D34: 30000 | E34: =SUM(C34*D34) -> 180000
B35: OAT MILK | C35: 1 | D35: 60000 | E35: =SUM(C35*D35) -> 60000
B36: ALMOND MIILK | C36: 2 | D36: 70000 | E36: =SUM(C36*D36) -> 140000
F37: =SUM(F2:F36) -> 2549400

Sheet PNB (Alcohol)
A1: DATE | B1: INV NO. | C1: DESCRIPTIONS | D1: QTY | E1: BILLS | F1: UNIT PRICE | G1: SUB TOTAL | H1: TOTAL
A2: 45961 | B2: SPNO2510622 | C2: JOSE CUERVO GOLD | D2: 3 | F2: 425000 | G2: =D2*F2 -> 1275000 | H2: =SUM(D2*F2) -> 1275000
A3: 45972 | B3: SPNO2511144 | C3: JACK DANIIELS 700 ML | D3: 2 | F3: 500000 | G3: =D3*F3 -> 1000000 | H3: =SUM(G3:G5) -> 3950000
C4: HERRADURA REPOSADO 750 ML | D4: 2 | F4: 775000 | G4: =D4*F4 -> 1550000
C5: HENDRICK GIN 750 ML | D5: 2 | F5: 700000 | G5: =D5*F5 -> 1400000
A6: 45985 | B6: SPN02511408 | C6: HAVANA CLUB ANEJO 3 ANOS 700 ML | D6: 4 | F6: 450000 | G6: =D6*F6 -> 1800000 | H6: =SUM(G6:G6) -> 1800000
H7: =SUM(H2:H6) -> 7025000

Sheet DSP (Alcohol)
A1: DATE | B1: INV NO. | C1: DESCRIPTIONS | D1: QTY | E1: PRICE | F1: DISCOUNT | G1: UNIT PRICE | H1: SUBTOTAL | I1: TOTAL | J1: BILL
A2: 45962 | B2: SO/DSP/25/11/0057 | C2: DA VINCI LEONARDO PROSECCO DOC | D2: 4 | E2: 370000 | F2: =E2*10% -> 37000 | G2: =E2-F2 -> 333000 | H2: =D2*G2 -> 1332000 | I2: =SUM(H2:H3) -> 2376000
C3: DONA DOMINGA CLASICO DE FAILIA SYRAH | D3: 4 | E3: 290000 | F3: =E3*10% -> 29000 | G3: =E3-F3 -> 261000 | H3: =D3*G3 -> 1044000
A4: 45962 | B4: SOMDG/DSP/25/11/0002 | C4: MDG - F VODKA | D4: 3 | E4: 246000 | G4: =E4-F4 -> 246000 | H4: =D4*G4 -> 738000 | I4: =SUM(H4) -> 738000
A5: 45968 | B5: SO/DSP/25/11/0480 | C5: MCGUIGAN - BLACK LABEL SAUVIGNON BLANC | D5: 1 | E5: 295000 | F5: =E5*10% -> 29500 | G5: =E5-F5 -> 265500 | H5: =D5*G5 -> 265500 | I5: =SUM(H5) -> 265500
A6: 45969 | B6: SO/DSP/25/11/0480 | C6: HUNTER'S PINOT GRIS | D6: 2 | E6: 385000 | F6: =E6*10% -> 38500 | G6: =E6-F6 -> 346500 | H6: =D6*G6 -> 693000 | I6: =SUM(H6) -> 693000
A7: 45974 | B7: SO/DSP/25/11/0895 | C7: MCGUIGAN - BLACK LABEL SAUVIGNON BLANC | D7: 3 | E7: 295000 | F7: =E7*10% -> 29500 | G7: =E7-F7 -> 265500 | H7: =D7*G7 -> 796500 | I7: =SUM(H7:H9) -> 2272500
C8: DONA DOMINGA CLASICO DE FAILIA SYRAH | D8: 3 | E8: 290000 | F8: =E8*10% -> 29000 | G8: =E8-F8 -> 261000 | H8: =D8*G8 -> 783000
C9: HUNTER'S RIESLING | D9: 2 | E9: 385000 | F9: =E9*10% -> 38500 | G9: =E9-F9 -> 346500 | H9: =SUM(D9*G9) -> 693000
A10: 45976 | B10: SO/DSP/25/11/1050 | C10: MCGUIGAN - BLACK LABEL SAUVIGNON BLANC | D10: 3 | E10: 295000 | F10: =E10*10% -> 29500 | G10: =E10-F10 -> 265500 | H10: =SUM(D10*G10) -> 796500 | I10: =SUM(H10) -> 796500
A11: 45978 | B11: SO/DSP/25/11/1189 | C11: HUNTER'S PINOT GRIS | D11: 2 | E11: 385000 | F11: =E11*10% -> 38500 | G11: =E11-F11 -> 346500 | H11: =SUM(D11*G11) -> 693000 | I11: =SUM(H11) -> 693000
A12: 45983 | B12: SO/DSP/25/11/1442 | C12: MCGUIGAN - BLACK LABEL SAUVIGNON BLANC | D12: 4 | E12: 295000 | F12: =E12*10% -> 29500 | G12: =E12-F12 -> 265500 | H12: =SUM(D12*G12) -> 1062000 | I12: =SUM(H12) -> 1062000
A13: 45983 | B13: SOPR/ABC/25/11/0312 | C13: HAVANA CLUB 3 YO | D13: 4 | E13: 334000 | G13: =E13-F13 -> 334000 | H13: =SUM(D13*G13) -> 1336000 | I13: =SUM(H13) -> 1336000
A14: 45985 | B14: SO/DSP/25/11/1506 | C14: ANTIGAL - ESTIMULO MALBEC | D14: 3 | E14: 270000 | F14: =E14*10% -> 27000 | G14: =E14-F14 -> 243000 | H14: =SUM(D14*G14) -> 729000 | I14: =SUM(H14) -> 729000
A15: 45989 | B15: SO/DSP/25/11/1807 | C15: MCGUIGAN - BLACK LABEL SAUVIGNON BLANC | D15: 4 | E15: 295000 | F15: =E15*10% -> 29500 | G15: =E15-F15 -> 265500 | H15: =SUM(D15*G15) -> 1062000 | I15: =SUM(H15) -> 1062000
A16: TOTAL | F16: =SUM(I2:I15) -> 12023500

Sheet DSP ARYA BIMA (Alcohol)
A1: DATE | B1: INV NO. | C1: DESCRIPTIONS | D1: QTY | E1: BILLS | F1: PRICE | G1: TOTAL
A3: TOTAL

Sheet SELERA OR STIR UP (Syrup)
A1: DATE | B1: INV NO. | C1: DESCRIPTIONS | D1: QTY | E1: BILLS | F1: PRICE | G1: SUBTOTAL | H1: TOTAL
A2: 45964 | B2: SO-2504340 | C2: LOYAL LYCHEE PET | D2: 3 | F2: 100000 | G2: =D2*F2 -> 300000 | H2: =SUM(G2:G6) -> 1500000
C3: PARADISE PEACH PET | D3: 4 | F3: 100000 | G3: =D3*F3 -> 400000
C4: VOILA VANILLA PET | D4: 3 | F4: 100000 | G4: =D4*F4 -> 300000
C5: CRIMINAL CARAMEL PET | D5: 3 | F5: 100000 | G5: =D5*F5 -> 300000
C6: GROOVY GRAPE | D6: 2 | F6: 100000 | G6: =D6*F6 -> 200000
A7: SUB TOTAL | D7: =SUM(D2:D6) -> 15 | F7: PPN (11%) | H7: =H2*11% -> 165000
A8: TOTAL | E8: =SUM(H2:H7) -> 1665000
E9: GRAND TOTAL | F9: =SUM(E8) -> 1665000

Sheet DW BALI (Alcohol)
A1: DATE | B1: INV NO. | C1: DESCRIPTIONS | D1: AMOUNT | E1: BILLS | F1: PRICE | G1: TOTAL
A2: 45986 | B2: DW/67/088 | C2: ROKU GIN 700 ML | D2: 2 | F2: 620000 | G2: =F2*D2 -> 1240000
A3: 45988 | B3: DW/67/237 | C3: CAMPARI MILANO 750 ML | D3: 2 | F3: 435000 | G3: =F3*D3 -> 870000
A4: GRAND TOTAL | E4: =SUM(G2:G3) -> 2110000

Sheet DDB (Alcohol)
A1: DATE | B1: INV NO. | C1: DESCRIPTIONS | D1: AMOUNT | E1: BILLS | F1: PRICE | G1: TOTAL
A2: 45961 | B2: 36222 | C2: CAPE DISCOVERY BRUT CUVEE 750ML | D2: 4 | F2: 157658 | G2: =SUM(D2*F2) -> 630632
A3: SUB TOTAL | F3: PPN | G3: =G2*11% -> 69369.52
A4: TOTAL | E4: 700001
A5: 45983 | B5: 37685 | C5: GORDON GIN PREMIUM DRY 750 ML | D5: 4 | F5: 236487 | G5: =D5*F5 -> 945948
A6: SUB TOTAL | F6: PPN | G6: =G5*11% -> 104054.28
A7: TOTAL | E7: =SUM(G5:G6) -> 1050002.3
A14: GRAND TOTAL | E14: =SUM(E4+E7+E10+E13) -> 1750003.3

Sheet NANO DEWATA (Alcohol)
A1: DATE | B1: INV NO. | C1: DESCRIPTIONS | D1: AMOUNT | E1: BILLS | F1: PRICE | G1: TOTAL
D2: 3 | G2: =SUM(D2*F2) -> 0
A3: SUB TOTAL | D3: 3
A4: TOTAL | E4: =SUM(G2:G3) -> 0
D5: 3 | G5: =SUM(D5*F5) -> 0
A6: SUB TOTAL | D6: 3
A7: TOTAL | E7: =SUM(G5:G6) -> 0
A14: GRAND TOTAL | E14: =SUM(E4+E7+E10+E13) -> 0

Sheet BALI PERMATA JAYA (Corona Beer)
A1: DATE | B1: INV NO. | C1: DESCRIPTIONS | D1: AMOUNT | E1: BILLS | F1: PRICE | G1: TOTAL | H1: STATUS
A2: 45978 | B2: INV/PERMAQ/25/11/0549 | C2: CORONA BEER | D2: 24 | F2: 44670 | G2: =SUM(D2*F2) -> 1072080
A3: SUB TOTAL | D3: =SUM(D2) -> 24 | F3: PPN | G3: =G2*11% -> 117928.8
A4: TOTAL | E4: =SUM(G2:G3) -> 1190008.8
G5: =SUM(D5*F5) -> 0
A6: SUB TOTAL | D6: =SUM(D5) -> 0 | F6: PPN | G6: =G5*11% -> 0
A7: TOTAL | E7: =SUM(G5:G6) -> 0
G8: =SUM(D8*F8) -> 0
A9: SUB TOTAL | F9: PPN | G9: =G8*11% -> 0
A10: TOTAL | E10: =SUM(G8:G9) -> 0
G11: =SUM(D11*F11) -> 0
A12: SUB TOTAL | F12: PPN | G12: =G11*11% -> 0
A13: TOTAL | E13: =SUM(G11:G12) -> 0
A15: SUB TOTAL | F15: PPN | G15: =G14*11% -> 0
A16: TOTAL | E16: =SUM(G14:G15) -> 0
A17: GRAND TOTAL | E17: =E4+E7+E10+E13+E16 -> 1190008.8

Sheet BLACK COFFEE ROASTERS (Coffee)
A1: DATE | B1: INV NO. | C1: DESCRIPTIONS | D1: QTY | E1: PRICE | F1: BILLS | G1: TOTAL
A2: 45971 | B2: BL2-10-2166 | C2: CANGGU BLEND 1 KG | D2: 10 | E2: 280000 | G2: =SUM(D2*E2) -> 2800000
A3: 45985 | B3: BL2-10-2232 | C3: CANGGU BLEND 1 KG | D3: 10 | E3: 280000 | G3: =SUM(D3*E3) -> 2800000
A4: Total | F4: =SUM(G2:G3) -> 5600000

Sheet PT. PRASIDA LANTUR MAJU (Wine)
A1: DATE | B1: INV NO. | C1: DESCRIPTIONS | D1: QTY | E1: BILLS | F1: PRICE | G1: TOTAL
A2: 45962 | B2: PLM-INV4286/025 | C2: ISOLA BLANCO 750ML | D2: 3 | F2: 180180 | G2: =SUM(D2*F2) -> 540540
A3: SUBTOTAL | D3: =SUM(D2) -> 3 | F3: PPN | G3: =G2*11% -> 59459.4
A4: TOTAL | E4: 600000
A7: TOTAL | E7: =SUM(G5:G6) -> 0
A8: GRAND TOTAL | E8: =E4+E7 -> 600000

Sheet PT LOVINA BEACH BREWERY
A1: DATE | B1: INV NO. | C1: DESCRIPTIONS | D1: BILLS | E1: TOTAL | F1: STATUS
A3: TOTAL | D3: =SUM(E2:E2) -> 0

Sheet CHAI CHITAI (Tea Leaf,etc)
A1: DATE | B1: INV NO. | C1: DESCRIPTIONS | D1: QTY | E1: BILLS | F1: PRICE | G1: TOTAL
A12: GRAND TOTAL | E12: =SUM(G7+G11) -> 0

Sheet MULIA JAYA (Passion Fruit)
A1: DATE | B1: DESCRIPTIONS | C1: QTY | D1: BILLS | E1: PRICE | F1: TOTAL | G1: STATUS
A2: 45982 | B2: PASSION FRUIT | C2: 6 | E2: 50000 | F2: =C2*E2 -> 300000 | G2: PAID
A3: TOTAL

Sheet Dewata Kencana Distribusi (Vdka
A1: DATE | B1: DESCRIPTIONS | C1: QTY | D1: BILLS | E1: UNIT PRICE | F1: TOTAL | G1: STATUS
F3: =SUM(F2:F2) -> 0

Sheet TOTAL
A1: NO | B1: SUPPLIER | C1: TOTAL
A2: 1 | B2: BUK BUNGA | C2: ='BUK BUNGA (Groceries)'!F275 -> 19433000
A3: 2 | B3: TOKO EKA WHOLESALE | C3: ='WARUNG EKA (Drinks, Etc)'!G118 -> 12478500
A4: 3 | B4: DEWATA COCONUT | C4: ='DEWATA COCONUT (Coconut)'!E10 -> 1800000
A5: 4 | B5: SEDANA JAYA | C5: ='SEDANA JAYA'!F37 -> 2549400
A6: 5 | B6: PNB | C6: ='PNB (Alcohol)'!H7 -> 7025000
A7: 6 | B7: DSP | C7: ='DSP (Alcohol)'!F16 -> 12023500
A8: 7 | B8: DSP ARYA BIMA | C8: ='DSP ARYA BIMA (Alcohol)'!E3 -> 0
A9: 8 | B9: SELERA (SYRUP) | C9: ='SELERA OR STIR UP (Syrup)'!F9 -> 1665000
A10: 9 | B10: DW BALI | C10: ='DW BALI (Alcohol)'!E4 -> 2110000
A11: 10 | B11: DDB | C11: ='DDB (Alcohol)'!E14 -> 1750003.3
A12: 11 | B12: NANO DEWATA | C12: ='NANO DEWATA (Alcohol)'!E14 -> 0
A13: 12 | B13: BALI PERMATA JAYA | C13: ='BALI PERMATA JAYA (Corona Beer)'!E17 -> 1190008.8
A14: 13 | B14: BLACK COFFEE ROASTERY | C14: ='BLACK COFFEE ROASTERS (Coffee)'!F4 -> 5600000
A15: 14 | B15: PRASIDA LANTUR MAJU | C15: ='PT. PRASIDA LANTUR MAJU (Wine)'!E8 -> 600000
A16: 15 | B16: PT. LOVINA BEACH BREWERY | C16: ='PT LOVINA BEACH BREWERY'!D3 -> 0
A17: 16 | B17: CHAI CHITAI | C17: ='CHAI CHITAI (Tea Leaf,etc)'!E12 -> 0
A18: 17 | B18: MULIA JAYA | C18: ='MULIA JAYA (Passion Fruit)'!D3 -> 0
A19: 18 | B19: DEWATA KENCANA DISTRIBUSI | C19: ='Dewata Kencana Distribusi (Vdka'!F3 -> 0
A20: TOTAL | C20: =SUM(C2:C13) -> 62024412
