Workbook

Sheet BUK BUNGA (Groceries)
A1: DATE | B1: ITEM | C1: QYT | D1: PRICE | E1: SUBTOTAL | F1: TOTAL
A2: 45962 | B2: BABY ROMAINE LETTUCE | C2: 0.5 | D2: 40000 | E2: =SUM(C2*D2) -> 20000 | F2: =SUM(E2:E15) -> 1745000
B3: RED LOLLO ROSSO | C3: 0.3 | D3: 80000 | E3: =SUM(C3*D3) -> 24000
B4: WILD ROCKET | C4: 0.3 | D4: 80000 | E4: =SUM(C4*D4) -> 24000
B5: PARSLEY | C5: 0.1 | D5: 60000 | E5: =SUM(C5*D5) -> 6000
B6: OLIVE OIL (1 LITER) | C6: 1 | D6: 360000 | E6: =SUM(C6*D6) -> 360000
B7: MILAC WHIPPING CREAM | C7: 2 | D7: 90000 | E7: =SUM(C7*D7) -> 180000
B8: MAESTRO MAYONNAISE | C8: 2 | D8: 35000 | E8: =SUM(C8*D8) -> 70000
B9: CHEDDAR CHEESE SLICE | C9: 25 | D9: 15000 | E9: =SUM(C9*D9) -> 375000
B10: BBQ SAUCE | C10: 3 | D10: 40000 | E10: =SUM(C10*D10) -> 120000
B11: BAKING PAPER | C11: 2 | D11: 40000 | E11: =SUM(C11*D11) -> 80000
B12: SEMOLINA | C12: 2 | D12: 58000 | E12: =SUM(C12*D12) -> 116000
B13: ROMA KELAPA BISCUIT | C13: 2 | D13: 15000 | E13: =SUM(C13*D13) -> 30000
B14: BACON (1 KG) | C14: 1 | D14: 170000 | E14: =SUM(C14*D14) -> 170000
B15: HAM (1KG) | C15: 1 | D15: 170000 | E15: =SUM(C15*D15) -> 170000
A16: 45963 | B16: OIL | C16: 1 | D16: 100000 | E16: =SUM(C16*D16) -> 100000 | F16: =SUM(E16:E26) -> 1339000
B17: SOUR CREAM | C17: 1 | D17: 160000 | E17: =SUM(C17*D17) -> 160000
B18: TORTILLA WRAP | C18: 2 | D18: 90000 | E18: =SUM(C18*D18) -> 180000
B19: SPINACH | C19: 0.5 | D19: 120000 | E19: =SUM(C19*D19) -> 60000
B20: CREAM CHEESE | C20: 1 | D20: 170000 | E20: =SUM(C20*D20) -> 170000
B21: MOZARELLA CHEESE | C21: 1 | D21: 390000 | E21: =SUM(C21*D21) -> 390000
B22: BACON | C22: 1 | D22: 170000 | E22: =SUM(C22*D22) -> 170000
B23: MUSHROOM BUTTON | C23: 1 | D23: 48000 | E23: =SUM(C23*D23) -> 48000
B24: ROSEMARY | C24: 0.1 | D24: 150000 | E24: =SUM(C24*D24) -> 15000
B25: THYME | C25: 0.1 | D25: 300000 | E25: =SUM(C25*D25) -> 30000
B26: BASIL | C26: 0.2 | D26: 80000 | E26: =SUM(C26*D26) -> 16000
A27: 45964 | B27: MILK | C27: 2 | D27: 22000 | E27: =SUM(C27*D27) -> 44000 | F27: =SUM(E27:E44) -> 2169000
B28: MILAC WHIPPING CREAM | C28: 3 | D28: 90000 | E28: =SUM(C28*D28) -> 270000
B29: KEWPIE MAYONNAISE | C29: 1 | D29: 100000 | E29: =SUM(C29*D29) -> 100000
B30: ZUCCHINI | C30: 2 | D30: 40000 | E30: =SUM(C30*D30) -> 80000
B31: SHIMEJI | C31: 2 | D31: 18000 | E31: =SUM(C31*D31) -> 36000
B32: OIL | C32: 1 | D32: 100000 | E32: =SUM(C32*D32) -> 100000
B33: COCONUT CREAM KARA | C33: 1 | D33: 220000 | E33: =SUM(C33*D33) -> 220000
B34: OLIVE OIL (1 LITER) | C34: 1 | D34: 360000 | E34: =SUM(C34*D34) -> 360000
B35: LEMON | C35: 1 | D35: 30000 | E35: =SUM(C35*D35) -> 30000
B36: GORGONZOLA | C36: 1 | D36: 195000 | E36: =SUM(C36*D36) -> 195000
B37: RED LETTUCE (SELADA MERAH) | C37: 0.3 | D37: 80000 | E37: =SUM(C37*D37) -> 24000
B38: PINEAPPLE | C38: 4 | D38: 10000 | E38: =SUM(C38*D38) -> 40000
B39: BANANA | C39: 26 | D39: 2000 | E39: =SUM(C39*D39) -> 52000
B40: DRAGON FRUIT | C40: 1.8 | D40: 28000 | E40: 50000
...

Sheet SEDANA JAYA (Groceries)
A1: DATE | B1: ITEM | C1: QYT | D1: PRICE | E1: TOTAL PRICE | F1: TOTAL
A2: 45962 | B2: CORIANDER | C2: 0.05 | D2: 110000 | E2: =SUM(C2*D2) -> 5500 | F2: =SUM(E2:E17) -> 1341300
B3: SHALLOT | C3: 0.3 | D3: 61000 | E3: =SUM(C3*D3) -> 18300
B4: GARLIC | C4: 0.3 | D4: 55000 | E4: =SUM(C4*D4) -> 16500
B5: DRAGON FRUIT | C5: 1 | D5: 28000 | E5: =SUM(C5*D5) -> 28000
B6: ZUCCHINI | C6: 1 | D6: 50000 | E6: =SUM(C6*D6) -> 50000
B7: POTATO | C7: 5 | D7: 24000 | E7: =SUM(C7*D7) -> 120000
B8: BAKING PAPER | C8: 2 | D8: 350000 | E8: =SUM(C8*D8) -> 700000
B9: SEMOLINA | C9: 2 | D9: 75000 | E9: =SUM(C9*D9) -> 150000
B10: MANGO | C10: 1 | D10: 39000 | E10: =SUM(C10*D10) -> 39000
B11: AVOCADO | C11: 1 | D11: 39000 | E11: =SUM(C11*D11) -> 39000
B12: LOCAL LEMON | C12: 1 | D12: 50000 | E12: =SUM(C12*D12) -> 50000
B13: PINEAPPLE | C13: 2 | D13: 10000 | E13: =SUM(C13*D13) -> 20000
B14: STRAWBERRY | C14: 0.2 | D14: 83000 | E14: =SUM(C14*D14) -> 16600
... B17: CHERRY YELLOW TOMATO | C17: 0.4 | D17: 61000 | E17: =SUM(C17*D17) -> 24400
A18: 45963 | B18: BASMATI RICE | C18: 2 | D18: 80000 | E18: =SUM(C18*D18) -> 160000 | F18: =SUM(E18:E38) -> 1433800
B19: SUGAR | C19: 2 | D19: 25000 | E19: =SUM(C19*D19) -> 50000
B20: SWEET POTATO | C20: 5 | D20: 25000 | E20: =SUM(C20*D20) -> 125000
B21: ONION | C21: 4 | D21: 39000 | E21: =SUM(C21*D21) -> 156000
B22: BANANA | C22: 5 | D22: 22000 | E22: =SUM(C22*D22) -> 110000
B23: EGGS | C23: 5 | D23: 66000 | E23: =SUM(C23*D23) -> 330000
B24: OREGANO | C24: 2 | D24: 45000 | E24: =SUM(C24*D24) -> 90000
B25: HONEY BLOSSOM | C25: 2 | D25: 50000 | E25: =SUM(C25*D25) -> 100000
B26: LEEK | C26: 0.1 | D26: 33000 | E26: =SUM(C26*D26) -> 3300
B27: PARSLEY | C27: 0.1 | D27: 83000 | E27: =SUM(C27*D27) -> 8300
B28: GARLIC | C28: 0.2 | D28: 55000 | E28: =SUM(C28*D28) -> 11000
B29: EGGPLANT | C29: 1 | D29: 9000 | E29: =SUM(C29*D29) -> 9000
B30: TOMATO | C30: 1.5 | D30: 17000 | E30: =SUM(C30*D30) -> 25500
... B38: MANGO | C38: 1 | D38: 39000 | E38: =SUM(C38*D38) -> 39000
A39: 45963 | B39: EDAMAME | C39: 1 | D39: 30000 | E39: =SUM(C39*D39) -> 30000 | F39: =SUM(E39:E40) -> 38800
B40: BASIL | C40: 0.1 | D40: 88000 | E40: =SUM(C40*D40) -> 8800
A41: 45964 | B41: KEWPIE MAYONNAISE | C41: 1 | D41: 130000 | E41: =SUM(C41*D41) -> 130000 | F41: =SUM(E41:E62) -> 1869700
B42: BIG RED CHILI | C42: 0.3 | D42: 72000 | E42: =SUM(C42*D42) -> 21600
B43: SHALLOT | C43: 0.3 | D43: 61000 | E43: =SUM(C43*D43) -> 18300
B44: LEEK | C44: 0.1 | D44: 132000 | E44: =SUM(C44*D44) -> 13200
B45: TOMATO | C45: 1 | D45: 17000 | E45: =SUM(C45*D45) -> 17000
B46: DRAGON FRUIT | C46: 2 | D46: 28000 | E46: =SUM(C46*D46) -> 56000
B47: SHIMEJI | C47: 2 | D47: 25000 | E47: =SUM(C47*D47) -> 50000
B48: POTATO | C48: 10 | D48: 24000 | E48: =SUM(C48*D48) -> 240000
B49: EGGS | C49: 5 | D49: 66000 | E49: =SUM(C49*D49) -> 330000
...

Sheet RAFI SEAFOOD (Seafood)
A1: DATE | B1: DESCRIPTION | C1: QUANTITY | D1: PRICE | E1: BILLS | F1: SUBTOTAL | G1: TOTAL
A2: 45963 | B2: SALMON FL | C2: 4.7 | D2: 370000 | E2: =_xlfn.DISPIMG("ID_61A6B6D73D3A4854A82E473D394FEE5A",1) -> =DISPIMG("ID_61A6B6D73D3A4854A82E473D394FEE5A",1) | F2: =SUM(C2*D2) -> 1739000 | G2: =SUM(F2:F4) -> 2159500
B3: MAHI FL | C3: 1.7 | D3: 115000 | F3: =SUM(C3*D3) -> 195500
B4: CHICKEN WING | C4: 5 | D4: 45000 | F4: =SUM(C4*D4) -> 225000
A5: 45965 | B5: P20 | C5: 3 | D5: 180000 | E5: =_xlfn.DISPIMG("ID_7BF01879F5304626B866F9D1EC0B9718",1) -> =DISPIMG("ID_7BF01879F5304626B866F9D1EC0B9718",1) | F5: =SUM(C5*D5) -> 540000 | G5: =SUM(F5:F6) -> 1428000
B6: SALMON FL | C6: 2.4 | D6: 370000 | F6: =SUM(C6*D6) -> 888000
A7: 45968 | B7: P20 | C7: 3 | D7: 180000 | E7: =_xlfn.DISPIMG("ID_1931EB1B8CC94F76A8E1ECCB232924DE",1) -> =DISPIMG("ID_1931EB1B8CC94F76A8E1ECCB232924DE",1) | F7: =SUM(C7*D7) -> 540000 | G7: =SUM(C7*D7+C8*D8+C11*D11) -> 2382000
B8: TUBE SQUID | C8: 3 | D8: 85000 | F8: =SUM(C8*D8) -> 255000
B9: MAHI FL | C9: 1.9 | D9: 115000
B10: SALMON FL | C10: 1.7 | D10: 370000
B11: TUNA | C11: 13.8 | D11: 115000 | F11: =SUM(C11*D11) -> 1587000
A12: 45971 | B12: P20 | C12: 2 | D12: 180000 | E12: =_xlfn.DISPIMG("ID_C9ED45B96FB44D8A8EA9EB8F2BDEF5E7",1) -> =DISPIMG("ID_C9ED45B96FB44D8A8EA9EB8F2BDEF5E7",1) | F12: =SUM(C12*D12) -> 360000 | G12: =SUM(F12:F13) -> 460000
B13: CLAM | C13: 2 | D13: 50000 | F13: =SUM(C13*D13) -> 100000
A14: 45972 | B14: P20 | C14: 5 | D14: 180000 | E14: =_xlfn.DISPIMG("ID_ED1EE2DFF883415D8D5E1866FC075DE1",1) -> =DISPIMG("ID_ED1EE2DFF883415D8D5E1866FC075DE1",1) | F14: =C14*D14 -> 900000 | G14: =SUM(F14:F15) -> 1070000
B15: TUBE SQUID | C15: 2 | D15: 85000 | F15: =C15*D15 -> 170000
A16: 45974 | B16: SALMON FL | C16: 3.8 | D16: 370000 | E16: =_xlfn.DISPIMG("ID_DD7C71329EF1420BB6A1F509D8242FB3",1) -> =DISPIMG("ID_DD7C71329EF1420BB6A1F509D8242FB3",1) | F16: =SUM(C16*D16) -> 1406000 | G16: =SUM(C16*D16+C17*D17+C18*D18) -> 2024000
B17: CHICKEN LEG FL | C17: 5 | D17: 60000 | F17: =SUM(C17*D17) -> 300000
B18: CHICKEN BREAST FL | C18: 5.3 | D18: 60000 | F18: =SUM(C18*D18) -> 318000
A19: 45978 | B19: TUNA | C19: 14.6 | D19: 120000 | E19: =_xlfn.DISPIMG("ID_5B5F1B4600184CE69D0AAC65BDEFB0F0",1) -> =DISPIMG("ID_5B5F1B4600184CE69D0AAC65BDEFB0F0",1) | F19: =SUM(C19*D19) -> 1752000 | G19: =SUM(F19:F23) -> 5477000
B20: SALMON | C20: 5.6 | D20: 370000 | F20: =SUM(C20*D20) -> 2072000
B21: MAHI-MAHI | C21: 3.6 | D21: 115000 | F21: =SUM(C21*D21) -> 414000
B22: PRAWN | C22: 4.4 | D22: 185000 | F22: =SUM(C22*D22) -> 814000
B23: SQUID TUBE | C23: 5 | D23: 85000 | F23: =SUM(C23*D23) -> 425000
A24: 45984 | B24: PRAWN | C24: 2.9 | D24: 185000 | E24: =_xlfn.DISPIMG("ID_A0F30E7669374D90B0122D8131BA4785",1) -> =DISPIMG("ID_A0F30E7669374D90B0122D8131BA4785",1) | F24: =SUM(C24*D24) -> 536500 | G24: =SUM(C24*D24+C25*D25) -> 1551250
B25: SALMON | C25: 3.69 | D25: 275000 | F25: =SUM(C25*D25) -> 1014750
A26: 45986 | B26: TUNA | C26: 7.9 | D26: 120000 | E26: =_xlfn.DISPIMG("ID_178B981EF0C2474B958D59670E886CC4",1) -> =DISPIMG("ID_178B981EF0C2474B958D59670E886CC4",1) | F26: =SUM(C26*D26) -> 948000 | G26: =SUM(F26:F29) -> 1938500
B27: MAHI-MAHI | C27: 3.6 | D27: 115000 | F27: =SUM(C27*D27) -> 414000
B28: CHICKEN WING | C28: 5 | D28: 45000 | F28: =SUM(C28*D28) -> 225000
B29: PRAWN | C29: 1.9 | D29: 185000 | F29: =SUM(C29*D29) -> 351500
F30: =C30*D30 -> 0 | G30: =SUM(F30:F32) -> 0
F31: =C31*D31 -> 0
F32: =C32*D32 -> 0
F33: =SUM(C33*D33) -> 0 | G33: =SUM(F33:F35) -> 0
F34: =SUM(C34*D34) -> 0
F35: =SUM(C35*D35) -> 0
D61: =SUM(G2:G60) -> 18490250

Sheet MAMA RADA PRODUCTION (Dumpling)
A1: DATE | B1: INV NO. | C1: DESCRIPTIONS | D1: QTY | E1: BIILS | F1: PRICE | G1: SUBTOTAL | H1: TOTAL
A2: 45966 | B2: SI202511050008 | C2: MEAT DUMPLINGS | D2: 2 | E2: =_xlfn.DISPIMG("ID_75F57DB5C38C465492093AF388167662",1) -> =DISPIMG("ID_75F57DB5C38C465492093AF388167662",1) | F2: 160000 | G2: =D2*F2 -> 320000 | H2: =SUM(G2) -> 320000
G3: =SUM(D3*F3+D4*F4) -> 0
G5: =SUM(D5*F5+D6*F6+D7*F7) -> 0
G8: =SUM(D8*F8) -> 0
E12: GRAND TOTAL | H12: =SUM(H2:H11) -> 320000

Sheet KSP (Chicken)
A1: DATE | B1: INV NO. | C1: DESCRIPTIONS | D1: QTY | E1: BILLS | F1: PRICE | G1: SUB TOTAL | H1: TOTAL
A2: 45965 | B2: B00330/PRN-R/2025 | C2: BONELESS BREAST TK SP | D2: 7.9 | E2: =_xlfn.DISPIMG("ID_BC41213F5DF34C9FA380163A0DB01F5E",1) -> =DISPIMG("ID_BC41213F5DF34C9FA380163A0DB01F5E",1) | F2: 48000 | G2: =SUM(D2*F2) -> 379200 | H2: =SUM(D2*F2+D3*F3) -> 1118400
C3: BONELESS LEG TK SP | D3: 15.4 | F3: 48000 | G3: =SUM(D3*F3) -> 739200
A4: 45968 | B4: B00355/PRN-R/2025 | C4: BONELESS BREAST TK SP | D4: 5.8 | E4: =_xlfn.DISPIMG("ID_840C154ED5C648A3AFFBFA4A3E161E08",1) -> =DISPIMG("ID_840C154ED5C648A3AFFBFA4A3E161E08",1) | F4: 48000 | G4: =SUM(D4*F4) -> 278400 | H4: =SUM(D4*F4+D5*F5+D6*F6) -> 960600
C5: BONELESS LEG TK SP | D5: 10.6 | F5: 48000 | G5: =SUM(D5*F5) -> 508800
C6: WING TD | D6: 5.1 | F6: 34000 | G6: =SUM(D6*F6) -> 173400
A7: 45975 | B7: B00418/PRN-R/2025 | C7: BONELESS BREAST TK SP | D7: 5.8 | E7: =_xlfn.DISPIMG("ID_E04E53902D31429B9CCCC3BF0D548570",1) -> =DISPIMG("ID_E04E53902D31429B9CCCC3BF0D548570",1) | F7: 48000 | G7: =SUM(D7*F7) -> 278400 | H7: =SUM(G7:G8) -> 782400
C8: BONELESS LEG TK SP | D8: 10.5 | F8: 48000 | G8: =SUM(D8*F8) -> 504000
A9: 45980 | B9: B14829/2025M | C9: BONELESS BREAST TK SP FROZEN | D9: 4.85 | E9: =_xlfn.DISPIMG("ID_D0D7F85949BC4377AA6D333D4CD41D95",1) -> =DISPIMG("ID_D0D7F85949BC4377AA6D333D4CD41D95",1) | F9: 50000 | G9: =D9*F9 -> 242500 | H9: =SUM(G9:G10) -> 1187250
C10: BONELESS LEG TK SP FROZEN | D10: 18.895 | F10: 50000 | G10: =D10*F10 -> 944750
A11: 45989 | B11: B00475/PRN-R/2025 | C11: BONELESS BREAST TK SP | D11: 5.6 | E11: =_xlfn.DISPIMG("ID_3B01175CA21E443B8591D01EA0BFD05B",1) -> =DISPIMG("ID_3B01175CA21E443B8591D01EA0BFD05B",1) | F11: 52000 | G11: =D11*F11 -> 291200 | H11: =SUM(G11:G12) -> 1021200
C12: BONELESS LEG TK SP | D12: 14.6 | F12: 50000 | G12: =D12*F12 -> 730000
E13: =SUM(H2:H11) -> 5069850

Sheet SURYA CIPTA NIAGA BALI (Beef)
A1: DATE | B1: INV NO. | C1: DESCRIPTIONS | D1: QTY | E1: BILLS | F1: PRICE | G1: SUBTOTAL | H1: TOTAL | I1: STATUS
A2: 45962 | B2: 2511/FK-0104 | C2: STRIPLOIN ICHI BROWN | D2: 11.79 | E2: =_xlfn.DISPIMG("ID_B7457DA6CFC04C12B9163F9E9156146E",1) -> =DISPIMG("ID_B7457DA6CFC04C12B9163F9E9156146E",1) | F2: 180000 | G2: =D2*F2 -> 2122200 | H2: =SUM(G2:G3) -> 5277200
C3: TOP SIDE BLACK ANGUS GF ONYX | D3: 12.62 | F3: 250000 | G3: =D3*F3 -> 3155000
A4: 45976 | B4: 2511/FK-1864 | C4: STRIPLOIN ICHI BROWN | D4: 11.28 | E4: =_xlfn.DISPIMG("ID_AD391E00A66A474F8756047855F2805B",1) -> =DISPIMG("ID_AD391E00A66A474F8756047855F2805B",1) | F4: 180000 | G4: =D4*F4 -> 2030400 | H4: =SUM(G4:G5) -> 8140400
C5: TOPSIDE WAGYU ONYX | D5: 24.44 | F5: 250000 | G5: =D5*F5 -> 6110000
G6: =D6*F6 -> 0 | H6: =SUM(D6*F6) -> 0
G8: =D8*F8 -> 0 | H8: =SUM(D8*F8) -> 0
A9: TOTAL | H9: =SUM(H4:H8) -> 8140400

Sheet BAYU AGNI MERTA (Gas)
A1: DATE | B1: INV NO. | C1: DESCRIPTIONS | D1: QTY | E1: BILLS | F1: PRICE | G1: TOTAL
A2: 45976 | B2: 0505 | C2: LPG 50KG | D2: 4 | E2: =_xlfn.DISPIMG("ID_54351053BC8E46418B4A98193A9A278C",1) -> =DISPIMG("ID_54351053BC8E46418B4A98193A9A278C",1) | F2: 975000 | G2: =SUM(D2*F2) -> 3900000
G3: =D3*F3 -> 0
A4: TOTAL | E4: =SUM(G2:G3) -> 3900000

Sheet Joy Green (Mix Berry)
A1: NO | B1: DATE | C1: TOTAL | D1: PC | E1: STATUS
A3: Total | D3: =SUM(C2:C2) -> 0

Sheet CELEBRITY BAKERY (Bakery)
A1: DATE | B1: INV.NO | C1: DESCRIPTION | D1: QTY | E1: BILLS | F1: PRICE | G1: TOTAL
A5: TOTAL | E5: =SUM(G2) -> 0

Sheet Krop (Edible flower)
A1: DATE | B1: INV.NO | C1: DESCRIPTION | D1: QTY | E1: BILLS | F1: PRICE | G1: SUBTOTAL | H1: TOTAL
A2: 45981 | B2: 113900 | C2: EDIBLE FLOWER MIX (N) | D2: 1 | E2: =_xlfn.DISPIMG("ID_C848E8246FB7453D95C66010065E8B54",1) -> =DISPIMG("ID_C848E8246FB7453D95C66010065E8B54",1) | F2: 35000 | G2: =D2*F2 -> 35000 | H2: =SUM(G2:G2) -> 35000
A3: 45981 | B3: 113901 | C3: EDIBLE FLOWER (N) | D3: 1 | E3: =_xlfn.DISPIMG("ID_58B4EF0B2AA4427C939B2DA3AAE48B25",1) -> =DISPIMG("ID_58B4EF0B2AA4427C939B2DA3AAE48B25",1) | F3: 35000 | G3: =D3*F3 -> 35000 | H3: =SUM(G3:G6) -> 117000
C4: STARFLOWER (20 GR) | D4: 1 | F4: 35000 | G4: =D4*F4 -> 35000
C5: GREEN MUSTARD | D5: 1 | F5: 22000 | G5: =D5*F5 -> 22000
C6: RED RADISH | D6: 1 | F6: 25000 | G6: =D6*F6 -> 25000
A7: TOTAL | H7: =SUM(H2:H6) -> 152000

Sheet Boiler (Dumplings&Syrniki)
A1: DATE | B1: INV.NO | C1: DESCRIPTION | D1: QTY | E1: BILLS | F1: PRICE | G1: SUBTOTAL | H1: TOTAL | I1: TOTAL AFTER TAX
G2: =D2*F2 -> 0 | H2: =SUM(G2:G4) -> 0 | I2: =(H2*10%)+H2 -> 0
G3: =D3*F3 -> 0
G4: =D4*F4 -> 0
A5: TOTAL | E5: =SUM(I2) -> 0

Sheet Abdi Jaya (TKW, Vacuum Bag)
A1: DATE | B1: INV.NO | C1: DESCRIPTION | D1: QTY | E1: BILLS | F1: PRICE | G1: SUBTOTAL | H1: TOTAL
A2: 45961 | B2: 1825 | C2: LAP MICROFIBER HANAGA | D2: 5 | E2: =_xlfn.DISPIMG("ID_17DCA37126B64375B1E971D9A82062AB",1) -> =DISPIMG("ID_17DCA37126B64375B1E971D9A82062AB",1) | F2: 25000 | G2: =D2*F2 -> 125000 | H2: =SUM(G2:G3) -> 230000
C3: BOTOL PEMB 500 ML | D3: 7 | F3: 15000 | G3: =D3*F3 -> 105000
A4: 45966 | B4: 1919 | C4: LUNCH BOX L BROWN | D4: 5 | E4: =_xlfn.DISPIMG("ID_C9ADF786CFF24CE1BB935EEA7A797571",1) -> =DISPIMG("ID_C9ADF786CFF24CE1BB935EEA7A797571",1) | F4: 85000 | G4: =D4*F4 -> 425000 | H4: =SUM(G4:G5) -> 595000
C5: LONG HAND TOWEL SEE YOU | D5: 1 | F5: 170000 | G5: =D5*F5 -> 170000
A6: 45982 | B6: 471 | C6: HAND GLOVE L | D6: 3 | E6: =_xlfn.DISPIMG("ID_2C31F25015B34051AF8982974BA995BD",1) -> =DISPIMG("ID_2C31F25015B34051AF8982974BA995BD",1) | F6: 55000 | G6: =D6*F6 -> 165000 | H6: =SUM(G6:G7) -> 195000
C7: P KILAT 32 | D7: 1 | F7: 30000 | G7: =D7*F7 -> 30000
A8: GRAND TOTAL | D8: =SUM(H4) -> 595000

Sheet Dishy Soap (Chemicals)
A1: DATE | B1: DESCRIPTION | C1: QTY | D1: BILLS | E1: PRICE | F1: SUBTOTAL | G1: TOTAL
A2: 45968 | B2: DISINFECTANT 5L | C2: 1 | D2: =_xlfn.DISPIMG("ID_572945C48E0B49BFB280D76E62452999",1) -> =DISPIMG("ID_572945C48E0B49BFB280D76E62452999",1) | E2: 95000 | F2: =C2*E2 -> 95000 | G2: =SUM(F2:F6) -> 515000
B3: HD SNT GEL 5L | C3: 1 | E3: 200000 | F3: =C3*E3 -> 200000
B4: DISHY 5L | C4: 2 | E4: 55000 | F4: =C4*E4 -> 110000
B5: DISHY HANDWASH | C5: 1 | E5: 60000 | F5: =C5*E5 -> 60000
B6: LIQUID DETERGENT | C6: 1 | E6: 50000 | F6: =C6*E6 -> 50000
A7: 45975 | B7: DISHY 5L | C7: 3 | D7: =_xlfn.DISPIMG("ID_7224370257A0448C93AE4AA79F37205D",1) -> =DISPIMG("ID_7224370257A0448C93AE4AA79F37205D",1) | E7: 55000 | F7: =C7*E7 -> 165000 | G7: =SUM(F7:F9) -> 315000
B8: DISINFECTAN 5L | C8: 1 | E8: 95000 | F8: =C8*E8 -> 95000
B9: FLOOR CLEANER | C9: 1 | E9: 55000 | F9: =C9*E9 -> 55000
A10: 45982 | B10: DISHY 5L | C10: 1 | D10: =_xlfn.DISPIMG("ID_3E1B11DEFFB948E4B654DAF46EF42C73",1) -> =DISPIMG("ID_3E1B11DEFFB948E4B654DAF46EF42C73",1) | E10: 55000 | F10: =SUM(E10) -> 55000 | G10: =SUM(F10) -> 55000
A11: GRAND TOTAL | G11: =SUM(G2) -> 515000

Sheet Abiseka (Fresh Milk)
A1: DATE | B1: DESCRIPTION | C1: QTY | D1: BILLS | E1: PRICE | F1: SUBTOTAL | G1: TOTAL
A3: GRAND TOTAL | G3: =SUM(G2) -> 0

Sheet TOTAL
A1: SUPPLIER | B1: Total
A2: BU BUNGA | B2: ='BUK BUNGA (Groceries)'!F467 -> 38122200
A3: SEDANA JAYA | B3: ='SEDANA JAYA (Groceries)'!F660 -> 38255970
A4: RAFI SEAFOOD | B4: ='RAFI SEAFOOD (Seafood)'!D61 -> 18490250
A5: MAMA RADA PRODUCTION | B5: ='MAMA RADA PRODUCTION (Dumpling)'!H12 -> 320000
A6: KSP | B6: ='KSP (Chicken)'!E13 -> 5069850
A7: SURYA CIPTA NIAGA BALI | B7: ='SURYA CIPTA NIAGA BALI (Beef)'!E9 -> 0
A8: BAYU AGNI MERTA | B8: ='BAYU AGNI MERTA (Gas)'!E4 -> 3900000
A9: JOY GREEN | B9: ='Joy Green (Mix Berry)'!D3 -> 0
A10: CELEBRITY BAKERY | B10: ='CELEBRITY BAKERY (Bakery)'!E5 -> 0
A11: KROP NATIION | B11: ='Krop (Edible flower)'!H7 -> 152000
A12: BOILER | B12: ='Boiler (Dumplings&Syrniki)'!E5 -> 0
A13: ABDI JAYA | B13: ='Abdi Jaya (TKW, Vacuum Bag)'!D8 -> 595000
A14: DISHY SOAP | B14: ='Dishy Soap (Chemicals)'!G11 -> 515000
A15: ABISEKA | B15: ='Abiseka (Fresh Milk)'!G3 -> 0
A16: TOTAL | B16: =SUM(B2:B12) -> 104310270
