Workbook

Sheet BUK BUNGA (Groceries)
A1: DATE | B1: ITEM | C1: QYT | D1: PRICE | E1: SUBTOTAL | F1: TOTAL
A2: 45994 | B2: TOMATO PEELED CAN | C2: 5 | D2: 120000 | E2: =D2*C2 -> 600000 | F2: =SUM(E2) -> 600000
A3: 45995 | B3: CASHEW NUT | C3: 1 | D3: 160000 | E3: =D3*C3 -> 160000 | F3: =SUM(E3:E17) -> 2537000
B4: COCOA POWDER | C4: 2 | D4: 50000 | E4: =D4*C4 -> 100000
B5: CREAM CHEESE | C5: 2 | D5: 170000 | E5: =D5*C5 -> 340000
B6: SOUR CREAM | C6: 2 | D6: 160000 | E6: =D6*C6 -> 320000
B7: FRESH MILK | C7: 4 | D7: 22000 | E7: =D7*C7 -> 88000
B8: MILAC CREAM | C8: 2 | D8: 90000 | E8: =D8*C8 -> 180000
B9: BACON (1KG) | C9: 2 | D9: 170000 | E9: =D9*C9 -> 340000
B10: OLIVE OIL | C10: 1 | D10: 360000 | E10: =D10*C10 -> 360000
B11: SESAME DRESSING | C11: 2 | D11: 120000 | E11: =D11*C11 -> 240000
B12: GREEN BEANS | C12: 0.2 | D12: 20000 | E12: =D12*C12 -> 4000
B13: SPONGE | C13: 10 | D13: 5000 | E13: =D13*C13 -> 50000
B14: TRASH BAG | C14: 3 | D14: 20000 | E14: =D14*C14 -> 60000
B15: KG PLASTIC | C15: 2 | D15: 25000 | E15: =D15*C15 -> 50000
... B17: WHITE AGAR-AGAR | C17: 1 | D17: 95000 | E17: =D17*C17 -> 95000
A18: 45996 | B18: TORTILLA SMALL | C18: 1 | D18: 70000 | E18: =D18*C18 -> 70000 | F18: =SUM(E18) -> 70000
A19: 45996 | B19: DOUBLE ZERO | C19: 1 | D19: 200000 | E19: =D19*C19 -> 200000 | F19: =SUM(E19:E34) -> 2484000
B20: CAKRA FLOUR | C20: 2 | D20: 15000 | E20: =D20*C20 -> 30000
B21: ACID CAP GAJAH | C21: 5 | D21: 5000 | E21: =D21*C21 -> 25000
B22: HAM (1KG) | C22: 2 | D22: 170000 | E22: =D22*C22 -> 340000
B23: BBQ SAUCE | C23: 5 | D23: 40000 | E23: =D23*C23 -> 200000
B24: CHILI SAUCE | C24: 2 | D24: 25000 | E24: =D24*C24 -> 50000
B25: BANGKOK SAUCE | C25: 3 | D25: 20000 | E25: =D25*C25 -> 60000
B26: MILAC WHIPPING CREAM | C26: 4 | D26: 90000 | E26: =D26*C26 -> 360000
B27: FRESH MILK | C27: 2 | D27: 22000 | E27: =D27*C27 -> 44000
B28: PARMESAN BLOCK | C28: 1 | D28: 275000 | E28: =D28*C28 -> 275000
B29: KEWPIE MAYONNAISE | C29: 1 | D29: 100000 | E29: =D29*C29 -> 100000
B30: MAESTRO MAYONNAISE | C30: 2 | D30: 35000 | E30: =D30*C30 -> 70000
B31: BRIE CHEESE | C31: 1 | D31: 95000 | E31: =D31*C31 -> 95000
... B34: TORTILLA | C34: 1 | D34: 95000 | E34: =D34*C34 -> 95000
A35: 45997 | B35: MILAC WHIPPING CREAM | C35: 2 | D35: 90000 | E35: =D35*C35 -> 180000 | F35: =SUM(E35:E50) -> 1967000
B36: KEWPIE MAYONNAISE | C36: 1 | D36: 100000 | E36: =D36*C36 -> 100000
B37: FETA CHEESSE | C37: 2 | D37: 90000 | E37: =D37*C37 -> 180000
B38: TOMATO KETCHUP | C38: 3 | D38: 20000 | E38: =D38*C38 -> 60000
B39: LOLO ROSSO | C39: 0.3 | D39: 100000 | E39: =D39*C39 -> 30000
B40: ROSEMARY | C40: 0.1 | D40: 150000 | E40: =D40*C40 -> 15000
B41: AVOCADO | C41: 1 | D41: 40000 | E41: =D41*C41 -> 40000
B42: MANGO | C42: 1.36 | D42: 38000 | E42: 52000
B43: CREAM CHEESE | C43: 2 | D43: 170000 | E43: =D43*C43 -> 340000
...

Sheet SEDANA JAYA (Groceries)
A1: DATE | B1: ITEM | C1: QYT | D1: PRICE | E1: SUBTOTAL | F1: TOTAL
A2: 45992 | B2: RED PEPPER | C2: 0.5 | D2: 83000 | E2: =D2*C2 -> 41500 | F2: =SUM(E2:E15) -> 1804900
B3: BANANA | C3: 4 | D3: 22000 | E3: =D3*C3 -> 88000
B4: BAKED BEANS | C4: 3 | D4: 45000 | E4: =D4*C4 -> 135000
B5: CHICK PEAS | C5: 4 | D5: 110000 | E5: =D5*C5 -> 440000
B6: OIL | C6: 5 | D6: 150000 | E6: =D6*C6 -> 750000
B7: LOCAL LEMON | C7: 1 | D7: 75000 | E7: =D7*C7 -> 75000
B8: AVOCADO | C8: 1 | D8: 39000 | E8: =D8*C8 -> 39000
B9: MANGO | C9: 1 | D9: 39000 | E9: =D9*C9 -> 39000
B10: EDAMAME | C10: 0.5 | D10: 45000 | E10: =D10*C10 -> 22500
B11: GREEN APPLE | C11: 1 | D11: 50000 | E11: =D11*C11 -> 50000
B12: WHITE PEAR | C12: 1.7 | D12: 40000 | E12: =D12*C12 -> 68000
B13: LIME | C13: 0.3 | D13: 28000 | E13: =D13*C13 -> 8400
B14: EGGPLANT | C14: 1 | D14: 10000 | E14: =D14*C14 -> 10000
B15: GREEN LETTUCE | C15: 0.5 | D15: 77000 | E15: =D15*C15 -> 38500
A16: 45993 | B16: DRAGON FRUIT | C16: 2 | D16: 28000 | E16: =D16*C16 -> 56000 | F16: =SUM(E16:E36) -> 2570700
B17: EGG | C17: 2 | D17: 66000 | E17: =D17*C17 -> 132000
B18: POTATO | C18: 7 | D18: 24000 | E18: =D18*C18 -> 168000
B19: SWEET POTATO | C19: 3 | D19: 25000 | E19: =D19*C19 -> 75000
B20: ONION | C20: 1 | D20: 39000 | E20: =D20*C20 -> 39000
B21: SALT | C21: 3 | D21: 20000 | E21: =D21*C21 -> 60000
B22: TOTOLE | C22: 3 | D22: 75000 | E22: =D22*C22 -> 225000
B23: BASMATI RICE SUKRIYA | C23: 3 | D23: 80000 | E23: =D23*C23 -> 240000
B24: RED RICE | C24: 3 | D24: 75000 | E24: =D24*C24 -> 225000
B25: BLACK PEPPER WHOLE | C25: 0.5 | D25: 200000 | E25: =D25*C25 -> 100000
B26: SUGAR | C26: 3 | D26: 25000 | E26: =D26*C26 -> 75000
B27: OLIVE OIL | C27: 1 | D27: 450000 | E27: =D27*C27 -> 450000
B28: TABASCO | C28: 1 | D28: 85000 | E28: =D28*C28 -> 85000
... B36: YELLOW PEPPER | C36: 0.5 | D36: 94000 | E36: =D36*C36 -> 47000
A37: 45993 | B37: AVOCADO | C37: 1 | D37: 39000 | E37: =D37*C37 -> 39000 | F37: =SUM(E37:E56) -> 1499400
B38: SUNKIST | C38: 1 | D38: 50000 | E38: =D38*C38 -> 50000
B39: LEMON | C39: 1 | D39: 83000 | E39: =D39*C39 -> 83000
B40: MANGO | C40: 1 | D40: 39000 | E40: =D40*C40 -> 39000
B41: BASIL | C41: 0.1 | D41: 88000 | E41: =D41*C41 -> 8800
B42: MINT | C42: 0.1 | D42: 72000 | E42: =D42*C42 -> 7200
B43: CHERRY RED TOMATO | C43: 0.5 | D43: 50000 | E43: =D43*C43 -> 25000
B44: CHERRY YELLOW TOMATO | C44: 0.4 | D44: 61000 | E44: =D44*C44 -> 24400
B45: STRAWBERRY (250) | C45: 0.3 | D45: 120000 | E45: =D45*C45 -> 36000
B46: QUAIL EGG | C46: 30 | D46: 1000 | E46: =D46*C46 -> 30000
B47: ICE BERG | C47: 0.5 | D47: 70000 | E47: =D47*C47 -> 35000
...

Sheet RAFI SEAFOOD (Seafood)
A1: DATE | B1: DESCRIPTION | C1: QUANTITY | D1: PRICE | E1: BILLS | F1: SUBTOTAL | G1: TOTAL
A2: 45992 | B2: TUNA | C2: 7.5 | D2: 115000 | F2: 862000 | G2: =SUM(F2:F6) -> 2976000
B3: PRAWN | C3: 2.8 | D3: 180000 | F3: =SUM(C3*D3) -> 504000
B4: MAHI | C4: 3.7 | D4: 115000 | F4: 425000
B5: SQUID | C5: 2 | D5: 85000 | F5: =SUM(C5*D5) -> 170000
B6: MINCE BEEF | C6: 7 | D6: 145000 | F6: =SUM(C6*D6) -> 1015000
A7: 45996 | B7: SALMON | C7: 5.6 | D7: 375000 | F7: =SUM(C7*D7) -> 2100000 | G7: =SUM(F7) -> 2100000
A8: 45997 | B8: SQUID CUBE | C8: 1 | D8: 85000 | F8: =SUM(C8*D8) -> 85000 | G8: =SUM(F8:F9) -> 640000
B9: PRAWN | C9: 3 | D9: 185000 | F9: =SUM(C9*D9) -> 555000
A10: 46001 | B10: PRAWN | C10: 3 | D10: 185000 | F10: =SUM(C10*D10) -> 555000 | G10: =SUM(F10:F12) -> 2705000
B11: TUNA | C11: 8.4 | D11: 115000 | F11: =SUM(C11*D11) -> 966000
B12: SALMON | C12: 3.2 | D12: 370000 | F12: =SUM(C12*D12) -> 1184000
A13: 46004 | B13: SALMON | C13: 3 | D13: 375000 | F13: =SUM(C13*D13) -> 1125000 | G13: =SUM(F13:F17) -> 2813500
B14: MAHI-MAHI | C14: 2.6 | D14: 115000 | F14: =C14*D14 -> 299000
B15: TUNA | C15: 6.1 | D15: 115000 | F15: =C15*D15 -> 701500
B16: PRAWN 20 | C16: 2.8 | D16: 185000 | F16: =SUM(C16*D16) -> 518000
B17: SQUID TUBE | C17: 2 | D17: 85000 | F17: =SUM(C17*D17) -> 170000
F18: =SUM(C18*D18) -> 0
F19: =SUM(C19*D19) -> 0 | G19: =SUM(F19:F23) -> 0
F20: =SUM(C20*D20) -> 0
F21: =SUM(C21*D21) -> 0
F22: =SUM(C22*D22) -> 0
F23: =SUM(C23*D23) -> 0
F24: =SUM(C24*D24) -> 0 | G24: =SUM(C24*D24+C25*D25) -> 0
F25: =SUM(C25*D25) -> 0
F26: =SUM(C26*D26) -> 0 | G26: =SUM(F26:F29) -> 0
F27: =SUM(C27*D27) -> 0
F28: =SUM(C28*D28) -> 0
F29: =SUM(C29*D29) -> 0
F30: =C30*D30 -> 0 | G30: =SUM(F30:F32) -> 0
F31: =C31*D31 -> 0
F32: =C32*D32 -> 0
F33: =SUM(C33*D33) -> 0 | G33: =SUM(F33:F35) -> 0
F34: =SUM(C34*D34) -> 0
F35: =SUM(C35*D35) -> 0
D61: =SUM(G2:G60) -> 11234500

Sheet MAMA RADA PRODUCTION (Dumpling)
A1: DATE | B1: INV NO. | C1: DESCRIPTIONS | D1: QTY | E1: BIILS | F1: PRICE | G1: SUBTOTAL | H1: TOTAL
G2: =D2*F2 -> 0 | H2: =SUM(G2) -> 0
G3: =SUM(D3*F3+D4*F4) -> 0
G5: =SUM(D5*F5+D6*F6+D7*F7) -> 0
G8: =SUM(D8*F8) -> 0
E12: GRAND TOTAL | H12: =SUM(H2:H11) -> 0

Sheet KSP (Chicken)
A1: DATE | B1: INV NO. | C1: DESCRIPTIONS | D1: QTY | E1: BILLS | F1: PRICE | G1: SUB TOTAL | H1: TOTAL
A2: 45993 | B2: B00518/PRN-R/2025 | C2: BONELESS BREAST TK SP | D2: 5.4 | F2: 52500 | G2: =SUM(D2*F2) -> 283500 | H2: =SUM(G2:G4) -> 1018650
C3: BONELESS LEG TK SP | D3: 10.8 | F3: 50500 | G3: =SUM(D3*F3) -> 545400
C4: WING TD | D4: 5.5 | F4: 34500 | G4: =SUM(D4*F4) -> 189750
A5: 45996 | B5: B00557/PRN-R/2025 | C5: BONELESS BREAST TK SP | D5: 5.6 | F5: 52500 | G5: =SUM(D5*F5) -> 294000 | H5: =SUM(G5:G6) -> 1066650
C6: BONELESS LEG TK SP | D6: 15.3 | F6: 50500 | G6: =SUM(D6*F6) -> 772650
A7: 46003 | B7: B00640/PRN-R/2025 | C7: BONELESS BREAST TK SP | D7: 5.1 | F7: 54000 | G7: =SUM(D7*F7) -> 275400 | H7: =SUM(G7:G8) -> 1112600
C8: BONELESS LEG TK SP | D8: 16.1 | F8: 52000 | G8: =SUM(D8*F8) -> 837200
G9: =D9*F9 -> 0 | H9: =SUM(G9:G10) -> 0
G10: =D10*F10 -> 0
G11: =D11*F11 -> 0 | H11: =SUM(G11:G12) -> 0
G12: =D12*F12 -> 0
H13: =SUM(H2:H12) -> 3197900

Sheet SURYA CIPTA NIAGA BALI (Beef)
A1: DATE | B1: INV NO. | C1: DESCRIPTIONS | D1: QTY | E1: BILLS | F1: PRICE | G1: SUBTOTAL | H1: TOTAL | I1: STATUS
A2: 45995 | B2: 2512/FK-0494 | C2: TOP SIDE CAP OFF AA6-7 | D2: 23.74 | F2: 250000 | G2: =D2*F2 -> 5935000 | H2: =SUM(G2:G3) -> 7717000 | I2: 45972
C3: STRIPLOIN ICHI BROWN | D3: 9.9 | F3: 180000 | G3: =D3*F3 -> 1782000
G4: =D4*F4 -> 0 | H4: =SUM(G4:G5) -> 0
G5: =D5*F5 -> 0
G6: =D6*F6 -> 0 | H6: =SUM(D6*F6) -> 0
G8: =D8*F8 -> 0 | H8: =SUM(D8*F8) -> 0
A9: TOTAL | G9: =SUM(H2:H8) -> 7717000

Sheet BAYU AGNI MERTA (Gas)
A1: DATE | B1: INV NO. | C1: DESCRIPTIONS | D1: QTY | E1: BILLS | F1: PRICE | G1: TOTAL
A2: 45996 | B2: 1240 | C2: LPG 50KG | D2: 4 | F2: 975000 | G2: =SUM(D2*F2) -> 3900000
G3: =D3*F3 -> 0
A4: TOTAL | E4: =SUM(G2:G3) -> 3900000

Sheet Joy Green (Mix Berry)
A1: NO | B1: DATE | C1: TOTAL | D1: PC | E1: STATUS
A3: Total | D3: =SUM(C2:C2) -> 0

Sheet CELEBRITY BAKERY (Bakery)
A1: DATE | B1: INV.NO | C1: DESCRIPTION | D1: QTY | E1: BILLS | F1: PRICE | G1: TOTAL
A5: TOTAL | E5: =SUM(G2) -> 0

Sheet Krop (Edible flower)
A1: DATE | B1: INV.NO | C1: DESCRIPTION | D1: QTY | E1: BILLS | F1: PRICE | G1: SUBTOTAL | H1: TOTAL
A2: 45995 | B2: 115510 | C2: ELDER FLOWER (N) | D2: 1 | E2: =_xlfn.DISPIMG("ID_8F921BF7E7AD4DE39EDA81F284BE5F0A",1) -> =DISPIMG("ID_8F921BF7E7AD4DE39EDA81F284BE5F0A",1) | F2: 35000 | G2: =D2*F2 -> 35000 | H2: =SUM(G2:G5) -> 117000
C3: EDIBLE FLOWER MIX (N) | D3: 1 | F3: 35000 | G3: =D3*F3 -> 35000
C4: GREEN MUSTARD | D4: 1 | F4: 22000 | G4: =D4*F4 -> 22000
C5: RED RADISH | D5: 1 | F5: 25000 | G5: =D5*F5 -> 25000
G6: =D6*F6 -> 0
A7: TOTAL | H7: =SUM(H2:H6) -> 117000

Sheet Boiler (Dumplings&Syrniki)
A1: DATE | B1: INV.NO | C1: DESCRIPTION | D1: QTY | E1: BILLS | F1: PRICE | G1: SUBTOTAL | H1: TOTAL | I1: TOTAL AFTER TAX
G2: =D2*F2 -> 0 | H2: =SUM(G2:G4) -> 0 | I2: =(H2*10%)+H2 -> 0
G3: =D3*F3 -> 0
G4: =D4*F4 -> 0
A5: TOTAL | E5: =SUM(I2) -> 0

Sheet Abdi Jaya (TKW, Vacuum Bag)
A1: DATE | B1: INV.NO | C1: DESCRIPTION | D1: QTY | E1: BILLS | F1: PRICE | G1: SUBTOTAL | H1: TOTAL
A2: 45996 | B2: 821 | C2: VACUUM PLASTIC 16X25 | D2: 5 | F2: 65000 | G2: =D2*F2 -> 325000 | H2: =SUM(G2:G4) -> 770000
C3: VACUUM PLASTIC 20X30 | D3: 5 | F3: 85000 | G3: =D3*F3 -> 425000
C4: PLASTIC FOR CUTLERIES | D4: 1 | F4: 20000 | G4: =D4*F4 -> 20000
A5: 46002 | B5: 0414 | C5: PAPER BOWL 650ML | D5: 3 | F5: 760000 | G5: =D5*F5 -> 2280000 | H5: =SUM(G5:G14) -> 10774000
C6: PAPER BOWL 1000ML | D6: 3 | F6: 900000 | G6: =D6*F6 -> 2700000
C7: BOX BURGER | D7: 2 | F7: 500000 | G7: =D7*F7 -> 1000000
C8: SAUCE CUP 60ML | D8: 2 | F8: 432000 | G8: =D8*F8 -> 864000
C9: HAND GLOVE BLACK L | D9: 5 | F9: 55000 | G9: =D9*F9 -> 275000
C10: PLASTIC WRAP 45 | D10: 4 | F10: 165000 | G10: =D10*F10 -> 660000
C11: BAKING PAPER | D11: 3 | F11: 220000 | G11: =D11*F11 -> 660000
C12: PLASTIC VACUUM 20X30 | D12: 4 | F12: 85000 | G12: =D12*F12 -> 340000
C13: PLASTIC VACUUM 16X25 | D13: 3 | F13: 65000 | G13: =D13*F13 -> 195000
C14: ALUMINIUM FOIL | D14: 6 | F14: 300000 | G14: =D14*F14 -> 1800000
A15: GRAND TOTAL | D15: =SUM(H2:H14) -> 11544000

Sheet Dishy Soap (Chemicals)
A1: DATE | B1: DESCRIPTION | C1: QTY | D1: BILLS | E1: PRICE | F1: SUBTOTAL | G1: TOTAL
A2: 45992 | B2: DISHY 5L DISH WASHING | C2: 5 | E2: 55000 | F2: =C2*E2 -> 275000 | G2: =SUM(F2:F2) -> 275000
A3: 46003 | B3: DISHWASH DISHY 5L | C3: 5 | E3: 55000 | F3: =C3*E3 -> 275000 | G3: =SUM(F3:F8) -> 895000
B4: FLOOR MOP LAVENDER 5L | C4: 1 | E4: 55000 | F4: =C4*E4 -> 55000
B5: KARBOL 5L | C5: 1 | E5: 55000 | F5: =C5*E5 -> 55000
B6: DETERGENT 5L | C6: 3 | E6: 50000 | F6: =C6*E6 -> 150000
B7: FURNITURE SANITIZER 5L | C7: 1 | E7: 160000 | F7: =C7*E7 -> 160000
B8: HAND SANITIZER GEL | C8: 1 | E8: 200000 | F8: =C8*E8 -> 200000
A9: GRAND TOTAL | G9: =SUM(G2:G8) -> 1170000

Sheet Abiseka (Fresh Milk)
A1: DATE | B1: DESCRIPTION | C1: QTY | D1: BILLS | E1: PRICE | F1: SUBTOTAL | G1: TOTAL
A3: GRAND TOTAL | G3: =SUM(G2) -> 0

Sheet TOTAL
A1: SUPPLIER | B1: Total
A2: BU BUNGA | B2: ='BUK BUNGA (Groceries)'!F466 -> 19497000
A3: SEDANA JAYA | B3: ='SEDANA JAYA (Groceries)'!F660 -> 17239600
A4: RAFI SEAFOOD | B4: ='RAFI SEAFOOD (Seafood)'!D61 -> 11234500
A5: MAMA RADA PRODUCTION | B5: ='MAMA RADA PRODUCTION (Dumpling)'!H12 -> 0
A6: KSP | B6: ='KSP (Chicken)'!H13 -> 3197900
A7: SURYA CIPTA NIAGA BALI | B7: ='SURYA CIPTA NIAGA BALI (Beef)'!G9 -> 7717000
A8: BAYU AGNI MERTA | B8: ='BAYU AGNI MERTA (Gas)'!E4 -> 3900000
A9: JOY GREEN | B9: ='Joy Green (Mix Berry)'!D3 -> 0
A10: CELEBRITY BAKERY | B10: ='CELEBRITY BAKERY (Bakery)'!E5 -> 0
A11: KROP NATIION | B11: ='Krop (Edible flower)'!H7 -> 117000
A12: BOILER | B12: ='Boiler (Dumplings&Syrniki)'!E5 -> 0
A13: ABDI JAYA | B13: ='Abdi Jaya (TKW, Vacuum Bag)'!D15 -> 11544000
A14: DISHY SOAP | B14: ='Dishy Soap (Chemicals)'!G9 -> 1170000
A15: ABISEKA | B15: ='Abiseka (Fresh Milk)'!G3 -> 0
A16: TOTAL | B16: =SUM(B2:B12) -> 62903000
