Workbook

Sheet TEGAL JAYA (Bar Groceries)
A1: DATE | B1: ITEM | C1: INV NO. | D1: QYT | E1: PRICE | F1: SUBTOTAL | G1: TOTAL | H1: =SUM(G:G) -> 2787300
A2: 46114 | B2: IMPORTED LEMON | C2: 9229 | D2: 1 | E2: 45000 | F2: =E2*D2 -> 45000 | G2: =SUM(F2:F5) -> 253000
B3: KINTAMANI ORANGE | D3: 6 | E3: 25000 | F3: =E3*D3 -> 150000
B4: WHITE SUGAR | D4: 2 | E4: 25000 | F4: =E4*D4 -> 50000
B5: LIME | D5: 0.5 | E5: 16000 | F5: =E5*D5 -> 8000
A6: 46116 | B6: FRESH MILK (GREENFIELDS) | C6: 9051 | D6: 2 | E6: 35000 | F6: =E6*D6 -> 70000 | G6: =SUM(F6:F10) -> 296800
B7: LIME | D7: 0.3 | E7: 16000 | F7: =E7*D7 -> 4800
B8: WATERMELON | D8: 3.8 | E8: 15000 | F8: =E8*D8 -> 57000
B9: IMPORTED LEMON | D9: 2 | E9: 45000 | F9: =E9*D9 -> 90000
B10: KINTAMANI ORANGE | D10: 3 | E10: 25000 | F10: =E10*D10 -> 75000
A11: 46125 | B11: HONEY PINEAPPLE | C11: 11476 | D11: 5 | E11: 12000 | F11: =E11*D11 -> 60000 | G11: =SUM(F11:F18) -> 920000
B12: IMPORTED LEMON | D12: 1 | E12: 45000 | F12: =E12*D12 -> 45000
B13: KINTAMANI ORANGE | D13: 5 | E13: 30000 | F13: =E13*D13 -> 150000
B14: OAT MILK | D14: 4 | E14: 80000 | F14: =E14*D14 -> 320000
B15: FRESH MILK (GREENFIELDS) | D15: 4 | E15: 35000 | F15: =E15*D15 -> 140000
B16: STRAWBERRY | D16: 1 | E16: 80000 | F16: =E16*D16 -> 80000
B17: GREEN APPLE | D17: 1.1 | E17: 50000 | F17: =E17*D17 -> 55000
B18: MANGO | D18: 1 | E18: 70000 | F18: =E18*D18 -> 70000
A19: 46127 | B19: BEET ROOT | C19: N/A | D19: 1 | E19: 35000 | F19: =E19*D19 -> 35000 | G19: =SUM(F19:F26) -> 404800
B20: BABY CUCUMBER/ KYURI | D20: 1.1 | E20: 18000 | F20: =E20*D20 -> 19800
B21: MANGO | D21: 1 | E21: 70000 | F21: =E21*D21 -> 70000
B22: STRAWBERRY | D22: 0.5 | E22: 80000 | F22: =E22*D22 -> 40000
B23: LUMAJANG ORANGE | D23: 4 | E23: 25000 | F23: =E23*D23 -> 100000
B24: IMPORTED LEMON | D24: 1 | E24: 45000 | F24: =E24*D24 -> 45000
B25: SUNKIST | D25: 1 | E25: 45000 | F25: =E25*D25 -> 45000
B26: THE SARIWANGI | D26: 2 | E26: 25000 | F26: =E26*D26 -> 50000
A27: 46128 | B27: KINTAMANI ORANGE | C27: 9095 | D27: 5 | E27: 30000 | F27: =E27*D27 -> 150000 | G27: =SUM(F27:F31) -> 344500
B28: IMPORTED LEMON | D28: 1 | E28: 45000 | F28: =E28*D28 -> 45000
B29: HONEY PINEAPPLE | D29: 5 | E29: 12000 | F29: =E29*D29 -> 60000
B30: GREEN APPLE | D30: 1.1 | E30: 45000 | F30: =E30*D30 -> 49500
B31: STRAWBERRY | D31: 0.5 | E31: 80000 | F31: =E31*D31 -> 40000
A32: 46132 | B32: STRAWBERRY | C32: 10862 | D32: 0.5 | E32: 90000 | F32: =E32*D32 -> 45000 | G32: =SUM(F32:F42) -> 568200
B33: CUCUMBER | D33: 0.5 | E33: 16000 | F33: =E33*D33 -> 8000
B34: CARROT | D34: 0.6 | E34: 20000 | F34: =E34*D34 -> 12000
B35: MANGO | D35: 3 | E35: 70000 | F35: =E35*D35 -> 210000
B36: ENGLISH SPINACH | D36: 0.6 | E36: 15000 | F36: =E36*D36 -> 9000
B37: MUSTARD GREEN | D37: 0.5 | E37: 25000 | F37: =E37*D37 -> 12500
B38: WATERMELON | D38: 3.2 | E38: 15000 | F38: =E38*D38 -> 48000
B39: AVOCADO | D39: 1.3 | E39: 35000 | F39: =E39*D39 -> 45500
B40: LIME | D40: 0.2 | E40: 16000 | F40: =E40*D40 -> 3200
...

Sheet BUK BUNGA BAR (Groceries)
A1: DATE | B1: ITEM | C1: QYT | D1: PRICE | E1: SUB TOTAL | F1: TOTAL | G1: =SUM(F:F) -> 8433000
A2: 46113 | B2: FRESH MILK (GREENFIELDS) | C2: 6 | D2: 24000 | E2: =D2*C2 -> 144000 | F2: =SUM(E2:E8) -> 810000
B3: OAT MILK | C3: 2 | D3: 40000 | E3: =D3*C3 -> 80000
B4: WATERMELON | C4: 6.41 | D4: 20000 | E4: 128000
B5: IMPORTED LEMON | C5: 2 | D5: 70000 | E5: =D5*C5 -> 140000
B6: AVOCADO | C6: 1.335 | D6: 40000 | E6: 53000
B7: KINTAMANI ORANGE | C7: 5 | D7: 35000 | E7: =D7*C7 -> 175000
B8: YOGHURT | C8: 1 | D8: 90000 | E8: =D8*C8 -> 90000
A9: 46114 | B9: FRESH MILK (GREENFIELDS) | C9: 4 | D9: 24000 | E9: =D9*C9 -> 96000 | F9: =SUM(E9:E11) -> 248000
B10: OAT MILK | C10: 2 | D10: 40000 | E10: =D10*C10 -> 80000
B11: BANANA | C11: 36 | D11: 2000 | E11: =D11*C11 -> 72000
A12: 46115 | B12: HONEY | C12: 1 | D12: 35000 | E12: =D12*C12 -> 35000 | F12: =SUM(E12:E18) -> 490000
B13: FRESH MILK (GREENFIELDS) | C13: 4 | D13: 24000 | E13: =D13*C13 -> 96000
B14: OAT MILK | C14: 2 | D14: 40000 | E14: =D14*C14 -> 80000
B15: KINTAMANI ORANGE | C15: 3 | D15: 35000 | E15: =D15*C15 -> 105000
B16: IMPORTED LEMON | C16: 2 | D16: 70000 | E16: =D16*C16 -> 140000
B17: LIME | C17: 0.3 | D17: 30000 | E17: =D17*C17 -> 9000
B18: SARIWANGI | C18: 1 | D18: 25000 | E18: =D18*C18 -> 25000
A19: 46117 | B19: FRESH MILK (GREENFIELDS) | C19: 4 | D19: 24000 | E19: =D19*C19 -> 96000 | F19: =SUM(E19:E23) -> 333000
B20: OAT MILK | C20: 2 | D20: 40000 | E20: =D20*C20 -> 80000
B21: LIME | C21: 0.5 | D21: 30000 | E21: =D21*C21 -> 15000
B22: KINTAMANI ORANGE | C22: 2 | D22: 35000 | E22: =D22*C22 -> 70000
B23: MANGO | C23: 1.2 | D23: 60000 | E23: =D23*C23 -> 72000
A24: 46118 | B24: GREEN MUSTARD | C24: 0.4 | D24: 20000 | E24: =D24*C24 -> 8000 | F24: =SUM(E24:E34) -> 630000
B25: KINTAMANI ORANGE | C25: 2 | D25: 35000 | E25: =D25*C25 -> 70000
B26: MANGO | C26: 2 | D26: 60000 | E26: =D26*C26 -> 120000
B27: IMPORTED LEMON | C27: 2 | D27: 70000 | E27: =D27*C27 -> 140000
B28: CUCUMBER | C28: 2 | D28: 15000 | E28: =D28*C28 -> 30000
B29: LIME | C29: 0.4 | D29: 30000 | E29: =D29*C29 -> 12000
B30: ENGLISH SPINACH | C30: 0.2 | D30: 40000 | E30: =D30*C30 -> 8000
B31: BASIL | C31: 0.2 | D31: 80000 | E31: =D31*C31 -> 16000
B32: STRAWBERRY | C32: 0.5 | D32: 100000 | E32: =D32*C32 -> 50000
B33: FRESH MILK (GREENFIELDS) | C33: 4 | D33: 24000 | E33: =D33*C33 -> 96000
B34: OAT MILK | C34: 2 | D34: 40000 | E34: =D34*C34 -> 80000
A35: 46119 | B35: FRESH MILK (GREENFIELDS) | C35: 5 | D35: 24000 | E35: =D35*C35 -> 120000 | F35: =SUM(E35:E36) -> 235000
B36: WATERMELON | C36: 5.205 | D36: 22000 | E36: 115000
A37: 46120 | B37: FRESH MILK (GREENFIELDS) | C37: 4 | D37: 24000 | E37: =D37*C37 -> 96000 | F37: =SUM(E37:E38) -> 166000
B38: CHERRY RED TOMATOES | C38: 1 | D38: 70000 | E38: =D38*C38 -> 70000
A39: 46121 | B39: HONEY PINEAPPLE | C39: 5 | D39: 10000 | E39: =D39*C39 -> 50000 | F39: =SUM(E39:E46) -> 772000
B40: KINTAMANI ORANGE | C40: 3 | D40: 35000 | E40: =D40*C40 -> 105000
...

Sheet WARUNG EKA (Drinks, Etc)
A1: DATE | B1: ITEM | C1: INV NO | D1: QYT | E1: PRICE | F1: SUBTOTAL | G1: TOTALPRICE | H1: =SUM(G:G) -> 7132000
A2: 46113 | B2: AQUA REFLECTIONS STILL 750 ML | C2: 82580 | D2: 1 | E2: 115000 | F2: =E2*D2 -> 115000 | G2: =SUM(F2:F7) -> 540000
B3: AQUA REFLECTIONS SPARKLING 750 ML | D3: 1 | E3: 120000 | F3: =E3*D3 -> 120000
B4: POLARIS SODA WATER CAN 330 ML | D4: 1 | E4: 125000 | F4: =E4*D4 -> 125000
B5: SCHWEPPES GINGER ALE CAN 250 ML | D5: 1 | E5: 125000 | F5: =E5*D5 -> 125000
B6: CRYSTAL ICE 5 KG | D6: 4 | E6: 8000 | F6: =E6*D6 -> 32000
B7: CLEO GALLOON 19 LTR | D7: 1 | E7: 23000 | F7: =E7*D7 -> 23000
A8: 46114 | B8: CRYSTAL ICE 5 KG | C8: 8287 | D8: 6 | E8: 8000 | F8: =E8*D8 -> 48000 | G8: =SUM(F8:F9) -> 69000
B9: AQUA GALLOON 19 LTR | D9: 1 | E9: 21000 | F9: =E9*D9 -> 21000
A10: 46114 | B10: BINTANG PINT 330 ML | C10: 8303 | D10: 1 | E10: 480000 | F10: =E10*D10 -> 480000 | G10: =SUM(F10:F11) -> 492000
B11: EMPTY BOTTLE CHARGE | D11: 6 | E11: 2000 | F11: =E11*D11 -> 12000
A12: 46115 | B12: CLEO GALLOON 19 LTR | C12: 82704 | D12: 1 | E12: 23000 | F12: =E12*D12 -> 23000 | G12: =SUM(F12:F18) -> 629000
B13: AQUA GALLOON 19 LTR | D13: 1 | E13: 21000 | F13: =E13*D13 -> 21000
B14: CRYSTAL ICE 5 KG | D14: 8 | E14: 10000 | F14: =E14*D14 -> 80000
B15: POLARIS SODA WATER CAN 330 ML | D15: 1 | E15: 125000 | F15: =E15*D15 -> 125000
B16: AQUA REFLECTIONS STILL 380 ML | D16: 1 | E16: 125000 | F16: =E16*D16 -> 125000
B17: AQUA REFLECTIONS SPARKLING 380 ML | D17: 1 | E17: 135000 | F17: =E17*D17 -> 135000
B18: AQUA REFLECTIONS SPARKLING 750 ML | D18: 1 | E18: 120000 | F18: =E18*D18 -> 120000
A19: 46116 | B19: CRYSTAL ICE 5 KG | C19: 82791 | D19: 3 | E19: 10000 | F19: =E19*D19 -> 30000 | G19: =SUM(F19:F21) -> 166000
B20: AQUA REFLECTIONS STILL 750 ML | D20: 1 | E20: 115000 | F20: =E20*D20 -> 115000
B21: AQUA GALLOON 19 LTR | D21: 1 | E21: 21000 | F21: =E21*D21 -> 21000
A22: 46117 | B22: AQUA GALLOON 19 LTR | C22: 82895 | D22: 1 | E22: 21000 | F22: =E22*D22 -> 21000 | G22: =SUM(F22:F27) -> 815000
B23: CLEO GALLOON 19 LTR | D23: 1 | E23: 23000 | F23: =E23*D23 -> 23000
B24: CRYSTAL ICE 5 KG | D24: 2 | E24: 8000 | F24: =E24*D24 -> 16000
B25: AQUA REFLECTIONS STILL 750 ML | D25: 1 | E25: 115000 | F25: =E25*D25 -> 115000
B26: AQUA REFLECTIONS SPARKLING 750 ML | D26: 1 | E26: 120000 | F26: =E26*D26 -> 120000
B27: RED BULL BLUE IMPORT CAN 250 ML | D27: 1 | E27: 520000 | F27: =E27*D27 -> 520000
A28: 46118 | B28: CRYSTAL ICE 5 KG | C28: 82979 | D28: 4 | E28: 8000 | F28: =E28*D28 -> 32000 | G28: =SUM(F28:F30) -> 199000
B29: AQUA GALLOON 19 LTR | D29: 2 | E29: 21000 | F29: =E29*D29 -> 42000
B30: POLARIS SODA WATER CAN 330 ML | D30: 1 | E30: 125000 | F30: =E30*D30 -> 125000
A31: 46119 | B31: CLEO GALLOON 19 LTR | C31: 83064 | D31: 1 | E31: 23000 | F31: =E31*D31 -> 23000 | G31: =SUM(F31:F32) -> 55000
B32: CRYSTAL ICE 5 KG | D32: 4 | E32: 8000 | F32: =E32*D32 -> 32000
A33: 46120 | B33: AQUA GALLOON 19 LTR | C33: 83152 | D33: 1 | E33: 21000 | F33: =E33*D33 -> 21000 | G33: =SUM(F33:F37) -> 668000
B34: CRYSTAL ICE 5 KG | D34: 5 | E34: 8000 | F34: =E34*D34 -> 40000
B35: AQUA REFLECTIONS STILL 750 ML | D35: 1 | E35: 115000 | F35: =E35*D35 -> 115000
B36: BINTANG PINT 330 ML | D36: 1 | E36: 480000 | F36: =E36*D36 -> 480000
B37: EMPTY BOTTLE CHARGE | D37: 8 | E37: 1500 | F37: =E37*D37 -> 12000
A38: 46121 | B38: CRYSTAL ICE 5 KG | C38: 83250 | D38: 5 | E38: 8000 | F38: =E38*D38 -> 40000 | G38: =SUM(F38:F42) -> 409000
B39: AQUA GALLOON 19 LTR | D39: 3 | E39: 21000 | F39: =E39*D39 -> 63000
B40: CLEO GALLOON 19 LTR | D40: 2 | E40: 23000 | F40: =E40*D40 -> 46000
...

Sheet DEWATA COCONUT (Coconut)
A1: DATE | B1: INV NO. | C1: DESCRIPTIONS | D1: QTY | E1: PRICE | F1: TOTAL | G1: BILLS | H1: =E15 -> 1070000
A2: 46114 | B2: 14098 | C2: COCONUT LOGO | D2: 10 | E2: 12000 | F2: =E2*D2 -> 120000
A3: 46116 | B3: 14226 | C3: COCONUT LOGO | D3: 10 | E3: 12000 | F3: =E3*D3 -> 120000
A4: 46118 | B4: 14303 | C4: COCONUT LOGO | D4: 10 | E4: 12000 | F4: =E4*D4 -> 120000
A5: 46119 | B5: 14326 | C5: COCONUT LOGO | D5: 10 | E5: 12000 | F5: =E5*D5 -> 120000
A6: 46120 | B6: 13813 | C6: COCONUT LOGO | D6: 10 | E6: 11000 | F6: =E6*D6 -> 110000
A7: 46121 | B7: 14378 | C7: COCONUT LOGO | D7: 10 | E7: 12000 | F7: =E7*D7 -> 120000
A8: 46122 | B8: 14465 | C8: COCONUT LOGO | D8: 10 | E8: 12000 | F8: =E8*D8 -> 120000
A9: 46127 | B9: 14653 | C9: COCONUT LOGO | D9: 10 | E9: 12000 | F9: =E9*D9 -> 120000
A10: 46128 | B10: 14688 | C10: COCONUT LOGO | D10: 10 | E10: 12000 | F10: =E10*D10 -> 120000
E15: =SUM(F2:F14) -> 1070000

Sheet SEDANA JAYA
A1: DATE | B1: ITEM | C1: QYT | D1: PRICE | E1: TOTAL PRICE | F1: TOTAL | G1: =E47 -> 0
E47: =SUM(F2:F46) -> 0

Sheet PNB (Alcohol)
A1: DATE | B1: INV NO. | C1: DESCRIPTIONS | D1: QTY | E1: UNIT PRICE | F1: SUB TOTAL | G1: TOTAL | H1: BILLS | I1: =G7 -> 0
F2: =E2*D2 -> 0 | G2: =SUM(F2) -> 0
G7: =SUM(G2:G6) -> 0

Sheet DSP (Alcohol)
A1: DATE | B1: INV NO. | C1: DESCRIPTIONS | D1: QTY | E1: PRICE | F1: DISCOUNT | G1: UNIT PRICE | H1: SUBTOTAL | I1: TOTAL | J1: BILL | K1: =F16 -> 2128500
A2: 46118 | B2: SO/DSP/26/04/0423 | C2: MCGUIGAN-BLACK LABEL SAUVIGNON BLANC | D2: 3 | E2: 295000 | F2: =E2*10% -> 29500 | G2: =E2-F2 -> 265500 | H2: =SUM(D2*G2) -> 796500 | I2: =SUM(H2) -> 796500
A3: 46130 | B3: SO/DSP/26/04/1407 | C3: DA VINCI LEONARDO PROSECCO DOC | D3: 4 | E3: 370000 | F3: =E3*10% -> 37000 | G3: =E3-F3 -> 333000 | H3: =SUM(D3*G3) -> 1332000 | I3: =SUM(H3) -> 1332000
F4: =E4*10% -> 0 | G4: =E4-F4 -> 0 | H4: =SUM(D4*G4) -> 0
F5: =E5*10% -> 0 | G5: =E5-F5 -> 0 | H5: =SUM(D5*G5) -> 0
F6: =E6*10% -> 0 | G6: =E6-F6 -> 0 | H6: =SUM(D6*G6) -> 0
F7: =E7*10% -> 0 | G7: =E7-F7 -> 0 | H7: =SUM(D7*G7) -> 0
F8: =E8*10% -> 0 | G8: =E8-F8 -> 0 | H8: =SUM(D8*G8) -> 0
F9: =E9*10% -> 0 | G9: =E9-F9 -> 0 | H9: =SUM(D9*G9) -> 0
F10: =E10*10% -> 0 | G10: =E10-F10 -> 0 | H10: =SUM(D10*G10) -> 0
F11: =E11*10% -> 0 | G11: =E11-F11 -> 0 | H11: =SUM(D11*G11) -> 0
F12: =E12*10% -> 0 | G12: =E12-F12 -> 0 | H12: =SUM(D12*G12) -> 0
F13: =E13*10% -> 0 | G13: =E13-F13 -> 0 | H13: =SUM(D13*G13) -> 0
F14: =E14*10% -> 0 | G14: =E14-F14 -> 0 | H14: =SUM(D14*G14) -> 0
F15: =E15*10% -> 0 | G15: =E15-F15 -> 0 | H15: =SUM(D15*G15) -> 0
A16: TOTAL | F16: =SUM(I2:I15) -> 2128500

Sheet DSP ARYA BIMA (Alcohol)
A1: DATE | B1: INV NO. | C1: DESCRIPTIONS | D1: QTY | E1: BILLS | F1: PRICE | G1: TOTAL | H1: =E3 -> 0
G2: =F2*D2 -> 0
A3: TOTAL | E3: =SUM(G2) -> 0

Sheet SELERA OR STIR UP (Syrup)
A1: DATE | B1: INV NO. | C1: DESCRIPTIONS | D1: QTY | E1: PRICE | F1: SUBTOTAL | G1: TOTAL | H1: BILLS | I1: =E14 -> 1110000
A2: 46118 | B2: SO.03-260134 | C2: MARVELOUS MANGO PET 800 ML | D2: 5 | E2: 100000 | F2: =D2*E2 -> 500000 | G2: =SUM(F2:F4) -> 1000000
C3: KOOL KIWI PET 800 ML | D3: 3 | E3: 100000 | F3: =D3*E3 -> 300000
C4: VOILA VANILLA PET 800 ML | D4: 2 | E4: 100000 | F4: =D4*E4 -> 200000
A5: SUB TOTAL | D5: =SUM(D2:D2) -> 5 | E5: PPN (11%) | G5: =G2*11% -> 110000
A6: TOTAL | E6: =SUM(G2:G5) -> 1110000
F7: =D7*E7 -> 0 | G7: =SUM(F7:F11) -> 0
F8: =D8*E8 -> 0
F9: =D9*E9 -> 0
F10: =D10*E10 -> 0
F11: =D11*E11 -> 0
A12: SUB TOTAL | D12: =SUM(D7:D11) -> 0 | E12: PPN (11%) | G12: =G7*11% -> 0
A13: TOTAL | E13: =SUM(G7:G12) -> 0
D14: GRAND TOTAL | E14: =SUM(E6,E13) -> 1110000

Sheet DW BALI (Alcohol)
A1: DATE | B1: INV NO. | C1: DESCRIPTIONS | D1: AMOUNT | E1: PRICE | F1: SUBTOTAL | G1: TOTAL | H1: DUE DATE | I1: BILLS | J1: =E8 -> 1620000
A2: 46118 | B2: DW/75/069 | C2: HAVANA CLUB 3 YO 700 ML | D2: 2 | E2: 360000 | F2: =E2*D2 -> 720000 | G2: =SUM(F2:F3) -> 1620000 | H2: 46132
C3: JIM BEAM BLACK 700 ML | D3: 2 | E3: 450000 | F3: =E3*D3 -> 900000
F4: =E4*D4 -> 0
F5: =E5*D5 -> 0
F6: =E6*D6 -> 0
A8: GRAND TOTAL | E8: =SUM(G2:G7) -> 1620000

Sheet DDB (Alcohol)
A1: DATE | B1: INV NO. | C1: DESCRIPTIONS | D1: AMOUNT | E1: PRICE | F1: TOTAL | G1: BILLS | H1: =E20 -> 1312502.9
A2: 46118 | B2: 46464 | C2: GORDON GIN PREMIUM DRY 750 ML | D2: 3 | E2: 236487 | F2: =SUM(D2*E2) -> 709461
A3: SUB TOTAL | E3: PPN | F3: =F2*11% -> 78040.71
A4: TOTAL | E4: =SUM(F2:F3) -> 787501.71
A5: 46129 | B5: 47379 | C5: CAPE DISCOVERY BRUT CUVEE 750 ML | D5: 3 | E5: 157658 | F5: =D5*E5 -> 472974
A6: SUB TOTAL | E6: PPN | F6: =F5*11% -> 52027.14
A7: TOTAL | E7: =SUM(F5:F6) -> 525001.14
F8: =E8*D8 -> 0
F9: =F8*11% -> 0
A10: TOTAL | E10: =SUM(F8:F9) -> 0
F11: =E11*D11 -> 0
F12: =F11*11% -> 0
A13: TOTAL | E13: =SUM(F11:F12) -> 0
F14: =E14*D14 -> 0
F15: =F14*11% -> 0
A16: TOTAL | E16: =SUM(F14:F15) -> 0
A19: TOTAL | E19: =SUM(F17:F18) -> 0
A20: GRAND TOTAL | E20: =SUM(E4+E7+E10+E13+E16+E19) -> 1312502.9

Sheet NANO DEWATA NON CK(Alcohol)
A1: DATE | B1: INV NO. | C1: DESCRIPTIONS | D1: AMOUNT | E1: PRICE | F1: TOTAL | G1: BILLS | H1: =E14 -> 0
F2: =SUM(D2*E2) -> 0
A3: SUB TOTAL
A4: TOTAL | E4: =SUM(F2:F3) -> 0
F5: =SUM(D5*E5) -> 0
A6: SUB TOTAL
A7: TOTAL | E7: =SUM(F5:F6) -> 0
A9: SUB TOTAL
A10: TOTAL | E10: =SUM(F8:F9) -> 0
A12: SUB TOTAL
A13: TOTAL | E13: =SUM(F11:F12) -> 0
A14: GRAND TOTAL | E14: =SUM(E4+E7+G10+G13) -> 0

Sheet NANO DEWATA CK (Alcohol)
A1: DATE | B1: INV NO. | C1: DESCRIPTIONS | D1: AMOUNT | E1: PRICE | F1: DISCOUNT | G1: TOTAL | H1: BILLS | I1: =E14 -> 599999.41
A2: 46129 | B2: INV/NANDAQ/26/04/0431 | C2: SAN TELMO MALBEC | D2: 3 | E2: 202702.5 | F2: =E2*11.11111% -> 22522.498 | G2: =(E2-F2)*D2 -> 540540.01
A3: PPN | G3: =G2*11% -> 59459.401
A4: TOTAL | E4: =SUM(G2:G3) -> 599999.41
F5: =E5*11.11111% -> 0 | G5: =(E5-F5)*D5 -> 0
A6: PPN | G6: =G5*11% -> 0
A7: TOTAL | E7: =SUM(G5:G6) -> 0
F8: =E8*11.11111% -> 0 | G8: =(E8-F8)*D8 -> 0
A9: PPN | G9: =G8*11% -> 0
A10: TOTAL | E10: =SUM(G8:G9) -> 0
A14: GRAND TOTAL | E14: =SUM(E4+E7+E10+H13) -> 599999.41

Sheet BALI PERMATA JAYA (Corona Beer)
A1: DATE | B1: INV NO. | C1: DESCRIPTIONS | D1: QTY | E1: PRICE | F1: TOTAL | G1: STATUS | H1: BILLS | I1: =E17 -> 1190000
A2: 46114 | B2: INV/PERMAQ/26/04/0069 | C2: CORONA BEER | D2: 24 | E2: 44669.67 | F2: =SUM(D2*E2) -> 1072072.1
A3: SUB TOTAL | D3: =SUM(D2) -> 24 | E3: PPN | F3: =F2*11% -> 117927.93
A4: TOTAL | E4: =SUM(F2:F3) -> 1190000
F5: =SUM(D5*E5) -> 0
A6: SUB TOTAL | D6: =SUM(D5) -> 0 | E6: PPN | F6: =F5*11% -> 0
A7: TOTAL | E7: =SUM(F5:F6) -> 0
F8: =SUM(D8*E8) -> 0
A9: SUB TOTAL | D9: =SUM(D8) -> 0 | E9: PPN | F9: =F8*11% -> 0
A10: TOTAL | E10: =SUM(F8:F9) -> 0
F11: =SUM(D11*E11) -> 0
A12: SUB TOTAL | D12: 0 | E12: PPN | F12: =F11*11% -> 0
A13: TOTAL | E13: =SUM(F11:F12) -> 0
A15: SUB TOTAL | D15: 0 | E15: PPN | F15: =F14*11% -> 0
A16: TOTAL | E16: =SUM(F14:F15) -> 0
A17: GRAND TOTAL | E17: =E4+E7+E10+E13+E16 -> 1190000

Sheet BLACK COFFEE ROASTERS (Coffee)
A1: DATE | B1: INV NO. | C1: DESCRIPTIONS | D1: QTY | E1: PRICE | F1: BILLS | G1: TOTAL | H1: DUE DATE | I1: STATUS | J1: =F4 -> 0
G2: =SUM(D2*E2) -> 0
G3: =SUM(D3*E3) -> 0
A4: Total | F4: =SUM(G:G)-SUMIF(I:I,"PAID",G:G) -> 0

Sheet PT. PRASIDA LANTUR MAJU (Wine)
A1: DATE | B1: INV NO. | C1: DESCRIPTIONS | D1: QTY | E1: PRICE | F1: TOTAL | G1: DUE DATE | H1: BILLS | I1: =E11 -> 0
F2: =SUM(D2*E2) -> 0
A3: SUBTOTAL | D3: =SUM(D2) -> 0 | E3: PPN | F3: =F2*11% -> 0
A4: TOTAL | E4: =SUM(F2:F3) -> 0
F5: =E5*D5 -> 0
A6: SUBTOTAL | D6: =SUM(D5) -> 0 | E6: PPN | F6: =F5*11% -> 0
A7: TOTAL | E7: =SUM(F5:F6) -> 0
F8: =E8*D8 -> 0
A9: SUBTOTAL | D9: =SUM(D8) -> 0 | E9: PPN | F9: =F8*11% -> 0
A10: TOTAL | E10: =SUM(F8:F9) -> 0
A11: GRAND TOTAL | E11: =SUM(E4,E7,E10) -> 0

Sheet PT LOVINA BEACH BREWERY
A1: DATE | B1: INV NO. | C1: DESCRIPTIONS | D1: TOTAL | E1: STATUS | F1: BILLS | G1: =C3 -> 0
A3: TOTAL | C3: =SUM(D2:D2) -> 0

Sheet CHAI CHITAI (Tea Leaf,etc)
A1: DATE | B1: INV NO. | C1: DESCRIPTIONS | D1: QTY | E1: PRICE | F1: SUBTOTAL | G1: TOTAL | H1: DISCOUNT | I1: TAX | J1: TOTAL | K1: BILLS | L1: =E9 -> 2240000
A2: 46125 | B2: #1 | C2: CHAMOMILE | D2: 4 | E2: 110000 | F2: =E2*D2 -> 440000 | G2: =SUM(F2:F3) -> 3200000 | H2: =G2*30% -> 960000 | I2: =(G2-H2)*0% -> 0 | J2: =G2-H2 -> 2240000
C3: RED GABA | D3: 4 | E3: 690000 | F3: =E3*D3 -> 2760000
F6: =E6*D6 -> 0 | G6: =SUM(F6) -> 0 | H6: =G6*30% -> 0 | I6: =(G6-H6)*0% -> 0 | J6: =G6-H6 -> 0
A9: GRAND TOTAL | E9: =SUM(J2:J8) -> 2240000

Sheet MULIA JAYA (Passion Fruit)
A1: DATE | B1: DESCRIPTIONS | C1: QTY | D1: PRICE | E1: TOTAL | F1: STATUS | G1: BILLS | H1: =D3 -> 0
E2: =C2*D2 -> 0
A3: TOTAL | D3: =SUM(E2) -> 0

Sheet Dewata Kencana Distribusi (Vdka
A1: DATE | B1: DESCRIPTIONS | C1: QTY | D1: UNIT PRICE | E1: TOTAL | F1: STATUS | G1: DUE DATE | H1: BILLS | I1: =D3 -> 0
E2: =D2*C2 -> 0
A3: TOTAL | D3: =SUM(E:E)-SUMIF(F:F,"PAID",E:E) -> 0

Sheet TOTAL
A1: NO | B1: SUPPLIER | C1: TOTAL
A2: 1 | B2: TEGAL JAYA | C2: ='TEGAL JAYA (Bar Groceries)'!H1 -> 2787300
A3: 2 | B3: BUK BUNGA | C3: ='BUK BUNGA BAR (Groceries)'!E227 -> 8433000
A4: 3 | B4: TOKO EKA WHOLESALE | C4: ='WARUNG EKA (Drinks, Etc)'!H1 -> 7132000
A5: 4 | B5: DEWATA COCONUT | C5: ='DEWATA COCONUT (Coconut)'!H1 -> 1070000
A6: 5 | B6: SEDANA JAYA | C6: ='SEDANA JAYA'!G1 -> 0
A7: 6 | B7: PNB | C7: ='PNB (Alcohol)'!I1 -> 0
A8: 7 | B8: DSP | C8: ='DSP (Alcohol)'!K1 -> 2128500
A9: 8 | B9: DSP ARYA BIMA | C9: ='DSP ARYA BIMA (Alcohol)'!H1 -> 0
A10: 9 | B10: SELERA (SYRUP) | C10: ='SELERA OR STIR UP (Syrup)'!I1 -> 1110000
A11: 10 | B11: DW BALI | C11: ='DW BALI (Alcohol)'!J1 -> 1620000
A12: 11 | B12: DDB | C12: ='DDB (Alcohol)'!H1 -> 1312502.9
A13: 12 | B13: NANO DEWATA NON CK | C13: ='NANO DEWATA NON CK(Alcohol)'!H1 -> 0
A14: 13 | B14: NANO DEWATA CK | C14: ='NANO DEWATA CK (Alcohol)'!I1 -> 599999.41
A15: 14 | B15: BALI PERMATA JAYA | C15: ='BALI PERMATA JAYA (Corona Beer)'!I1 -> 1190000
A16: 15 | B16: BLACK COFFEE ROASTERY | C16: ='BLACK COFFEE ROASTERS (Coffee)'!J1 -> 0
A17: 16 | B17: PRASIDA LANTUR MAJU | C17: ='PT. PRASIDA LANTUR MAJU (Wine)'!I1 -> 0
A18: 17 | B18: PT. LOVINA BEACH BREWERY | C18: ='PT LOVINA BEACH BREWERY'!G1 -> 0
A19: 18 | B19: CHAI CHITAI | C19: ='CHAI CHITAI (Tea Leaf,etc)'!L1 -> 2240000
A20: 19 | B20: MULIA JAYA | C20: ='MULIA JAYA (Passion Fruit)'!H1 -> 0
A21: 20 | B21: DEWATA KENCANA DISTRIBUSI | C21: ='Dewata Kencana Distribusi (Vdka'!I1 -> 0
A22: TOTAL | C22: =SUM(C2:C21) -> 29623302
