Workbook

Sheet BUK BUNGA (Groceries)
A1: DATE | B1: ITEM | C1: QYT | D1: PRICE | E1: SUB TOTAL | F1: TOTAL
E2: =SUM(C2*D2) -> 0 | F2: =SUM(E2:E13) -> 0
E3: =SUM(C3*D3) -> 0
E4: =SUM(C4*D4) -> 0
E5: =SUM(C5*D5) -> 0
E6: =SUM(C6*D6) -> 0
E7: =SUM(C7*D7) -> 0
E8: =SUM(C8*D8) -> 0
E9: =SUM(C9*D9) -> 0
E10: =SUM(C10*D10) -> 0
E11: =SUM(C11*D11) -> 0
E12: =SUM(C12*D12) -> 0
E13: =SUM(C13*D13) -> 0 | F13: =SUM(E13:E19) -> 0
E14: =SUM(C14*D14) -> 0
E15: =SUM(C15*D15) -> 0
E16: =SUM(C16*D16) -> 0
E17: =SUM(C17*D17) -> 0
E18: =SUM(C18*D18) -> 0
E19: =SUM(C19*D19) -> 0
E20: =SUM(C20*D20) -> 0 | F20: =SUM(E20:E35) -> 0
E21: =SUM(C21*D21) -> 0
E22: =SUM(C22*D22) -> 0
E23: =SUM(C23*D23) -> 0
E24: =SUM(C24*D24) -> 0
E25: =SUM(C25*D25) -> 0
E26: =SUM(C26*D26) -> 0
E27: =SUM(C27*D27) -> 0
E28: =SUM(C28*D28) -> 0
E29: =SUM(C29*D29) -> 0
E30: =SUM(C30*D30) -> 0
E31: =SUM(C31*D31) -> 0
E32: =SUM(C32*D32) -> 0
... E35: =SUM(C35*D35) -> 0
E36: =SUM(C36*D36) -> 0 | F36: =SUM(E36:E41) -> 0
E37: =SUM(C37*D37) -> 0
E38: =SUM(C38*D38) -> 0
E39: =SUM(C39*D39) -> 0
E40: =SUM(C40*D40) -> 0
E41: =SUM(C41*D41) -> 0
E42: =SUM(C42*D42) -> 0 | F42: =SUM(E42:E47) -> 0
...

Sheet WARUNG EKA (Drinks, Etc)
A1: INV NO | B1: DATE | C1: ITEM | D1: QYT | E1: PRICE | F1: SUBTOTAL | G1: TOTALPRICE
F2: =SUM(D2*E2) -> 0 | G2: =SUM(F2:F3) -> 0
F3: =SUM(D3*E3) -> 0
F4: =SUM(D4*E4) -> 0 | G4: =SUM(F4:F6) -> 0
F5: =SUM(D5*E5) -> 0
F6: =SUM(D6*E6) -> 0
F7: =SUM(D7*E7) -> 0 | G7: =SUM(F7:F9) -> 0
F8: =SUM(D8*E8) -> 0
F9: =SUM(D9*E9) -> 0
F10: =SUM(D10*E10) -> 0 | G10: =SUM(F10:F15) -> 0
F11: =SUM(D11*E11) -> 0
F12: =SUM(D12*E12) -> 0
F13: =SUM(D13*E13) -> 0
F14: =SUM(D14*E14) -> 0
F15: =SUM(D15*E15) -> 0
F16: =SUM(D16*E16) -> 0 | G16: =SUM(F16:F18) -> 0
F17: =SUM(D17*E17) -> 0
F18: =SUM(D18*E18) -> 0
F19: =SUM(D19*E19) -> 0 | G19: =SUM(F19:F20) -> 0
F20: =SUM(D20*E20) -> 0
F21: =SUM(D21*E21) -> 0 | G21: =SUM(F21:F25) -> 0
F22: =SUM(D22*E22) -> 0
F23: =SUM(D23*E23) -> 0
F24: =SUM(D24*E24) -> 0
F25: =SUM(D25*E25) -> 0
F26: =SUM(D26*E26) -> 0 | G26: =SUM(F26:F28) -> 0
F27: =SUM(D27*E27) -> 0
F28: =SUM(D28*E28) -> 0
F29: =SUM(D29*E29) -> 0 | G29: =SUM(F29:F32) -> 0
F30: =SUM(D30*E30) -> 0
F31: =SUM(D31*E31) -> 0
F32: =SUM(D32*E32) -> 0
F33: =SUM(D33*E33) -> 0 | G33: =SUM(F33:F37) -> 0
F34: =SUM(D34*E34) -> 0
F35: =SUM(D35*E35) -> 0
F36: =SUM(D36*E36) -> 0
F37: =SUM(D37*E37) -> 0
F38: =SUM(D38*E38) -> 0 | G38: =SUM(F38:F41) -> 0
F39: =SUM(D39*E39) -> 0
F40: =SUM(D40*E40) -> 0
...

Sheet DEWATA COCONUT (Coconut)
A1: DATE | B1: INV NO. | C1: DESCRIPTIONS | D1: AMOUNT | E1: BILLS | F1: PRICE | G1: TOTAL
G2: =SUM(D2*F2) -> 0
G3: =SUM(D3*F3) -> 0
G4: =SUM(D4*F4) -> 0
G5: =SUM(D5*F5) -> 0
G6: =SUM(D6*F6) -> 0
G7: =SUM(D7*F7) -> 0
G8: =SUM(D8*F8) -> 0
G9: =SUM(D9*F9) -> 0
E10: =SUM(G2:G9) -> 0

Sheet SEDANA JAYA
A1: DATE | B1: ITEM | C1: QYT | D1: PRICE | E1: TOTAL PRICE | F1: TOTAL
A2: 45993 | B2: LUMAJANG ORANGE | C2: 3 | D2: 28000 | E2: =SUM(C2*D2) -> 84000 | F2: =SUM(E2:E10) -> 769100
B3: IMPORTED LEMON | C3: 2 | D3: 93000 | E3: =SUM(C3*D3) -> 186000
B4: MUSTARD | C4: 0.3 | D4: 17000 | E4: =SUM(C4*D4) -> 5100
B5: MALANG APPLE | C5: 1 | D5: 61000 | E5: =SUM(C5*D5) -> 61000
B6: CUCUMBER | C6: 1 | D6: 17000 | E6: =SUM(C6*D6) -> 17000
B7: CARROT | C7: 1 | D7: 31000 | E7: =SUM(C7*D7) -> 31000
B8: WATERMELON | C8: 8 | D8: 15000 | E8: =SUM(C8*D8) -> 120000
B9: FRESH MILK | C9: 5 | D9: 35000 | E9: =SUM(C9*D9) -> 175000
B10: LYCHEE CAN | C10: 2 | D10: 45000 | E10: =SUM(C10*D10) -> 90000
E11: =SUM(C11*D11) -> 0
E12: =SUM(C12*D12) -> 0 | F12: =SUM(E12:E22) -> 0
E13: =SUM(C13*D13) -> 0
E14: =SUM(C14*D14) -> 0
E15: =SUM(C15*D15) -> 0
E16: =SUM(C16*D16) -> 0
E17: =SUM(C17*D17) -> 0
E18: =SUM(C18*D18) -> 0
E19: =SUM(C19*D19) -> 0
E20: =SUM(C20*D20) -> 0
E21: =SUM(C21*D21) -> 0
E22: =SUM(C22*D22) -> 0
E23: =SUM(C23*D23) -> 0 | F23: =SUM(E23:E36) -> 0
E24: =SUM(C24*D24) -> 0
E25: =SUM(C25*D25) -> 0
E26: =SUM(C26*D26) -> 0
E27: =SUM(C27*D27) -> 0
E28: =SUM(C28*D28) -> 0
E29: =SUM(C29*D29) -> 0
E30: =SUM(C30*D30) -> 0
E31: =SUM(C31*D31) -> 0
E32: =SUM(C32*D32) -> 0
E33: =SUM(C33*D33) -> 0
E34: =SUM(C34*D34) -> 0
E35: =SUM(C35*D35) -> 0
E36: =SUM(C36*D36) -> 0
F37: =SUM(F2:F36) -> 769100

Sheet PNB (Alcohol)
A1: DATE | B1: INV NO. | C1: DESCRIPTIONS | D1: QTY | E1: BILLS | F1: UNIT PRICE | G1: SUB TOTAL | H1: TOTAL
A2: 45961 | B2: SPNO2510622 | G2: =D2*F2 -> 0 | H2: =SUM(D2*F2) -> 0
A3: 45972 | B3: SPNO2511144 | G3: =D3*F3 -> 0 | H3: =SUM(G3:G5) -> 0
G4: =D4*F4 -> 0
G5: =D5*F5 -> 0
A6: 45985 | B6: SPN02511408 | G6: =D6*F6 -> 0 | H6: =SUM(G6:G6) -> 0
H7: =SUM(H2:H6) -> 0

Sheet DSP (Alcohol)
A1: DATE | B1: INV NO. | C1: DESCRIPTIONS | D1: QTY | E1: PRICE | F1: DISCOUNT | G1: UNIT PRICE | H1: SUBTOTAL | I1: TOTAL | J1: BILL
F2: =E2*10% -> 0 | G2: =E2-F2 -> 0 | H2: =D2*G2 -> 0 | I2: =SUM(H2:H3) -> 0
F3: =E3*10% -> 0 | G3: =E3-F3 -> 0 | H3: =D3*G3 -> 0
G4: =E4-F4 -> 0 | H4: =D4*G4 -> 0 | I4: =SUM(H4) -> 0
F5: =E5*10% -> 0 | G5: =E5-F5 -> 0 | H5: =D5*G5 -> 0 | I5: =SUM(H5) -> 0
F6: =E6*10% -> 0 | G6: =E6-F6 -> 0 | H6: =D6*G6 -> 0 | I6: =SUM(H6) -> 0
F7: =E7*10% -> 0 | G7: =E7-F7 -> 0 | H7: =D7*G7 -> 0 | I7: =SUM(H7:H9) -> 0
F8: =E8*10% -> 0 | G8: =E8-F8 -> 0 | H8: =D8*G8 -> 0
F9: =E9*10% -> 0 | G9: =E9-F9 -> 0 | H9: =SUM(D9*G9) -> 0
F10: =E10*10% -> 0 | G10: =E10-F10 -> 0 | H10: =SUM(D10*G10) -> 0 | I10: =SUM(H10) -> 0
F11: =E11*10% -> 0 | G11: =E11-F11 -> 0 | H11: =SUM(D11*G11) -> 0 | I11: =SUM(H11) -> 0
F12: =E12*10% -> 0 | G12: =E12-F12 -> 0 | H12: =SUM(D12*G12) -> 0 | I12: =SUM(H12) -> 0
G13: =E13-F13 -> 0 | H13: =SUM(D13*G13) -> 0 | I13: =SUM(H13) -> 0
F14: =E14*10% -> 0 | G14: =E14-F14 -> 0 | H14: =SUM(D14*G14) -> 0 | I14: =SUM(H14) -> 0
F15: =E15*10% -> 0 | G15: =E15-F15 -> 0 | H15: =SUM(D15*G15) -> 0 | I15: =SUM(H15) -> 0
A16: TOTAL | F16: =SUM(I2:I15) -> 0

Sheet DSP ARYA BIMA (Alcohol)
A1: DATE | B1: INV NO. | C1: DESCRIPTIONS | D1: QTY | E1: BILLS | F1: PRICE | G1: TOTAL
A3: TOTAL

Sheet SELERA OR STIR UP (Syrup)
A1: DATE | B1: INV NO. | C1: DESCRIPTIONS | D1: QTY | E1: BILLS | F1: PRICE | G1: SUBTOTAL | H1: TOTAL
G2: =D2*F2 -> 0 | H2: =SUM(G2:G6) -> 0
G3: =D3*F3 -> 0
G4: =D4*F4 -> 0
G5: =D5*F5 -> 0
G6: =D6*F6 -> 0
A7: SUB TOTAL | D7: =SUM(D2:D6) -> 0 | F7: PPN (11%) | H7: =H2*11% -> 0
A8: TOTAL | E8: =SUM(H2:H7) -> 0
E9: GRAND TOTAL | F9: =SUM(E8) -> 0

Sheet DW BALI (Alcohol)
A1: DATE | B1: INV NO. | C1: DESCRIPTIONS | D1: AMOUNT | E1: BILLS | F1: PRICE | G1: TOTAL
G2: =F2*D2 -> 0
G3: =F3*D3 -> 0
A4: GRAND TOTAL | E4: =SUM(G2:G3) -> 0

Sheet DDB (Alcohol)
A1: DATE | B1: INV NO. | C1: DESCRIPTIONS | D1: AMOUNT | E1: BILLS | F1: PRICE | G1: TOTAL
G2: =SUM(D2*F2) -> 0
A3: SUB TOTAL | F3: PPN | G3: =G2*11% -> 0
A4: TOTAL | E4: =SUM(G2:G3) -> 0
G5: =D5*F5 -> 0
A6: SUB TOTAL | F6: PPN | G6: =G5*11% -> 0
A7: TOTAL | E7: =SUM(G5:G6) -> 0
A10: TOTAL
A13: TOTAL
A14: GRAND TOTAL | E14: =SUM(E4+E7+E10+E13) -> 0

Sheet NANO DEWATA (Alcohol)
A1: DATE | B1: INV NO. | C1: DESCRIPTIONS | D1: AMOUNT | E1: BILLS | F1: PRICE | G1: TOTAL
G2: =SUM(D2*F2) -> 0
A3: SUB TOTAL
A4: TOTAL | E4: =SUM(G2:G3) -> 0
G5: =SUM(D5*F5) -> 0
A6: SUB TOTAL
A7: TOTAL | E7: =SUM(G5:G6) -> 0
A14: GRAND TOTAL | E14: =SUM(E4+E7+E10+E13) -> 0

Sheet BALI PERMATA JAYA (Corona Beer)
A1: DATE | B1: INV NO. | C1: DESCRIPTIONS | D1: AMOUNT | E1: BILLS | F1: PRICE | G1: TOTAL | H1: STATUS
G2: =SUM(D2*F2) -> 0
A3: SUB TOTAL | D3: =SUM(D2) -> 0 | F3: PPN | G3: =G2*11% -> 0
A4: TOTAL | E4: =SUM(G2:G3) -> 0
G5: =SUM(D5*F5) -> 0
A6: SUB TOTAL | D6: =SUM(D5) -> 0 | F6: PPN | G6: =G5*11% -> 0
A7: TOTAL | E7: =SUM(G5:G6) -> 0
G8: =SUM(D8*F8) -> 0
A9: SUB TOTAL | F9: PPN | G9: =G8*11% -> 0
A10: TOTAL | E10: =SUM(G8:G9) -> 0
G11: =SUM(D11*F11) -> 0
A12: SUB TOTAL | F12: PPN | G12: =G11*11% -> 0
A13: TOTAL | E13: =SUM(G11:G12) -> 0
A15: SUB TOTAL | F15: PPN | G15: =G14*11% -> 0
A16: TOTAL | E16: =SUM(G14:G15) -> 0
A17: GRAND TOTAL | E17: =E4+E7+E10+E13+E16 -> 0

Sheet BLACK COFFEE ROASTERS (Coffee)
A1: DATE | B1: INV NO. | C1: DESCRIPTIONS | D1: QTY | E1: PRICE | F1: BILLS | G1: TOTAL
G2: =SUM(D2*E2) -> 0
G3: =SUM(D3*E3) -> 0
A4: Total | F4: =SUM(G2:G3) -> 0

Sheet PT. PRASIDA LANTUR MAJU (Wine)
A1: DATE | B1: INV NO. | C1: DESCRIPTIONS | D1: QTY | E1: BILLS | F1: PRICE | G1: TOTAL
G2: =SUM(D2*F2) -> 0
A3: SUBTOTAL | D3: =SUM(D2) -> 0 | F3: PPN | G3: =G2*11% -> 0
A4: TOTAL | E4: =SUM(G2:G3) -> 0
A7: TOTAL | E7: =SUM(G5:G6) -> 0
A8: GRAND TOTAL | E8: =E4+E7 -> 0

Sheet PT LOVINA BEACH BREWERY
A1: DATE | B1: INV NO. | C1: DESCRIPTIONS | D1: BILLS | E1: TOTAL | F1: STATUS
A3: TOTAL | D3: =SUM(E2:E2) -> 0

Sheet CHAI CHITAI (Tea Leaf,etc)
A1: DATE | B1: INV NO. | C1: DESCRIPTIONS | D1: QTY | E1: BILLS | F1: PRICE | G1: TOTAL
A12: GRAND TOTAL | E12: =SUM(G7+G11) -> 0

Sheet MULIA JAYA (Passion Fruit)
A1: DATE | B1: DESCRIPTIONS | C1: QTY | D1: BILLS | E1: PRICE | F1: TOTAL | G1: STATUS
F2: =C2*E2 -> 0
A3: TOTAL | D3: =SUM(F2) -> 0

Sheet Dewata Kencana Distribusi (Vdka
A1: DATE | B1: DESCRIPTIONS | C1: QTY | D1: BILLS | E1: UNIT PRICE | F1: TOTAL | G1: STATUS
A3: TOTAL | E3: =SUM(F2) -> 0

Sheet TOTAL
A1: NO | B1: SUPPLIER | C1: TOTAL
A2: 1 | B2: BUK BUNGA | C2: ='BUK BUNGA (Groceries)'!F275 -> 0
A3: 2 | B3: TOKO EKA WHOLESALE | C3: ='WARUNG EKA (Drinks, Etc)'!G118 -> 0
A4: 3 | B4: DEWATA COCONUT | C4: ='DEWATA COCONUT (Coconut)'!E10 -> 0
A5: 4 | B5: SEDANA JAYA | C5: ='SEDANA JAYA'!F37 -> 769100
A6: 5 | B6: PNB | C6: ='PNB (Alcohol)'!H7 -> 0
A7: 6 | B7: DSP | C7: ='DSP (Alcohol)'!F16 -> 0
A8: 7 | B8: DSP ARYA BIMA | C8: ='DSP ARYA BIMA (Alcohol)'!E3 -> 0
A9: 8 | B9: SELERA (SYRUP) | C9: ='SELERA OR STIR UP (Syrup)'!F9 -> 0
A10: 9 | B10: DW BALI | C10: ='DW BALI (Alcohol)'!E4 -> 0
A11: 10 | B11: DDB | C11: ='DDB (Alcohol)'!E14 -> 0
A12: 11 | B12: NANO DEWATA | C12: ='NANO DEWATA (Alcohol)'!E14 -> 0
A13: 12 | B13: BALI PERMATA JAYA | C13: ='BALI PERMATA JAYA (Corona Beer)'!E17 -> 0
A14: 13 | B14: BLACK COFFEE ROASTERY | C14: ='BLACK COFFEE ROASTERS (Coffee)'!F4 -> 0
A15: 14 | B15: PRASIDA LANTUR MAJU | C15: ='PT. PRASIDA LANTUR MAJU (Wine)'!E8 -> 0
A16: 15 | B16: PT. LOVINA BEACH BREWERY | C16: ='PT LOVINA BEACH BREWERY'!D3 -> 0
A17: 16 | B17: CHAI CHITAI | C17: ='CHAI CHITAI (Tea Leaf,etc)'!E12 -> 0
A18: 17 | B18: MULIA JAYA | C18: ='MULIA JAYA (Passion Fruit)'!D3 -> 0
A19: 18 | B19: DEWATA KENCANA DISTRIBUSI | C19: ='Dewata Kencana Distribusi (Vdka'!E3 -> 0
A20: TOTAL | C20: =SUM(C2:C13) -> 769100
