Workbook

Sheet BUK BUNGA (Groceries)
A1: DATE | B1: ITEM | C1: QYT | D1: PRICE | E1: SUBTOTAL | F1: TOTAL
F467: =SUM(F2:F466) -> 0

Sheet SEDANA JAYA (Groceries)
A1: DATE | B1: ITEM | C1: QYT | D1: PRICE | E1: SUBTOTAL | F1: TOTAL
A2: 45992 | B2: RED PEPPER | C2: 0.5 | D2: 83000 | E2: =D2*C2 -> 41500 | F2: =SUM(E2:E15) -> 1804900
B3: BANANA | C3: 4 | D3: 22000 | E3: =D3*C3 -> 88000
B4: BAKED BEANS | C4: 3 | D4: 45000 | E4: =D4*C4 -> 135000
B5: CHICK PEAS | C5: 4 | D5: 110000 | E5: =D5*C5 -> 440000
B6: OIL | C6: 5 | D6: 150000 | E6: =D6*C6 -> 750000
B7: LOCAL LEMON | C7: 1 | D7: 75000 | E7: =D7*C7 -> 75000
B8: AVOCADO | C8: 1 | D8: 39000 | E8: =D8*C8 -> 39000
B9: MANGO | C9: 1 | D9: 39000 | E9: =D9*C9 -> 39000
B10: EDAMAME | C10: 0.5 | D10: 45000 | E10: =D10*C10 -> 22500
B11: GREEN APPLE | C11: 1 | D11: 50000 | E11: =D11*C11 -> 50000
B12: WHITE PEAR | C12: 1.7 | D12: 40000 | E12: =D12*C12 -> 68000
B13: LIME | C13: 0.3 | D13: 28000 | E13: =D13*C13 -> 8400
B14: EGGPLANT | C14: 1 | D14: 10000 | E14: =D14*C14 -> 10000
B15: GREEN LETTUCE | C15: 0.5 | D15: 77000 | E15: =D15*C15 -> 38500
A16: 45993 | B16: DRAGON FRUIT | C16: 2 | D16: 28000 | E16: =D16*C16 -> 56000 | F16: =SUM(E16:E36) -> 2570700
B17: EGG | C17: 2 | D17: 66000 | E17: =D17*C17 -> 132000
B18: POTATO | C18: 7 | D18: 24000 | E18: =D18*C18 -> 168000
B19: SWEET POTATO | C19: 3 | D19: 25000 | E19: =D19*C19 -> 75000
B20: ONION | C20: 1 | D20: 39000 | E20: =D20*C20 -> 39000
B21: SALT | C21: 3 | D21: 20000 | E21: =D21*C21 -> 60000
B22: TOTOLE | C22: 3 | D22: 75000 | E22: =D22*C22 -> 225000
B23: BASMATI RICE SUKRIYA | C23: 3 | D23: 80000 | E23: =D23*C23 -> 240000
B24: RED RICE | C24: 3 | D24: 75000 | E24: =D24*C24 -> 225000
B25: BLACK PEPPER WHOLE | C25: 0.5 | D25: 200000 | E25: =D25*C25 -> 100000
B26: SUGAR | C26: 3 | D26: 25000 | E26: =D26*C26 -> 75000
B27: OLIVE OIL | C27: 1 | D27: 450000 | E27: =D27*C27 -> 450000
B28: TABASCO | C28: 1 | D28: 85000 | E28: =D28*C28 -> 85000
... B36: YELLOW PEPPER | C36: 0.5 | D36: 94000 | E36: =D36*C36 -> 47000
A37: 45993 | B37: AVOCADO | C37: 1 | D37: 39000 | E37: =D37*C37 -> 39000 | F37: =SUM(E37:E56) -> 1499400
B38: SUNKIST | C38: 1 | D38: 50000 | E38: =D38*C38 -> 50000
B39: LEMON | C39: 1 | D39: 83000 | E39: =D39*C39 -> 83000
B40: MANGO | C40: 1 | D40: 39000 | E40: =D40*C40 -> 39000
B41: BASIL | C41: 0.1 | D41: 88000 | E41: =D41*C41 -> 8800
B42: MINT | C42: 0.1 | D42: 72000 | E42: =D42*C42 -> 7200
B43: CHERRY RED TOMATO | C43: 0.5 | D43: 50000 | E43: =D43*C43 -> 25000
B44: CHERRY YELLOW TOMATO | C44: 0.4 | D44: 61000 | E44: =D44*C44 -> 24400
B45: STRAWBERRY (250) | C45: 0.3 | D45: 120000 | E45: =D45*C45 -> 36000
B46: QUAIL EGG | C46: 30 | D46: 1000 | E46: =D46*C46 -> 30000
B47: ICE BERG | C47: 0.5 | D47: 70000 | E47: =D47*C47 -> 35000
...

Sheet RAFI SEAFOOD (Seafood)
A1: DATE | B1: DESCRIPTION | C1: QUANTITY | D1: PRICE | E1: BILLS | F1: SUBTOTAL | G1: TOTAL
F2: =SUM(C2*D2) -> 0 | G2: =SUM(F2:F4) -> 0
F3: =SUM(C3*D3) -> 0
F4: =SUM(C4*D4) -> 0
F5: =SUM(C5*D5) -> 0 | G5: =SUM(F5:F6) -> 0
F6: =SUM(C6*D6) -> 0
F7: =SUM(C7*D7) -> 0 | G7: =SUM(C7*D7+C8*D8+C11*D11) -> 0
F8: =SUM(C8*D8) -> 0
F11: =SUM(C11*D11) -> 0
F12: =SUM(C12*D12) -> 0 | G12: =SUM(F12:F13) -> 0
F13: =SUM(C13*D13) -> 0
F14: =C14*D14 -> 0 | G14: =SUM(F14:F15) -> 0
F15: =C15*D15 -> 0
F16: =SUM(C16*D16) -> 0 | G16: =SUM(C16*D16+C17*D17+C18*D18) -> 0
F17: =SUM(C17*D17) -> 0
F18: =SUM(C18*D18) -> 0
F19: =SUM(C19*D19) -> 0 | G19: =SUM(F19:F23) -> 0
F20: =SUM(C20*D20) -> 0
F21: =SUM(C21*D21) -> 0
F22: =SUM(C22*D22) -> 0
F23: =SUM(C23*D23) -> 0
F24: =SUM(C24*D24) -> 0 | G24: =SUM(C24*D24+C25*D25) -> 0
F25: =SUM(C25*D25) -> 0
F26: =SUM(C26*D26) -> 0 | G26: =SUM(F26:F29) -> 0
F27: =SUM(C27*D27) -> 0
F28: =SUM(C28*D28) -> 0
F29: =SUM(C29*D29) -> 0
F30: =C30*D30 -> 0 | G30: =SUM(F30:F32) -> 0
F31: =C31*D31 -> 0
F32: =C32*D32 -> 0
F33: =SUM(C33*D33) -> 0 | G33: =SUM(F33:F35) -> 0
F34: =SUM(C34*D34) -> 0
F35: =SUM(C35*D35) -> 0
D61: =SUM(G2:G60) -> 0

Sheet MAMA RADA PRODUCTION (Dumpling)
A1: DATE | B1: INV NO. | C1: DESCRIPTIONS | D1: QTY | E1: BIILS | F1: PRICE | G1: SUBTOTAL | H1: TOTAL
G2: =D2*F2 -> 0 | H2: =SUM(G2) -> 0
G3: =SUM(D3*F3+D4*F4) -> 0
G5: =SUM(D5*F5+D6*F6+D7*F7) -> 0
G8: =SUM(D8*F8) -> 0
E12: GRAND TOTAL | H12: =SUM(H2:H11) -> 0

Sheet KSP (Chicken)
A1: DATE | B1: INV NO. | C1: DESCRIPTIONS | D1: QTY | E1: BILLS | F1: PRICE | G1: SUB TOTAL | H1: TOTAL
G2: =SUM(D2*F2) -> 0 | H2: =SUM(D2*F2+D3*F3) -> 0
G3: =SUM(D3*F3) -> 0
G4: =SUM(D4*F4) -> 0 | H4: =SUM(D4*F4+D5*F5+D6*F6) -> 0
G5: =SUM(D5*F5) -> 0
G6: =SUM(D6*F6) -> 0
G7: =SUM(D7*F7) -> 0 | H7: =SUM(G7:G8) -> 0
G8: =SUM(D8*F8) -> 0
G9: =D9*F9 -> 0 | H9: =SUM(G9:G10) -> 0
G10: =D10*F10 -> 0
G11: =D11*F11 -> 0 | H11: =SUM(G11:G12) -> 0
G12: =D12*F12 -> 0
H13: =SUM(H2:H12) -> 0

Sheet SURYA CIPTA NIAGA BALI (Beef)
A1: DATE | B1: INV NO. | C1: DESCRIPTIONS | D1: QTY | E1: BILLS | F1: PRICE | G1: SUBTOTAL | H1: TOTAL | I1: STATUS
G2: =D2*F2 -> 0 | H2: =SUM(G2:G3) -> 0
G3: =D3*F3 -> 0
G4: =D4*F4 -> 0 | H4: =SUM(G4:G5) -> 0
G5: =D5*F5 -> 0
G6: =D6*F6 -> 0 | H6: =SUM(D6*F6) -> 0
G8: =D8*F8 -> 0 | H8: =SUM(D8*F8) -> 0
A9: TOTAL | H9: =SUM(H2:H8) -> 0

Sheet BAYU AGNI MERTA (Gas)
A1: DATE | B1: INV NO. | C1: DESCRIPTIONS | D1: QTY | E1: BILLS | F1: PRICE | G1: TOTAL
G2: =SUM(D2*F2) -> 0
G3: =D3*F3 -> 0
A4: TOTAL | E4: =SUM(G2:G3) -> 0

Sheet Joy Green (Mix Berry)
A1: NO | B1: DATE | C1: TOTAL | D1: PC | E1: STATUS
A3: Total | D3: =SUM(C2:C2) -> 0

Sheet CELEBRITY BAKERY (Bakery)
A1: DATE | B1: INV.NO | C1: DESCRIPTION | D1: QTY | E1: BILLS | F1: PRICE | G1: TOTAL
A5: TOTAL | E5: =SUM(G2) -> 0

Sheet Krop (Edible flower)
A1: DATE | B1: INV.NO | C1: DESCRIPTION | D1: QTY | E1: BILLS | F1: PRICE | G1: SUBTOTAL | H1: TOTAL
G2: =D2*F2 -> 0 | H2: =SUM(G2:G2) -> 0
G3: =D3*F3 -> 0 | H3: =SUM(G3:G6) -> 0
G4: =D4*F4 -> 0
G5: =D5*F5 -> 0
G6: =D6*F6 -> 0
A7: TOTAL | H7: =SUM(H2:H6) -> 0

Sheet Boiler (Dumplings&Syrniki)
A1: DATE | B1: INV.NO | C1: DESCRIPTION | D1: QTY | E1: BILLS | F1: PRICE | G1: SUBTOTAL | H1: TOTAL | I1: TOTAL AFTER TAX
G2: =D2*F2 -> 0 | H2: =SUM(G2:G4) -> 0 | I2: =(H2*10%)+H2 -> 0
G3: =D3*F3 -> 0
G4: =D4*F4 -> 0
A5: TOTAL | E5: =SUM(I2) -> 0

Sheet Abdi Jaya (TKW, Vacuum Bag)
A1: DATE | B1: INV.NO | C1: DESCRIPTION | D1: QTY | E1: BILLS | F1: PRICE | G1: SUBTOTAL | H1: TOTAL
G2: =D2*F2 -> 0 | H2: =SUM(G2:G3) -> 0
G3: =D3*F3 -> 0
G4: =D4*F4 -> 0 | H4: =SUM(G4:G5) -> 0
G5: =D5*F5 -> 0
G6: =D6*F6 -> 0 | H6: =SUM(G6:G7) -> 0
G7: =D7*F7 -> 0
A8: GRAND TOTAL | D8: =SUM(H2:H7) -> 0

Sheet Dishy Soap (Chemicals)
A1: DATE | B1: DESCRIPTION | C1: QTY | D1: BILLS | E1: PRICE | F1: SUBTOTAL | G1: TOTAL
F2: =C2*E2 -> 0 | G2: =SUM(F2:F6) -> 0
F3: =C3*E3 -> 0
F4: =C4*E4 -> 0
F5: =C5*E5 -> 0
F6: =C6*E6 -> 0
F7: =C7*E7 -> 0 | G7: =SUM(F7:F9) -> 0
F8: =C8*E8 -> 0
F9: =C9*E9 -> 0
F10: =C10*E10 -> 0 | G10: =SUM(F10) -> 0
A11: GRAND TOTAL | G11: =SUM(G2:G10) -> 0

Sheet Abiseka (Fresh Milk)
A1: DATE | B1: DESCRIPTION | C1: QTY | D1: BILLS | E1: PRICE | F1: SUBTOTAL | G1: TOTAL
A3: GRAND TOTAL | G3: =SUM(G2) -> 0

Sheet TOTAL
A1: SUPPLIER | B1: Total
A2: BU BUNGA | B2: ='BUK BUNGA (Groceries)'!F467 -> 0
A3: SEDANA JAYA | B3: ='SEDANA JAYA (Groceries)'!F660 -> 5875000
A4: RAFI SEAFOOD | B4: ='RAFI SEAFOOD (Seafood)'!D61 -> 0
A5: MAMA RADA PRODUCTION | B5: ='MAMA RADA PRODUCTION (Dumpling)'!H12 -> 0
A6: KSP | B6: ='KSP (Chicken)'!H13 -> 0
A7: SURYA CIPTA NIAGA BALI | B7: ='SURYA CIPTA NIAGA BALI (Beef)'!H9 -> 0
A8: BAYU AGNI MERTA | B8: ='BAYU AGNI MERTA (Gas)'!E4 -> 0
A9: JOY GREEN | B9: ='Joy Green (Mix Berry)'!D3 -> 0
A10: CELEBRITY BAKERY | B10: ='CELEBRITY BAKERY (Bakery)'!E5 -> 0
A11: KROP NATIION | B11: ='Krop (Edible flower)'!H7 -> 0
A12: BOILER | B12: ='Boiler (Dumplings&Syrniki)'!E5 -> 0
A13: ABDI JAYA | B13: ='Abdi Jaya (TKW, Vacuum Bag)'!D8 -> 0
A14: DISHY SOAP | B14: ='Dishy Soap (Chemicals)'!G11 -> 0
A15: ABISEKA | B15: ='Abiseka (Fresh Milk)'!G3 -> 0
A16: TOTAL | B16: =SUM(B2:B12) -> 5875000
