Workbook

Sheet BUK BUNGA BAR (Groceries)
A1: DATE | B1: ITEM | C1: QYT | D1: PRICE | E1: SUB TOTAL | F1: TOTAL | G1: =SUM(F:F) -> 17802000
A2: 46054 | B2: HONEY PINEAPPLE | C2: 15 | D2: 10000 | E2: =SUM(C2*D2) -> 150000 | F2: =SUM(E2:E15) -> 974000
B3: IMPORTED LEMON | C3: 3 | D3: 70000 | E3: =SUM(C3*D3) -> 210000
B4: KINTAMANI ORANGE | C4: 5 | D4: 25000 | E4: =SUM(C4*D4) -> 125000
B5: CUCUMBER | C5: 1 | D5: 15000 | E5: =SUM(C5*D5) -> 15000
B6: GREEN APPLE | C6: 1 | D6: 48000 | E6: =SUM(C6*D6) -> 48000
B7: WATERMELON | C7: 7.74 | D7: 15000 | E7: 116000
B8: GREEN MUSTARD | C8: 0.5 | D8: 20000 | E8: =SUM(C8*D8) -> 10000
B9: LIME | C9: 0.5 | D9: 30000 | E9: =SUM(C9*D9) -> 15000
B10: MINT LEAVES | C10: 0.3 | D10: 80000 | E10: =SUM(C10*D10) -> 24000
B11: MANGO | C11: 1 | D11: 40000 | E11: =SUM(C11*D11) -> 40000
B12: STRAWBERRY | C12: 0.25 | D12: 100000 | E12: =SUM(C12*D12) -> 25000
B13: FRESH MILK (GREENFIELDS) | C13: 4 | D13: 24000 | E13: =SUM(C13*D13) -> 96000
B14: OAT MILK | C14: 1 | D14: 40000 | E14: =SUM(C14*D14) -> 40000
B15: SUGAR | C15: 3 | D15: 20000 | E15: =SUM(C15*D15) -> 60000
A16: 46055 | B16: HONEY PINEAPPLE | C16: 3 | D16: 10000 | E16: =SUM(C16*D16) -> 30000 | F16: =SUM(E16:E24) -> 524000
B17: KINTAMANI ORANGE | C17: 4 | D17: 25000 | E17: =SUM(C17*D17) -> 100000
B18: IMPORTED LEMON | C18: 2 | D18: 70000 | E18: =SUM(C18*D18) -> 140000
B19: CARROT | C19: 1 | D19: 30000 | E19: =SUM(C19*D19) -> 30000
B20: LIME | C20: 0.5 | D20: 30000 | E20: =SUM(C20*D20) -> 15000
B21: FRESH MILK (GREENFIELDS) | C21: 4 | D21: 24000 | E21: =SUM(C21*D21) -> 96000
B22: ALMOND MILK | C22: 1 | D22: 48000 | E22: =SUM(C22*D22) -> 48000
B23: OAT MILK | C23: 1 | D23: 40000 | E23: =SUM(C23*D23) -> 40000
B24: SARIWANGI | C24: 1 | D24: 25000 | E24: =SUM(C24*D24) -> 25000
A25: 46056 | B25: IMPORTED LEMON | C25: 1 | D25: 70000 | E25: =SUM(C25*D25) -> 70000 | F25: =SUM(E25:E41) -> 918000
B26: KINTAMANI ORANGE | C26: 3 | D26: 25000 | E26: =SUM(C26*D26) -> 75000
B27: BASIL | C27: 0.3 | D27: 80000 | E27: =SUM(C27*D27) -> 24000
B28: WATERMELON | C28: 3.415 | D28: 15000 | E28: 51000
B29: CUCUMBER | C29: 1 | D29: 15000 | E29: =SUM(C29*D29) -> 15000
B30: CARROT | C30: 1 | D30: 30000 | E30: =SUM(C30*D30) -> 30000
B31: GREEN APPLE | C31: 2 | D31: 48000 | E31: =SUM(C31*D31) -> 96000
B32: HONEY PINEAPPLE | C32: 8 | D32: 10000 | E32: =SUM(C32*D32) -> 80000
B33: STRAWBERRY | C33: 0.75 | D33: 100000 | E33: =SUM(C33*D33) -> 75000
B34: ROSEMARY | C34: 0.05 | D34: 150000 | E34: 8000
B35: FRESH MILK (GREENFIELDS) | C35: 6 | D35: 24000 | E35: =SUM(C35*D35) -> 144000
B36: OAT MILK | C36: 2 | D36: 40000 | E36: =SUM(C36*D36) -> 80000
B37: ALMOND MILK | C37: 1 | D37: 49000 | E37: =SUM(C37*D37) -> 49000
B38: GREEN MUSTARD | C38: 0.5 | D38: 20000 | E38: =SUM(C38*D38) -> 10000
B39: MANGO | C39: 1 | D39: 40000 | E39: =SUM(C39*D39) -> 40000
B40: ENGLISH SPINACH | C40: 0.3 | D40: 35000 | E40: 11000
...

Sheet WARUNG EKA (Drinks, Etc)
A1: INV NO | B1: DATE | C1: ITEM | D1: QYT | E1: PRICE | F1: SUBTOTAL | G1: TOTALPRICE | H1: =SUM(G:G) -> 11916000
A2: 78314 | B2: 46054 | C2: CRYSTAL ICE 5KG | D2: 6 | E2: 8000 | F2: =SUM(D2*E2) -> 48000 | G2: =SUM(F2:F4) -> 206000
C3: CLEO GALLOON 19 LTR | D3: 1 | E3: 23000 | F3: =SUM(D3*E3) -> 23000
C4: COCA-COLA CAN 330 ML | D4: 1 | E4: 135000 | F4: =SUM(D4*E4) -> 135000
A5: 78428 | B5: 46055 | C5: AQUA GALLOON 19 LTR | D5: 1 | E5: 21000 | F5: =SUM(D5*E5) -> 21000 | G5: =SUM(F5:F10) -> 567000
C6: CLEO GALLOON 19 LTR | D6: 1 | E6: 23000 | F6: =SUM(D6*E6) -> 23000
C7: AQUA REFLECTIONS STILL 750 ML | D7: 2 | E7: 115000 | F7: =SUM(D7*E7) -> 230000
C8: AQUA REFLECTIONS STILL 380 ML | D8: 1 | E8: 125000 | F8: =SUM(D8*E8) -> 125000
C9: AQUA REFLECTIONS SPARKLING 750 ML | D9: 1 | E9: 120000 | F9: =SUM(D9*E9) -> 120000
C10: CRYSTAL ICE 5KG | D10: 6 | E10: 8000 | F10: =SUM(D10*E10) -> 48000
A11: 78381 | B11: 46055 | C11: BINTANG PINT 330 ML | D11: 1 | E11: 480000 | F11: =SUM(D11*E11) -> 480000 | G11: =SUM(F11) -> 480000
A12: 78459 | B12: 46056 | C12: CLEO GALLOON 19 LTR | D12: 1 | E12: 23000 | F12: =SUM(D12*E12) -> 23000 | G12: =SUM(F12:F17) -> 480000
C13: CRYSTAL ICE 5KG | D13: 5 | E13: 8000 | F13: =SUM(D13*E13) -> 40000
C14: COKE ZERO CAN 330 ML | D14: 1 | E14: 135000 | F14: =SUM(D14*E14) -> 135000
C15: POLARIS SODA WATER CAN 330 ML | D15: 1 | E15: 125000 | F15: =SUM(D15*E15) -> 125000
C16: AQUA REFLECTIONS STILL 750 ML | D16: 1 | E16: 115000 | F16: =SUM(D16*E16) -> 115000
C17: AQUA GALLOON 19 LTR | D17: 2 | E17: 21000 | F17: =SUM(D17*E17) -> 42000
A18: 78535 | B18: 46057 | C18: AQUA REFLECTIONS STILL 750 ML | D18: 1 | E18: 115000 | F18: =SUM(D18*E18) -> 115000 | G18: =SUM(F18:F21) -> 320000
C19: AQUA REFLECTIONS SPARKLING 380 ML | D19: 1 | E19: 135000 | F19: =SUM(D19*E19) -> 135000
C20: CRYSTAL ICE 5KG | D20: 3 | E20: 8000 | F20: =SUM(D20*E20) -> 24000
C21: CLEO GALLOON 19 LTR | D21: 2 | E21: 23000 | F21: =SUM(D21*E21) -> 46000
A22: 78595 | B22: 46058 | C22: CRYSTAL ICE 5KG | D22: 4 | E22: 8000 | F22: =SUM(D22*E22) -> 32000 | G22: =SUM(F22:F23) -> 74000
C23: AQUA GALLOON 19 LTR | D23: 2 | E23: 21000 | F23: =SUM(D23*E23) -> 42000
A24: 78661 | B24: 46059 | C24: CRYSTAL ICE 5KG | D24: 6 | E24: 8000 | F24: =SUM(D24*E24) -> 48000 | G24: =SUM(F24:F27) -> 805000
C25: CLEO GALLOON 19 LTR | D25: 2 | E25: 23000 | F25: =SUM(D25*E25) -> 46000
C26: AQUA GALLOON 19 LTR | D26: 1 | E26: 21000 | F26: =SUM(D26*E26) -> 21000
C27: AQUA REFLECTIONS STILL 750 ML | D27: 6 | E27: 115000 | F27: =SUM(D27*E27) -> 690000
A28: 78721 | B28: 46060 | C28: POLARIS SODA WATER CAN 330 ML | D28: 1 | E28: 125000 | F28: =SUM(D28*E28) -> 125000 | G28: =SUM(F28:F32) -> 329000
C29: AQUA REFLECTIONS SPARKLING 750 ML | D29: 1 | E29: 120000 | F29: =SUM(D29*E29) -> 120000
C30: CRYSTAL ICE 5KG | D30: 5 | E30: 8000 | F30: =SUM(D30*E30) -> 40000
C31: AQUA GALLOON 19 LTR | D31: 1 | E31: 21000 | F31: =SUM(D31*E31) -> 21000
C32: CLEO GALLOON 19 LTR | D32: 1 | E32: 23000 | F32: =SUM(D32*E32) -> 23000
A33: 78787 | B33: 46061 | C33: CRYSTAL ICE 5KG | D33: 5 | E33: 8000 | F33: =SUM(D33*E33) -> 40000 | G33: =SUM(F33:F36) -> 227000
C34: CLEO GALLOON 19 LTR | D34: 2 | E34: 23000 | F34: =SUM(D34*E34) -> 46000
C35: AQUA GALLOON 19 LTR | D35: 1 | E35: 21000 | F35: =SUM(D35*E35) -> 21000
C36: AQUA REFLECTIONS SPARKLING 750 ML | D36: 1 | E36: 120000 | F36: =SUM(D36*E36) -> 120000
A37: 78888 | B37: 46062 | C37: CRYSTAL ICE 5KG | D37: 5 | E37: 8000 | F37: =SUM(D37*E37) -> 40000 | G37: =SUM(F37:F43) -> 729000
C38: AQUA GALLOON 19 LTR | D38: 1 | E38: 21000 | F38: =SUM(D38*E38) -> 21000
C39: CLEO GALLOON 19 LTR | D39: 1 | E39: 23000 | F39: =SUM(D39*E39) -> 23000
C40: AQUA REFLECTIONS STILL 380 ML | D40: 2 | E40: 125000 | F40: =SUM(D40*E40) -> 250000
...

Sheet DEWATA COCONUT (Coconut)
A1: DATE | B1: INV NO. | C1: DESCRIPTIONS | D1: AMOUNT | E1: BILLS | F1: PRICE | G1: TOTAL
A2: 46054 | B2: 12306 | C2: COCONUT LOGO | D2: 15 | F2: 13000 | G2: =SUM(D2*F2) -> 195000
A3: 46056 | B3: 12381 | C3: COCONUT LOGO | D3: 20 | F3: 13000 | G3: =SUM(D3*F3) -> 260000
A4: 46058 | B4: 12464 | C4: COCONUT LOGO | D4: 10 | F4: 13000 | G4: =SUM(D4*F4) -> 130000
A5: 46060 | B5: 12607 | C5: COCONUT LOGO | D5: 20 | F5: 12000 | G5: =SUM(D5*F5) -> 240000
A6: 46063 | B6: 12691 | C6: COCONUT LOGO | D6: 20 | F6: 12000 | G6: =SUM(D6*F6) -> 240000
A7: 46065 | B7: 12773 | C7: COCONUT LOGO | D7: 20 | F7: 13000 | G7: =SUM(D7*F7) -> 260000
A8: 46068 | B8: 12815 | C8: COCONUT LOGO | D8: 10 | F8: 13000 | G8: =SUM(D8*F8) -> 130000
A9: 46071 | B9: 12946 | C9: COCONUT LOGO | D9: 20 | F9: 13000 | G9: =SUM(F9*D9) -> 260000
A10: 46075 | B10: 13389 | C10: COCONUT LOGO | D10: 20 | F10: 13000 | G10: =SUM(F10*D10) -> 260000
A11: 46078 | B11: 13025 | C11: COCONUT LOGO | D11: 15 | F11: 12000 | G11: =SUM(F11*D11) -> 180000
A12: 46080 | B12: 13076 | C12: COCONUT LOGO | D12: 20 | F12: 13000 | G12: =SUM(F12*D12) -> 260000
G13: =SUM(D13*F13) -> 0
E14: =SUM(G2:G13) -> 2415000

Sheet SEDANA JAYA
A1: DATE | B1: ITEM | C1: QYT | D1: PRICE | E1: TOTAL PRICE | F1: TOTAL
E2: =SUM(C2*D2) -> 0 | F2: =SUM(E2:E23) -> 0
E3: =SUM(C3*D3) -> 0
E4: =SUM(C4*D4) -> 0
E5: =SUM(C5*D5) -> 0
E6: =SUM(C6*D6) -> 0
E7: =SUM(C7*D7) -> 0
E8: =SUM(C8*D8) -> 0
E9: =SUM(C9*D9) -> 0
E10: =SUM(C10*D10) -> 0
E11: =SUM(C11*D11) -> 0
E12: =SUM(C12*D12) -> 0
E13: =SUM(C13*D13) -> 0
E14: =SUM(C14*D14) -> 0
... E23: =SUM(C23*D23) -> 0
E24: =SUM(C24*D24) -> 0 | F24: =SUM(E24:E31) -> 0
E25: =SUM(C25*D25) -> 0
E26: =SUM(C26*D26) -> 0
E27: =SUM(C27*D27) -> 0
E28: =SUM(C28*D28) -> 0
E29: =SUM(C29*D29) -> 0
E30: =SUM(C30*D30) -> 0
E31: =SUM(C31*D31) -> 0
F47: =SUM(F2:F46) -> 0

Sheet PNB (Alcohol)
A1: DATE | B1: INV NO. | C1: DESCRIPTIONS | D1: QTY | E1: BILLS | F1: UNIT PRICE | G1: SUB TOTAL | H1: TOTAL
A2: 46059 | B2: SPNB2602345 | C2: MANCINO BIANCO 750 ML | D2: 3 | F2: 500000 | G2: =D2*F2 -> 1500000 | H2: =SUM(D2*F2) -> 1500000
G3: =D3*F3 -> 0 | H3: =SUM(G3:G5) -> 0
G4: =D4*F4 -> 0
G5: =D5*F5 -> 0
G6: =D6*F6 -> 0 | H6: =SUM(G6:G6) -> 0
H7: =SUM(H2:H6) -> 1500000

Sheet DSP (Alcohol)
A1: DATE | B1: INV NO. | C1: DESCRIPTIONS | D1: QTY | E1: PRICE | F1: DISCOUNT | G1: UNIT PRICE | H1: SUBTOTAL | I1: TOTAL | J1: BILL
A2: 46058 | B2: SOMDG/DSP/26/02/0030 | C2: MDG - F VODKA | D2: 3 | E2: 246000 | F2: 0 | G2: =E2-F2 -> 246000 | H2: =D2*G2 -> 738000 | I2: =SUM(H2) -> 738000
A3: 46058 | B3: SO/DSP/26/02/0284 | C3: DA VINCI LEONARDO PROSECCO DOC | D3: 2 | E3: 370000 | F3: =E3*10% -> 37000 | G3: =E3-F3 -> 333000 | H3: =D3*G3 -> 666000 | I3: =SUM(H3) -> 666000
A4: 46074 | B4: SO/DSP/26/02/1236 | C4: HUNTER'S RIESLING | D4: 2 | E4: 385000 | F4: =E4*10% -> 38500 | G4: =E4-F4 -> 346500 | H4: =D4*G4 -> 693000 | I4: =SUM(H4) -> 693000
A5: 46080 | B5: SO/DSP/26/02/1622 | C5: VIGNETI DEL VULTURE - PIPOLI ROSATO BASILICATA | D5: 1 | E5: 350000 | F5: =E5*10% -> 35000 | G5: =E5-F5 -> 315000 | H5: =D5*G5 -> 315000 | I5: =SUM(H5) -> 315000
A6: 46081 | B6: SO/DSP/26/02/1668 | C6: MCGUIGAN - BLACK LABEL SAUVIGNON BLANC | D6: 4 | E6: 295000 | F6: =E6*10% -> 29500 | G6: =E6-F6 -> 265500 | H6: =D6*G6 -> 1062000 | I6: =SUM(H6) -> 1062000
F7: =E7*10% -> 0 | G7: =E7-F7 -> 0 | H7: =D7*G7 -> 0 | I7: =SUM(H7:H9) -> 0
F8: =E8*10% -> 0 | G8: =E8-F8 -> 0 | H8: =D8*G8 -> 0
F9: =E9*10% -> 0 | G9: =E9-F9 -> 0 | H9: =SUM(D9*G9) -> 0
F10: =E10*10% -> 0 | G10: =E10-F10 -> 0 | H10: =SUM(D10*G10) -> 0 | I10: =SUM(H10) -> 0
F11: =E11*10% -> 0 | G11: =E11-F11 -> 0 | H11: =SUM(D11*G11) -> 0 | I11: =SUM(H11) -> 0
F12: =E12*10% -> 0 | G12: =E12-F12 -> 0 | H12: =SUM(D12*G12) -> 0 | I12: =SUM(H12) -> 0
G13: =E13-F13 -> 0 | H13: =SUM(D13*G13) -> 0 | I13: =SUM(H13) -> 0
F14: =E14*10% -> 0 | G14: =E14-F14 -> 0 | H14: =SUM(D14*G14) -> 0 | I14: =SUM(H14) -> 0
F15: =E15*10% -> 0 | G15: =E15-F15 -> 0 | H15: =SUM(D15*G15) -> 0 | I15: =SUM(H15) -> 0
A16: TOTAL | F16: =SUM(I2:I15) -> 3474000

Sheet DSP ARYA BIMA (Alcohol)
A1: DATE | B1: INV NO. | C1: DESCRIPTIONS | D1: QTY | E1: BILLS | F1: PRICE | G1: TOTAL
A2: 46058 | B2: SOPR/ABC/26/02/0071 | C2: HAVANA CLUB 3 YO | D2: 2 | F2: 334000 | G2: =F2*D2 -> 668000
A3: TOTAL | E3: =SUM(G2) -> 668000

Sheet SELERA OR STIR UP (Syrup)
A1: DATE | B1: INV NO. | C1: DESCRIPTIONS | D1: QTY | E1: BILLS | F1: PRICE | G1: SUBTOTAL | H1: TOTAL
A2: 46055 | B2: SO.03-260055 | C2: CRIMINAL CARAMEL PET | D2: 2 | F2: 100000 | G2: =D2*F2 -> 200000 | H2: =SUM(G2:G8) -> 2200000
C3: HANDSOME HAZELNUT PET | D3: 2 | F3: 100000 | G3: =D3*F3 -> 200000
C4: BESPOKE BUTTERSCOTCH | D4: 2 | F4: 100000 | G4: =D4*F4 -> 200000
C5: ELEGANT ELDERFLOWER PET | D5: 2 | F5: 100000 | G5: =D5*F5 -> 200000
C6: BLISFUL BLUEBERRY PET | D6: 2 | F6: 100000 | G6: =D6*F6 -> 200000
C7: GROOVY GRAPE | D7: 2 | F7: 100000 | G7: =D7*F7 -> 200000
C8: MARVELOUS MANGO PET | D8: 10 | F8: 100000 | G8: =D8*F8 -> 1000000
A9: SUB TOTAL | D9: =SUM(D2:D8) -> 22 | F9: PPN (11%) | H9: =H2*11% -> 242000
A10: TOTAL | E10: =SUM(H2:H9) -> 2442000
A11: 46071 | B11: SO.03-260075 | C11: LOYAL LYCHEE PET | D11: 2 | F11: 100000 | G11: =D11*F11 -> 200000 | H11: =SUM(G11:G19) -> 1700000
C12: ELEGANT ELDERFLOWER PET | D12: 1 | F12: 100000 | G12: =D12*F12 -> 100000
C13: CHEERFUL AMARENA CHERRY | D13: 2 | F13: 100000 | G13: =D13*F13 -> 200000
C14: GROOVY GRAPE | D14: 2 | F14: 100000 | G14: =D14*F14 -> 200000
C15: BLISSFUL BLUEBERRY PET | D15: 2 | F15: 100000 | G15: =D15*F15 -> 200000
C16: CRIMINIAL CARAMEL PET | D16: 3 | F16: 100000 | G16: =D16*F16 -> 300000
C17: HANDSOME HAZELNUT PET | D17: 2 | F17: 100000 | G17: =D17*F17 -> 200000
C18: BESPOKE BUTTERSCOTCH | D18: 2 | F18: 100000 | G18: =D18*F18 -> 200000
C19: VOILA VANILLA | D19: 1 | F19: 100000 | G19: =D19*F19 -> 100000
A20: SUB TOTAL | D20: =SUM(D11:D19) -> 17 | F20: PPN (11%) | H20: =H11*11% -> 187000
A21: TOTAL | E21: =SUM(H11:H20) -> 1887000
D22: GRAND TOTAL | F22: =SUM(E10,E21) -> 4329000

Sheet DW BALI (Alcohol)
A1: DATE | B1: INV NO. | C1: DESCRIPTIONS | D1: AMOUNT | E1: BILLS | F1: PRICE | G1: TOTAL
A2: 46059 | B2: DW/71/873 | C2: JIM BEAM BLACK 700 ML | D2: 2 | F2: 450000 | G2: =F2*D2 -> 900000
A3: 46071 | B3: DW/72/553 | C3: APEROL 700 ML | D3: 3 | F3: 380000 | G3: =SUM(F3*D3) -> 1140000
A4: 46074 | B4: DW/72/717 | C4: GREY GOOSE VODKA 750 ML | D4: 1 | F4: 580000 | G4: =SUM(F4*D4) -> 580000
G5: =F5*D5 -> 0
A6: GRAND TOTAL | E6: =SUM(G2:G5) -> 2620000

Sheet DDB (Alcohol)
A1: DATE | B1: INV NO. | C1: DESCRIPTIONS | D1: AMOUNT | E1: BILLS | F1: PRICE | G1: TOTAL
A2: 46074 | B2: 43723 | C2: GORDON GIN PREMIUM DRY 750 ML | D2: 2 | F2: 236487 | G2: =SUM(D2*F2) -> 472974
A3: SUB TOTAL | F3: PPN | G3: =G2*11% -> 52027.14
A4: TOTAL | E4: =SUM(G2:G3) -> 525001.14
G5: =D5*F5 -> 0
A6: SUB TOTAL | F6: PPN | G6: =G5*11% -> 0
A7: TOTAL | E7: =SUM(G5:G6) -> 0
A10: TOTAL
A13: TOTAL
A14: GRAND TOTAL | E14: =SUM(E4+E7+E10+E13) -> 525001.14

Sheet NANO DEWATA (Alcohol)
A1: DATE | B1: INV NO. | C1: DESCRIPTIONS | D1: AMOUNT | E1: BILLS | F1: PRICE | G1: TOTAL
A2: 46078 | B2: INX/NABLIX/26/02/0031 | C2: GIFFARD PARFAIT TRIPLE SEC | D2: 3 | F2: 285000 | G2: =SUM(D2*F2) -> 855000
A3: SUB TOTAL
A4: TOTAL | E4: =SUM(G2:G3) -> 855000
G5: =SUM(D5*F5) -> 0
A6: SUB TOTAL
A7: TOTAL | E7: =SUM(G5:G6) -> 0
A14: GRAND TOTAL | E14: =SUM(E4+E7+E10+E13) -> 855000

Sheet BALI PERMATA JAYA (Corona Beer)
A1: DATE | B1: INV NO. | C1: DESCRIPTIONS | D1: AMOUNT | E1: BILLS | F1: PRICE | G1: TOTAL | H1: STATUS
A2: 46078 | B2: INV/PERMAQ/26/02/0771 | C2: CORONA BEER | D2: 24 | F2: 44669.67 | G2: =SUM(D2*F2) -> 1072072.1
A3: SUB TOTAL | D3: =SUM(D2) -> 24 | F3: PPN | G3: =G2*11% -> 117927.93
A4: TOTAL | E4: =SUM(G2:G3) -> 1190000
G5: =SUM(D5*F5) -> 0
A6: SUB TOTAL | D6: =SUM(D5) -> 0 | F6: PPN | G6: =G5*11% -> 0
A7: TOTAL | E7: =SUM(G5:G6) -> 0
G8: =SUM(D8*F8) -> 0
A9: SUB TOTAL | F9: PPN | G9: =G8*11% -> 0
A10: TOTAL | E10: =SUM(G8:G9) -> 0
G11: =SUM(D11*F11) -> 0
A12: SUB TOTAL | F12: PPN | G12: =G11*11% -> 0
A13: TOTAL | E13: =SUM(G11:G12) -> 0
A15: SUB TOTAL | F15: PPN | G15: =G14*11% -> 0
A16: TOTAL | E16: =SUM(G14:G15) -> 0
A17: GRAND TOTAL | E17: =E4+E7+E10+E13+E16 -> 1190000

Sheet BLACK COFFEE ROASTERS (Coffee)
A1: DATE | B1: INV NO. | C1: DESCRIPTIONS | D1: QTY | E1: PRICE | F1: BILLS | G1: TOTAL | H1: DUE DATE | I1: STATUS
A2: 46055 | B2: BL2-10-2613 | C2: CANGGU BLEND 1 KG | D2: 20 | E2: 280000 | G2: =SUM(D2*E2) -> 5600000 | H2: 46062 | I2: PAID
G3: =SUM(D3*E3) -> 0
A4: Total | F4: =SUM(G:G)-SUMIF(I:I,"PAID*",G1) -> 0

Sheet PT. PRASIDA LANTUR MAJU (Wine)
A1: DATE | B1: INV NO. | C1: DESCRIPTIONS | D1: QTY | E1: BILLS | F1: PRICE | G1: TOTAL
A2: 46055 | B2: PLM-INV0351/2026 | C2: ISOLA RISERVA SYRAH 750 ML | D2: 3 | F2: 275000 | G2: =SUM(D2*F2) -> 825000
A3: SUBTOTAL | D3: =SUM(D2) -> 3 | F3: PPN | G3: =G2*11% -> 90750
A4: TOTAL | E4: =SUM(G2:G3) -> 915750
A5: 46058 | B5: PLM-INV0415/2026 | C5: ISOLA BIANCO 750 ML | D5: 3 | F5: 180180 | G5: =F5*D5 -> 540540
A6: SUBTOTAL | D6: =SUM(D5) -> 3 | F6: PPN | G6: =G5*11% -> 59459.4
A7: TOTAL | E7: 600000
A8: 46074 | B8: PLM-INV0602/2026 | C8: ISOLA RISERVA SYRAH 750 ML | D8: 2 | F8: 275000 | G8: =F8*D8 -> 550000
A9: SUBTOTAL | D9: =SUM(D8) -> 2 | F9: PPN | G9: =G8*11% -> 60500
A10: TOTAL | E10: =SUM(G8:G9) -> 610500
A11: GRAND TOTAL | E11: =SUM(E4,E7,E10) -> 2126250

Sheet PT LOVINA BEACH BREWERY
A1: DATE | B1: INV NO. | C1: DESCRIPTIONS | D1: BILLS | E1: TOTAL | F1: STATUS
A3: TOTAL | D3: =SUM(E2:E2) -> 0

Sheet CHAI CHITAI (Tea Leaf,etc)
A1: DATE | B1: INV NO. | C1: DESCRIPTIONS | D1: QTY | E1: BILLS | F1: PRICE | G1: SUBTOTAL | H1: TOTAL | I1: DISCOUNT | J1: TAX | K1: TOTAL
A2: 46069 | B2: #1 | C2: MILK OOLONG | D2: 2 | F2: 280000 | G2: =F2*D2 -> 560000 | H2: =SUM(G2:G5) -> 2700000 | I2: =H2*30% -> 810000 | J2: =(H2-I2)*0% -> 0 | K2: =H2-I2 -> 1890000
C3: MANGO OOLONG | D3: 6 | F3: 190000 | G3: =F3*D3 -> 1140000
C4: TIE GUAN YIN | D4: 2 | F4: 280000 | G4: =F4*D4 -> 560000
C5: CHAMOMILE | D5: 4 | F5: 110000 | G5: =F5*D5 -> 440000
A8: 46080 | B8: #2 | C8: RED GABA | D8: 4 | F8: 550000 | G8: =F8*D8 -> 2200000 | H8: =SUM(G8) -> 2200000 | I8: =H8*30% -> 660000 | J8: =(H8-I8)*0% -> 0 | K8: =H8-I8 -> 1540000
A11: GRAND TOTAL | E11: =SUM(K2:K10) -> 3430000

Sheet MULIA JAYA (Passion Fruit)
A1: DATE | B1: DESCRIPTIONS | C1: QTY | D1: BILLS | E1: PRICE | F1: TOTAL | G1: STATUS
F2: =C2*E2 -> 0
A3: TOTAL | D3: =SUM(F2) -> 0

Sheet Dewata Kencana Distribusi (Vdka
A1: DATE | B1: DESCRIPTIONS | C1: QTY | D1: BILLS | E1: UNIT PRICE | F1: TOTAL | G1: STATUS
A3: TOTAL | E3: =SUM(F2) -> 0

Sheet TOTAL
A1: NO | B1: SUPPLIER | C1: TOTAL
A2: 1 | B2: BUK BUNGA | C2: ='BUK BUNGA BAR (Groceries)'!E309 -> 17802000
A3: 2 | B3: TOKO EKA WHOLESALE | C3: ='WARUNG EKA (Drinks, Etc)'!F125 -> 11916000
A4: 3 | B4: DEWATA COCONUT | C4: ='DEWATA COCONUT (Coconut)'!E14 -> 2415000
A5: 4 | B5: SEDANA JAYA | C5: ='SEDANA JAYA'!F47 -> 0
A6: 5 | B6: PNB | C6: ='PNB (Alcohol)'!H7 -> 1500000
A7: 6 | B7: DSP | C7: ='DSP (Alcohol)'!F16 -> 3474000
A8: 7 | B8: DSP ARYA BIMA | C8: ='DSP ARYA BIMA (Alcohol)'!E3 -> 668000
A9: 8 | B9: SELERA (SYRUP) | C9: ='SELERA OR STIR UP (Syrup)'!F22 -> 4329000
A10: 9 | B10: DW BALI | C10: ='DW BALI (Alcohol)'!E6 -> 2620000
A11: 10 | B11: DDB | C11: ='DDB (Alcohol)'!E14 -> 525001.14
A12: 11 | B12: NANO DEWATA | C12: ='NANO DEWATA (Alcohol)'!E14 -> 855000
A13: 12 | B13: BALI PERMATA JAYA | C13: ='BALI PERMATA JAYA (Corona Beer)'!E17 -> 1190000
A14: 13 | B14: BLACK COFFEE ROASTERY | C14: ='BLACK COFFEE ROASTERS (Coffee)'!F4 -> 0
A15: 14 | B15: PRASIDA LANTUR MAJU | C15: ='PT. PRASIDA LANTUR MAJU (Wine)'!E11 -> 2126250
A16: 15 | B16: PT. LOVINA BEACH BREWERY | C16: ='PT LOVINA BEACH BREWERY'!D3 -> 0
A17: 16 | B17: CHAI CHITAI | C17: ='CHAI CHITAI (Tea Leaf,etc)'!E11 -> 3430000
A18: 17 | B18: MULIA JAYA | C18: ='MULIA JAYA (Passion Fruit)'!D3 -> 0
A19: 18 | B19: DEWATA KENCANA DISTRIBUSI | C19: ='Dewata Kencana Distribusi (Vdka'!E3 -> 0
A20: TOTAL | C20: =SUM(C2:C13) -> 47294001
