Workbook

Sheet BUK BUNGA (Groceries)
A1: DATE | B1: ITEM | C1: QYT | D1: PRICE | E1: SUBTOTAL | F1: TOTAL
A2: 46054 | B2: MILAC WHIPPING CREAM | C2: 6 | D2: 95000 | E2: =D2*C2 -> 570000 | F2: =SUM(E2:E8) -> 1257000
B3: FRESH MILK (DIAMOND) | C3: 4 | D3: 22000 | E3: =D3*C3 -> 88000
B4: CREAM CHEESE | C4: 1 | D4: 170000 | E4: =D4*C4 -> 170000
B5: PARMESAN GRATED | C5: 1 | D5: 270000 | E5: =D5*C5 -> 270000
B6: BBQ SAUCE | C6: 3 | D6: 40000 | E6: =D6*C6 -> 120000
B7: LOLLO ROSSO | C7: 0.3 | D7: 80000 | E7: =D7*C7 -> 24000
B8: FOOD COLORING | C8: 1 | D8: 15000 | E8: =D8*C8 -> 15000
A9: 46055 | B9: BABY CUCUMBER | C9: 0.5 | D9: 90000 | E9: =D9*C9 -> 45000 | F9: =SUM(E9:E32) -> 2575000
B10: MUSHROOM BUTTON | C10: 2 | D10: 48000 | E10: =D10*C10 -> 96000
B11: DILL | C11: 1 | D11: 110000 | E11: =D11*C11 -> 110000
B12: SUNKIST | C12: 1 | D12: 38000 | E12: =D12*C12 -> 38000
B13: AVOCADO | C13: 1 | D13: 40000 | E13: =D13*C13 -> 40000
B14: SALAD OIL | C14: 1 | D14: 210000 | E14: =D14*C14 -> 210000
B15: OREGANO | C15: 2 | D15: 30000 | E15: =D15*C15 -> 60000
B16: IMPORTED LEMON | C16: 1 | D16: 70000 | E16: =D16*C16 -> 70000
B17: DRAGON FRUIT | C17: 2.18 | D17: 25000 | E17: 55000
B18: YEAST | C18: 1 | D18: 70000 | E18: =D18*C18 -> 70000
B19: HONEY BLOSSOM | C19: 1 | D19: 35000 | E19: =D19*C19 -> 35000
B20: ONION | C20: 1 | D20: 40000 | E20: =D20*C20 -> 40000
B21: LIME | C21: 0.2 | D21: 30000 | E21: =D21*C21 -> 6000
B22: AMANDA BUTTER | C22: 2 | D22: 25000 | E22: =D22*C22 -> 50000
B23: QUAIL EGG | C23: 30 | D23: 1000 | E23: =D23*C23 -> 30000
B24: CANNED PEELED TOMATO | C24: 1 | D24: 120000 | E24: =D24*C24 -> 120000
B25: KARA (200) | C25: 1 | D25: 230000 | E25: =D25*C25 -> 230000
B26: BACON (1KG) | C26: 3 | D26: 170000 | E26: =D26*C26 -> 510000
B27: KEWPIE MAYONNAISE | C27: 1 | D27: 100000 | E27: =D27*C27 -> 100000
B28: MILAC WHIPPING CREAM | C28: 2 | D28: 95000 | E28: =D28*C28 -> 190000
B29: PARMESAN BLOCK | C29: 1 | D29: 275000 | E29: =D29*C29 -> 275000
... B31: EDAMAME | C31: 1 | D31: 30000 | E31: =D31*C31 -> 30000
B32: WATERMELON | C32: 3.65 | D32: 15000 | E32: 55000
A33: 46056 | B33: OIL (18 L) | C33: 1 | D33: 395000 | E33: =D33*C33 -> 395000 | F33: =SUM(E33:E41) -> 1915000
B34: CASHEW NUT | C34: 1 | D34: 160000 | E34: =D34*C34 -> 160000
B35: BBQ SAUCE | C35: 3 | D35: 40000 | E35: =D35*C35 -> 120000
B36: SESAME DRESSING | C36: 2 | D36: 120000 | E36: =D36*C36 -> 240000
B37: DOUBLE ZERO | C37: 1 | D37: 220000 | E37: =D37*C37 -> 220000
B38: MILAC WHIPPING CREAM | C38: 3 | D38: 95000 | E38: =D38*C38 -> 285000
B39: JALAPENO | C39: 1 | D39: 120000 | E39: =D39*C39 -> 120000
B40: GORGONZOLA CHEESE | C40: 1 | D40: 195000 | E40: =D40*C40 -> 195000
B41: FRENCH FRIES | C41: 4 | D41: 45000 | E41: =D41*C41 -> 180000
...

Sheet SEDANA JAYA (Groceries)
A1: DATE | B1: INVOICE NO. | C1: ITEM | D1: QYT | E1: PRICE | F1: SUBTOTAL | G1: TOTAL | H1: OUTSTANDING STATUS CHECK
A2: 46054 | B2: 029695 | C2: DOUBLE ZERO | D2: 1 | E2: 250000 | F2: =E2*D2 -> 250000 | G2: =SUM(F2:F23) -> 1811090
C3: MANGO | D3: 1 | E3: 39000 | F3: =E3*D3 -> 39000
C4: AVOCADO | D4: 1 | E4: 39000 | F4: =E4*D4 -> 39000
C5: LEMON | D5: 1 | E5: 83000 | F5: =E5*D5 -> 83000
C6: CREAM CHEESE | D6: 1 | E6: 250000 | F6: =E6*D6 -> 250000
C7: SUGAR | D7: 2 | E7: 30000 | F7: =E7*D7 -> 60000
C8: BANANA | D8: 2.8 | E8: 25000 | F8: =E8*D8 -> 70000
C9: EGG | D9: 4 | E9: 66000 | F9: =E9*D9 -> 264000
C10: POTATO | D10: 5 | E10: 25000 | F10: =E10*D10 -> 125000
C11: BASMATI RICE SHUKRIYA | D11: 2 | E11: 75000 | F11: =E11*D11 -> 150000
C12: LEEK | D12: 0.1 | E12: 39000 | F12: =E12*D12 -> 3900
C13: PARSLEY | D13: 0.1 | E13: 83000 | F13: =E13*D13 -> 8300
C14: CORIANDER | D14: 0.07 | E14: 77000 | F14: =E14*D14 -> 5390
... C23: BABY ROMAINE | D23: 1 | E23: 61000 | F23: =E23*D23 -> 61000
A24: 46054 | B24: 029696 | C24: ICEBERG | D24: 1 | E24: 45000 | F24: =E24*D24 -> 45000 | G24: =SUM(F24:F31) -> 246900
C25: GREEN LETTUCE | D25: 0.3 | E25: 44000 | F25: =E25*D25 -> 13200
C26: ROCKET LETTUCE | D26: 0.3 | E26: 94000 | F26: =E26*D26 -> 28200
C27: CHERRY RED TOMATO | D27: 0.5 | E27: 55000 | F27: =E27*D27 -> 27500
C28: CHERRY YELLOW TOMATO | D28: 0.5 | E28: 68000 | F28: =E28*D28 -> 34000
C29: QUAIL EGG | D29: 30 | E29: 1000 | F29: =E29*D29 -> 30000
C30: BROWN SUGAR | D30: 1 | E30: 45000 | F30: =E30*D30 -> 45000
C31: STRAWBERRY | D31: 0.2 | E31: 120000 | F31: =E31*D31 -> 24000
A32: 46055 | B32: 029701 | C32: BABY KYURI | D32: 1 | E32: 85000 | F32: =E32*D32 -> 85000 | G32: =SUM(F32:F53) -> 1163150
C33: SPAGHETTI | D33: 3 | E33: 25000 | F33: =E33*D33 -> 75000
C34: TOMATO KETCHUP | D34: 2 | E34: 35000 | F34: =E34*D34 -> 70000
C35: PORTABLE GAS | D35: 2 | E35: 35000 | F35: =E35*D35 -> 70000
C36: SUGAR | D36: 3 | E36: 30000 | F36: =E36*D36 -> 90000
C37: ONION | D37: 0.5 | E37: 39000 | F37: =E37*D37 -> 19500
C38: POTATO | D38: 5 | E38: 25000 | F38: =E38*D38 -> 125000
C39: SWEET POTATO | D39: 5 | E39: 25000 | F39: =E39*D39 -> 125000
C40: MAYONNAISE | D40: 2 | E40: 45000 | F40: =E40*D40 -> 90000
C41: ZUCCHINI | D41: 1 | E41: 55000 | F41: =E41*D41 -> 55000
C42: BIG RED CHILI | D42: 0.2 | E42: 72000 | F42: =E42*D42 -> 14400
C43: RED PEPPER | D43: 0.3 | E43: 83000 | F43: =E43*D43 -> 24900
C44: YELLOW PEPPER | D44: 0.3 | E44: 94000 | F44: =E44*D44 -> 28200
... C53: WHITE PEAR | D53: 2 | E53: 39000 | F53: =E53*D53 -> 78000
A54: 46055 | B54: 029702 | C54: MANGO | D54: 1.5 | E54: 39000 | F54: =E54*D54 -> 58500 | G54: =SUM(F54:F66) -> 533700
C55: WATERMELON | D55: 6 | E55: 15000 | F55: =E55*D55 -> 90000
C56: STRAWBERRY | D56: 0.2 | E56: 120000 | F56: =E56*D56 -> 24000
...

Sheet AD supplier (Groceries)
A1: DATE | B1: ITEM | C1: QYT | D1: PRICE | E1: SUBTOTAL | F1: TOTAL | G1: BILLS
A2: 46055 | B2: MOZARELLA CHEESE | C2: 4.6 | D2: 120000 | E2: =D2*C2 -> 552000 | F2: =SUM(E2:E4) -> 2982000
B3: CANNED PEELED TOMATOES (MERKO) | C3: 18 | D3: 100000 | E3: =D3*C3 -> 1800000
B4: PARMESAN CHEESE GRATED | C4: 3 | D4: 210000 | E4: =D4*C4 -> 630000
A5: 46055 | B5: BORGES EXTRA VIRGIN OIL 5L | C5: 1 | D5: 1300000 | E5: =D5*C5 -> 1300000 | F5: =SUM(E5) -> 1300000
F21: =SUM(F2:F20) -> 4282000

Sheet RAFI SEAFOOD (Seafood)
A1: DATE | B1: DESCRIPTION | C1: QUANTITY | D1: PRICE | E1: BILLS | F1: SUBTOTAL | G1: TOTAL
A2: 46054 | B2: SALMON | C2: 2.25 | D2: 370000 | F2: =SUM(C2*D2) -> 832500 | G2: =SUM(F2:F4) -> 1965500
B3: MAHI-MAHI | C3: 4.2 | D3: 115000 | F3: =SUM(C3*D3) -> 483000
B4: CHICKEN BREAST | C4: 10 | D4: 65000 | F4: =SUM(C4*D4) -> 650000
A5: 46055 | B5: PRAWN | C5: 5 | D5: 185000 | F5: =SUM(C5*D5) -> 925000 | G5: =SUM(F5:F8) -> 2670000
B6: SQUID | C6: 3 | D6: 85000 | F6: =SUM(C6*D6) -> 255000
B7: MINCED BEEF | C7: 5 | D7: 150000 | F7: =SUM(C7*D7) -> 750000
B8: SALMON | C8: 2 | D8: 370000 | F8: =SUM(C8*D8) -> 740000
A9: 46059 | B9: TUNA | C9: 6.8 | D9: 115000 | F9: =SUM(C9*D9) -> 782000 | G9: =SUM(F9:F13) -> 3650500
B10: SALMON | C10: 3.6 | D10: 370000 | F10: =SUM(C10*D10) -> 1332000
B11: PRAWN | C11: 5 | D11: 185000 | F11: =SUM(C11*D11) -> 925000
B12: SQUID TUBE | C12: 3 | D12: 85000 | F12: =SUM(C12*D12) -> 255000
B13: MAHI-MAHI | C13: 3.1 | D13: 115000 | F13: =SUM(C13*D13) -> 356500
D61: =SUM(G2:G60) -> 8286000

Sheet MAMA RADA PRODUCTION (Dumpling)
A1: DATE | B1: INV NO. | C1: DESCRIPTIONS | D1: QTY | E1: BIILS | F1: PRICE | G1: SUBTOTAL | H1: TOTAL
G2: =D2*F2 -> 0 | H2: =SUM(G2) -> 0
G3: =SUM(D3*F3+D4*F4) -> 0
G5: =SUM(D5*F5+D6*F6+D7*F7) -> 0
G8: =SUM(D8*F8) -> 0
E12: GRAND TOTAL | H12: =SUM(H2:H11) -> 0

Sheet KSP (Chicken)
A1: DATE | B1: INV NO. | C1: DESCRIPTIONS | D1: QTY | E1: BILLS | F1: PRICE | G1: SUB TOTAL | H1: TOTAL
A2: 46056 | B2: BO0365/PRN-R/2026 | C2: BONELESS BREAST TK SP | D2: 10.2 | F2: 52000 | G2: =SUM(D2*F2) -> 530400 | H2: =SUM(G2:G3) -> 1555500
C3: BONELESS LEG TK SP | D3: 20.1 | F3: 51000 | G3: =SUM(D3*F3) -> 1025100
A4: 46059 | B4: BO0412/PRN-R/2026 | C4: BONELESS BREAST TK SP | D4: 5.1 | E4: =_xlfn.DISPIMG("ID_2EBB1BBD77A04910995658200A91ED32",1) -> =DISPIMG("ID_2EBB1BBD77A04910995658200A91ED32",1) | F4: 52500 | G4: =SUM(D4*F4) -> 267750 | H4: =SUM(G4:G5) -> 1060850
C5: BONELESS LEG TK SP | D5: 15.4 | F5: 51500 | G5: =SUM(D5*F5) -> 793100
G6: =SUM(D6*F6) -> 0
G7: =SUM(D7*F7) -> 0
G8: =SUM(D8*F8) -> 0
G9: =D9*F9 -> 0
G10: =D10*F10 -> 0
G11: =D11*F11 -> 0
G12: =D12*F12 -> 0
H13: =SUM(H2:H12) -> 2616350

Sheet SURYA CIPTA NIAGA BALI (Beef)
A1: DATE | B1: INV NO. | C1: DESCRIPTIONS | D1: QTY | E1: BILLS | F1: PRICE | G1: SUBTOTAL | H1: TOTAL | I1: DUE DATE
A3: 46059 | B3: 2602/FK-0599 | C3: COW MEAT | D3: 5.02 | F3: 150000 | G3: =F3*D3 -> 753000 | H3: =SUM(G3:G5) -> 8553600 | I3: 46066
C4: STRIPLOIN ICHI BROWN | D4: 7.42 | F4: 180000 | G4: =F4*D4 -> 1335600
C5: TOP SIDE BLACK ANGUS GF ONYX | D5: 25.86 | F5: 250000 | G5: =F5*D5 -> 6465000
H6: =SUM(G6:G7) -> 0
G9: =D9*F9 -> 0 | H9: =SUM(D9*F9) -> 0
A10: TOTAL | G10: =SUM(H:H)-SUMIF(I:I,"PAID*",H:H) -> 8553600

Sheet BAYU AGNI MERTA (Gas)
A1: DATE | B1: INV NO. | C1: DESCRIPTIONS | D1: QTY | E1: BILLS | F1: PRICE | G1: TOTAL
G2: =SUM(D2*F2) -> 0
G3: =D3*F3 -> 0
A4: TOTAL | E4: =SUM(G2:G3) -> 0

Sheet Joy Green (Mix Berry)
A1: NO | B1: DATE | C1: TOTAL | D1: PC | E1: STATUS
A3: Total | D3: =SUM(C2:C2) -> 0

Sheet CELEBRITY BAKERY (Bakery)
A1: DATE | B1: INV.NO | C1: DESCRIPTION | D1: QTY | E1: BILLS | F1: PRICE | G1: SUBTOTAL | H1: TOTAL
G2: =F2*D2 -> 0 | H2: =SUM(G2:G3) -> 0
G3: =F3*D3 -> 0
A5: TOTAL | E5: =SUM(H2:H4) -> 0

Sheet Krop (Edible flower)
A1: DATE | B1: INV.NO | C1: DESCRIPTION | D1: QTY | E1: BILLS | F1: PRICE | G1: SUBTOTAL | H1: TOTAL
G2: =D2*F2 -> 0 | H2: =SUM(G2:G5) -> 0
G3: =D3*F3 -> 0
G4: =D4*F4 -> 0
G5: =D5*F5 -> 0
G6: =D6*F6 -> 0 | H6: =SUM(G6:G9) -> 0
G7: =D7*F7 -> 0
G8: =D8*F8 -> 0
G9: =D9*F9 -> 0
A10: TOTAL | H10: =SUM(H2:H9) -> 0

Sheet Boiler (Dumplings&Syrniki)
A1: DATE | B1: INV.NO | C1: DESCRIPTION | D1: QTY | E1: BILLS | F1: PRICE | G1: SUBTOTAL | H1: TOTAL | I1: TOTAL AFTER TAX
G2: =D2*F2 -> 0 | H2: =SUM(G2:G4) -> 0 | I2: =(H2*10%)+H2 -> 0
G3: =D3*F3 -> 0
G4: =D4*F4 -> 0
A5: TOTAL | E5: =SUM(I2:I4) -> 0

Sheet Abdi Jaya (TKW, Vacuum Bag)
A1: DATE | B1: INV.NO | C1: DESCRIPTION | D1: QTY | E1: BILLS | F1: PRICE | G1: SUBTOTAL | H1: TOTAL
G2: =D2*F2 -> 0 | H2: =SUM(G2:G4) -> 0
G3: =D3*F3 -> 0
G4: =D4*F4 -> 0
G5: =D5*F5 -> 0 | H5: =SUM(G5:G14) -> 0
G6: =D6*F6 -> 0
G7: =D7*F7 -> 0
G8: =D8*F8 -> 0
G9: =D9*F9 -> 0
G10: =D10*F10 -> 0
G11: =D11*F11 -> 0
G12: =D12*F12 -> 0
G13: =D13*F13 -> 0
G14: =D14*F14 -> 0
G15: =D15*F15 -> 0 | H15: =SUM(G15:G17) -> 0
G16: =D16*F16 -> 0
G17: =D17*F17 -> 0
G18: =D18*F18 -> 0 | H18: =SUM(G18:G20) -> 0
G19: =D19*F19 -> 0
G20: =D20*F20 -> 0
A21: GRAND TOTAL | F21: =SUM(H2:H20) -> 0

Sheet Dishy Soap (Chemicals)
A1: DATE | B1: DESCRIPTION | C1: QTY | D1: BILLS | E1: PRICE | F1: SUBTOTAL | G1: TOTAL
F2: =C2*E2 -> 0 | G2: =SUM(F2:F2) -> 0
F3: =C3*E3 -> 0 | G3: =SUM(F3:F8) -> 0
F4: =C4*E4 -> 0
F5: =C5*E5 -> 0
F6: =C6*E6 -> 0
F7: =C7*E7 -> 0
F8: =C8*E8 -> 0
F9: =C9*E9 -> 0 | G9: =SUM(F9:F10) -> 0
F10: =C10*E10 -> 0
A11: GRAND TOTAL | G11: =SUM(G2:G10) -> 0

Sheet TOTAL
A1: SUPPLIER | B1: Total
A2: BU BUNGA | B2: ='BUK BUNGA (Groceries)'!F550 -> 8797600
A3: SEDANA JAYA | B3: ='SEDANA JAYA (Groceries)'!G672 -> 15485310
A4: RAFI SEAFOOD | B4: ='RAFI SEAFOOD (Seafood)'!D61 -> 8286000
A5: MAMA RADA PRODUCTION | B5: ='MAMA RADA PRODUCTION (Dumpling)'!H12 -> 0
A6: KSP | B6: ='KSP (Chicken)'!H13 -> 2616350
A7: SURYA CIPTA NIAGA BALI | B7: ='SURYA CIPTA NIAGA BALI (Beef)'!G10 -> 8553600
A8: BAYU AGNI MERTA | B8: ='BAYU AGNI MERTA (Gas)'!E4 -> 0
A9: JOY GREEN | B9: ='Joy Green (Mix Berry)'!D3 -> 0
A10: CELEBRITY BAKERY | B10: ='CELEBRITY BAKERY (Bakery)'!E5 -> 0
A11: KROP NATIION | B11: ='Krop (Edible flower)'!H10 -> 0
A12: BOILER | B12: ='Boiler (Dumplings&Syrniki)'!E5 -> 0
A13: ABDI JAYA | B13: ='Abdi Jaya (TKW, Vacuum Bag)'!D21 -> 0
A14: DISHY SOAP | B14: ='Dishy Soap (Chemicals)'!G11 -> 0
A15: TOTAL | B15: =SUM(B2:B12) -> 43738860
